Workbook
Name Amount_HRDGA: #REF!
Name Amount_Salary: #REF!
Name Entity_HRDGA: #REF!
Name Entity_Salary: #REF!
Name FSLI_HRDGA: #REF!
Name FSLI_Salary: #REF!
Name Grouping_HRDGA: #REF!
Name Grouping_Salary: #REF!

Sheet BMG Business Plan
A1: PT Boga Makmur Gracia
A2: Business Plan
A3: Oct 26 to Dec 27 | K3: 2026 | L3: =YEAR(L5) -> 2026 | M3: =YEAR(M5) -> 2026 | N3: =YEAR(N5) -> 2026 | O3: =YEAR(O5) -> 2026 | P3: =YEAR(P5) -> 2026 | Q3: =YEAR(Q5) -> 2026 | R3: =YEAR(R5) -> 2026 | S3: =YEAR(S5) -> 2026 | ... AI3: =YEAR(AI5) -> 2027
I4: Delta | K4: YTD | L4: Actual | M4: Actual | N4: Actual | O4: Actual | P4: Actual | Q4: Actual | R4: Actual | S4: Actual | T4: BP | U4: BP | V4: BP | W4: BP | X4: BP | Y4: BP | Z4: BP | AA4: BP | AB4: BP | AC4: BP | AD4: BP | AE4: BP | AF4: BP | AG4: BP | AH4: BP | AI4: BP | AJ4: Total
G5: Names | H5: Unit | I5: % | J5: =L5-31 -> 46022 | K5: Bud 2026 | L5: 46053 | M5: =EOMONTH(L5,1) -> 46081 | N5: =EOMONTH(M5,1) -> 46112 | O5: =EOMONTH(N5,1) -> 46142 | P5: =EOMONTH(O5,1) -> 46173 | Q5: =EOMONTH(P5,1) -> 46203 | R5: =EOMONTH(Q5,1) -> 46234 | S5: =EOMONTH(R5,1) -> 46265 | T5: =EOMONTH(S5,1) -> 46295 | ... AI5: =EOMONTH(AH5,1) -> 46752 | AJ5: Bud 2027
L6: =EOMONTH($L$5,11) -> 46387 | M6: =EOMONTH($L$5,11) -> 46387 | N6: =EOMONTH($L$5,11) -> 46387 | O6: =EOMONTH($L$5,11) -> 46387 | P6: =EOMONTH($L$5,11) -> 46387 | Q6: =EOMONTH($L$5,11) -> 46387 | R6: =EOMONTH($L$5,11) -> 46387 | S6: =EOMONTH($L$5,11) -> 46387 | ... AI6: =EOMONTH($L$5,11) -> 46387
B7: Financial statements
B8: 1.1 | C8: Income statement
C9: Revenue - Gross | H9: Rp m | I9: =IFERROR((K9-J9)/J9,0) -> 0 | K9: =SUM(L9:W9) -> 101135.45 | L9: =SUMIFS('PL Actual MTM - Aug 26'!D:D,'PL Actual MTM - Aug 26'!$R:$R,"Revenue")/10^6 -> 9369.4466 | M9: =SUMIFS('PL Actual MTM - Aug 26'!E:E,'PL Actual MTM - Aug 26'!$R:$R,"Revenue")/10^6 -> 8659.5707 | N9: =SUMIFS('PL Actual MTM - Aug 26'!F:F,'PL Actual MTM - Aug 26'!$R:$R,"Revenue")/10^6 -> 6547.2579 | O9: =SUMIFS('PL Actual MTM - Aug 26'!G:G,'PL Actual MTM - Aug 26'!$R:$R,"Revenue")/10^6 -> 6850.5287 | P9: =SUMIFS('PL Actual MTM - Aug 26'!H:H,'PL Actual MTM - Aug 26'!$R:$R,"Revenue")/10^6 -> 7705.4169 | Q9: =SUMIFS('PL Actual MTM - Aug 26'!I:I,'PL Actual MTM - Aug 26'!$R:$R,"Revenue")/10^6 -> 8295.2878 | R9: =SUMIFS('PL Actual MTM - Aug 26'!J:J,'PL Actual MTM - Aug 26'!$R:$R,"Revenue")/10^6 -> 8929.6805 | S9: =SUMIFS('PL Actual MTM - Aug 26'!K:K,'PL Actual MTM - Aug 26'!$R:$R,"Revenue")/10^6 -> 9793.1255 | T9: =SUM(T10:T13) -> 8746.2829 | U9: =SUM(U10:U13) -> 8746.2829 | V9: =SUM(V10:V13) -> 8746.2829 | W9: =SUM(W10:W13) -> 8746.2829 | X9: =SUM(X10:X13) -> 8746.2829 | Y9: =SUM(Y10:Y13) -> 8746.2829 | Z9: =SUM(Z10:Z13) -> 8746.2829 | AA9: =SUM(AA10:AA13) -> 8746.2829 | ... AI9: =SUM(AI10:AI13) -> 8746.2829 | AJ9: =SUM(X9:AI9) -> 104955.39
D10: FCC | H10: Rp m | I10: =IFERROR((K10-J10)/J10,0) -> 0 | K10: =SUM(L10:W10) -> 91932.686 | L10: =SUM('Data Aktual'!Q241:Q242)/10^6 -> 8944.5075 | M10: =SUM('Data Aktual'!R241:R242)/10^6 -> 8504.9933 | N10: =SUM('Data Aktual'!S241:S242)/10^6 -> 6061.6471 | O10: =SUM('Data Aktual'!T241:T242)/10^6 -> 6092.7878 | P10: =SUM('Data Aktual'!U241:U242)/10^6 -> 7072.8378 | Q10: =SUM('Data Aktual'!V241:V242)/10^6 -> 6880.534 | R10: =SUM('Data Aktual'!W241:W242)/10^6 -> 7823.6608 | S10: =SUM('Data Aktual'!X241:X242)/10^6 -> 8705.7869 | T10: =SUM('Business Plan - Model Details'!R76/10^6) -> 7961.4826 | U10: =SUM('Business Plan - Model Details'!S76/10^6) -> 7961.4826 | V10: =SUM('Business Plan - Model Details'!T76/10^6) -> 7961.4826 | W10: =SUM('Business Plan - Model Details'!U76/10^6) -> 7961.4826 | X10: =SUM('Business Plan - Model Details'!V76/10^6) -> 7961.4826 | Y10: =SUM('Business Plan - Model Details'!W76/10^6) -> 7961.4826 | Z10: =SUM('Business Plan - Model Details'!X76/10^6) -> 7961.4826 | AA10: =SUM('Business Plan - Model Details'!Y76/10^6) -> 7961.4826 | ... AI10: =SUM('Business Plan - Model Details'!AG76/10^6) -> 7961.4826 | AJ10: =SUM(X10:AI10) -> 95537.791
D11: Ubi Ungu | H11: Rp m | I11: =IFERROR((K11-J11)/J11,0) -> 0 | K11: =SUM(L11:W11) -> 3399.4832 | L11: ='Business Plan - Model Details'!J77/10^6 -> 30.560211 | M11: ='Business Plan - Model Details'!K77/10^6 -> 0.26675 | N11: ='Business Plan - Model Details'!L77/10^6 -> 150.97565 | O11: ='Business Plan - Model Details'!M77/10^6 -> 273.6855 | P11: ='Business Plan - Model Details'!N77/10^6 -> 241.821 | Q11: ='Business Plan - Model Details'!O77/10^6 -> 684.21375 | R11: ='Business Plan - Model Details'!P77/10^6 -> 430.26775 | S11: ='Business Plan - Model Details'!Q77/10^6 -> 349.70925 | ... AI11: ='Business Plan - Model Details'!AG77/10^6 -> 309.49583 | AJ11: =SUM(X11:AI11) -> 3713.9499
D12: Ubi Orange | H12: Rp m | I12: =IFERROR((K12-J12)/J12,0) -> 0 | K12: =SUM(L12:W12) -> 3177.5584 | L12: ='Business Plan - Model Details'!J78/10^6 -> 25.717483 | M12: ='Business Plan - Model Details'!K78/10^6 -> 0.49816 | N12: ='Business Plan - Model Details'!L78/10^6 -> 150.95685 | O12: ='Business Plan - Model Details'!M78/10^6 -> 264.00085 | P12: ='Business Plan - Model Details'!N78/10^6 -> 255.5465 | Q12: ='Business Plan - Model Details'!O78/10^6 -> 653.8829 | R12: ='Business Plan - Model Details'!P78/10^6 -> 404.6592 | S12: ='Business Plan - Model Details'!Q78/10^6 -> 354.6037 | ... AI12: ='Business Plan - Model Details'!AG78/10^6 -> 266.92318 | AJ12: =SUM(X12:AI12) -> 3203.0782
D13: Others (actual: retail & maklon per invoice; projection: model total operating revenue less the three products) | F13: Others (MBS, Nutrifood, Koperasi, Lembutan, maklon & merek) | H13: Rp m | I13: =IFERROR((K13-J13)/J13,0) -> 0 | K13: =SUM(L13:W13) -> 3073.3863 | L13: ='Business Plan - Model Details'!J83/10^6 -> 429.98577 | M13: ='Business Plan - Model Details'!K83/10^6 -> 216.98377 | N13: ='Business Plan - Model Details'!L83/10^6 -> 92.358781 | O13: ='Business Plan - Model Details'!M83/10^6 -> 283.67813 | P13: ='Business Plan - Model Details'!N83/10^6 -> 196.73241 | Q13: ='Business Plan - Model Details'!O83/10^6 -> 175.60696 | R13: ='Business Plan - Model Details'!P83/10^6 -> 353.60476 | S13: ='Business Plan - Model Details'!Q83/10^6 -> 490.91055 | ... AI13: ='Business Plan - Model Details'!AG83/10^6 -> 208.3813 | AJ13: =SUM(X13:AI13) -> 2500.5756
C14: Sales Discount and Return | K14: =SUM(L14:W14) -> -78.30075 | L14: =SUM(L15:L16) -> 0 | M14: =SUM(M15:M16) -> 0 | N14: =SUM(N15:N16) -> -62.7011 | O14: =SUM(O15:O16) -> 0 | P14: =SUM(P15:P16) -> 0 | Q14: =SUM(Q15:Q16) -> 0 | R14: =SUM(R15:R16) -> -15.59965 | S14: =SUM(S15:S16) -> 0 | ... AI14: =SUM(AI15:AI16) -> 0 | AJ14: =SUM(X14:AI14) -> 0
D15: Sales Discount | H15: Rp m | I15: =IFERROR((K15-J15)/J15,0) -> 0 | K15: =SUM(L15:W15) -> 0 | L15: =SUMIFS('PL Actual MTM - Aug 26'!D:D,'PL Actual MTM - Aug 26'!$R:$R,"Sales Return")/10^6 -> 0 | M15: =SUMIFS('PL Actual MTM - Aug 26'!E:E,'PL Actual MTM - Aug 26'!$R:$R,"Sales Return")/10^6 -> 0 | N15: 0 | O15: =SUMIFS('PL Actual MTM - Aug 26'!G:G,'PL Actual MTM - Aug 26'!$R:$R,"Sales Return")/10^6 -> 0 | P15: =SUMIFS('PL Actual MTM - Aug 26'!H:H,'PL Actual MTM - Aug 26'!$R:$R,"Sales Return")/10^6 -> 0 | Q15: =SUMIFS('PL Actual MTM - Aug 26'!I:I,'PL Actual MTM - Aug 26'!$R:$R,"Sales Return")/10^6 -> 0 | R15: 0 | S15: =SUMIFS('PL Actual MTM - Aug 26'!K:K,'PL Actual MTM - Aug 26'!$R:$R,"Sales Return")/10^6 -> 0 | T15: 0 | U15: 0 | V15: 0 | W15: 0 | X15: 0 | Y15: 0 | Z15: 0 | AA15: 0 | AB15: 0 | AC15: 0 | AD15: 0 | AE15: 0 | AF15: 0 | AG15: 0 | AH15: 0 | AI15: 0 | AJ15: =SUM(X15:AI15) -> 0
D16: Sales Return | H16: Rp m | I16: =IFERROR((K16-J16)/J16,0) -> 0 | K16: =SUM(L16:W16) -> -78.30075 | L16: =SUMIFS('PL Actual MTM - Aug 26'!D:D,'PL Actual MTM - Aug 26'!$R:$R,"Sales Return")/10^6 -> 0 | M16: =SUMIFS('PL Actual MTM - Aug 26'!E:E,'PL Actual MTM - Aug 26'!$R:$R,"Sales Return")/10^6 -> 0 | N16: =SUMIFS('PL Actual MTM - Aug 26'!F:F,'PL Actual MTM - Aug 26'!$R:$R,"Sales Return")/10^6 -> -62.7011 | O16: =SUMIFS('PL Actual MTM - Aug 26'!G:G,'PL Actual MTM - Aug 26'!$R:$R,"Sales Return")/10^6 -> 0 | P16: =SUMIFS('PL Actual MTM - Aug 26'!H:H,'PL Actual MTM - Aug 26'!$R:$R,"Sales Return")/10^6 -> 0 | Q16: =SUMIFS('PL Actual MTM - Aug 26'!I:I,'PL Actual MTM - Aug 26'!$R:$R,"Sales Return")/10^6 -> 0 | R16: =SUMIFS('PL Actual MTM - Aug 26'!J:J,'PL Actual MTM - Aug 26'!$R:$R,"Sales Return")/10^6 -> -15.59965 | S16: =SUMIFS('PL Actual MTM - Aug 26'!K:K,'PL Actual MTM - Aug 26'!$R:$R,"Sales Return")/10^6 -> 0 | T16: 0 | U16: 0 | V16: 0 | W16: 0 | X16: 0 | Y16: 0 | Z16: 0 | AA16: 0 | AB16: 0 | AC16: 0 | AD16: 0 | AE16: 0 | AF16: 0 | AG16: 0 | AH16: 0 | AI16: 0 | AJ16: =SUM(X16:AI16) -> 0
C17: Revenue | H17: Rp m | I17: =IFERROR((K17-J17)/J17,0) -> 0 | J17: =SUM(J9,J16) -> 0 | K17: =SUM(K9,K16) -> 101057.15 | L17: =SUM(L14,L9) -> 9369.4466 | M17: =SUM(M14,M9) -> 8659.5707 | N17: =SUM(N14,N9) -> 6484.5568 | O17: =SUM(O14,O9) -> 6850.5287 | P17: =SUM(P14,P9) -> 7705.4169 | Q17: =SUM(Q14,Q9) -> 8295.2878 | R17: =SUM(R14,R9) -> 8914.0809 | S17: =SUM(S14,S9) -> 9793.1255 | ... AI17: =SUM(AI14,AI9) -> 8746.2829 | AJ17: =SUM(AJ9,AJ16) -> 104955.39
C18: FCC | H18: Rp m | I18: =IFERROR((K18-J18)/J18,0) -> 0 | K18: =SUM(L18:W18) -> -79243.625 | L18: =SUM(L20:L26,L28:L32) -> -6689.2956 | M18: =SUM(M20:M26,M28:M32) -> -6206.1889 | N18: =SUM(N20:N26,N28:N32) -> -5128.5947 | O18: =SUM(O20:O26,O28:O32) -> -5575.0519 | P18: =SUM(P20:P26,P28:P32) -> -6145.3555 | Q18: =SUM(Q20:Q26,Q28:Q32) -> -6472.8107 | R18: =SUM(R20:R26,R28:R32) -> -6798.4327 | S18: =SUM(S20:S26,S28:S32) -> -7437.8719 | ... AI18: =SUM(AI20:AI26,AI28:AI32) -> -7236.8158
D19: Manufacturing Cost
E20: Raw Materials | H20: Rp m | I20: =IFERROR((K20-J20)/J20,0) -> 0 | K20: =SUM(L20:W20) -> -29186.661 | L20: =-'Business Plan - Model Details'!J546/10^6 -> -2152.6057 | M20: =-'Business Plan - Model Details'!K546/10^6 -> -1978.8554 | N20: =-'Business Plan - Model Details'!L546/10^6 -> -1593.9767 | O20: =-'Business Plan - Model Details'!M546/10^6 -> -1650.8016 | P20: =-'Business Plan - Model Details'!N546/10^6 -> -2023.7932 | Q20: =-'Business Plan - Model Details'!O546/10^6 -> -2337.955 | R20: =-'Business Plan - Model Details'!P546/10^6 -> -2576.5355 | S20: =-'Business Plan - Model Details'!Q546/10^6 -> -3103.9859 | ... AI20: =-'Business Plan - Model Details'!AG546/10^6 -> -2998.8255 | AJ20: =SUM(X20:AI20) -> -35986.163
E21: OIL | H21: Rp m | I21: =IFERROR((K21-J21)/J21,0) -> 0 | K21: =SUM(L21:W21) -> -16008.371 | L21: =-'Business Plan - Model Details'!J547/10^6 -> -1501.893 | M21: =-'Business Plan - Model Details'!K547/10^6 -> -1387.4366 | N21: =-'Business Plan - Model Details'!L547/10^6 -> -1076.0138 | O21: =-'Business Plan - Model Details'!M547/10^6 -> -1147.087 | P21: =-'Business Plan - Model Details'!N547/10^6 -> -1270.1684 | Q21: =-'Business Plan - Model Details'!O547/10^6 -> -1259.1326 | R21: =-'Business Plan - Model Details'!P547/10^6 -> -1334.6782 | S21: =-'Business Plan - Model Details'!Q547/10^6 -> -1362.1392 | ... AI21: =-'Business Plan - Model Details'!AG547/10^6 -> -1416.791
E22: CNG | H22: Rp m | I22: =IFERROR((K22-J22)/J22,0) -> 0 | K22: =SUM(L22:W22) -> -12201.974 | L22: =-'Business Plan - Model Details'!J548/10^6 -> -1107.9619 | M22: =-'Business Plan - Model Details'!K548/10^6 -> -1018.5149 | N22: =-'Business Plan - Model Details'!L548/10^6 -> -817.96911 | O22: =-'Business Plan - Model Details'!M548/10^6 -> -850.71281 | P22: =-'Business Plan - Model Details'!N548/10^6 -> -990.88117 | Q22: =-'Business Plan - Model Details'!O548/10^6 -> -1022.5894 | R22: =-'Business Plan - Model Details'!P548/10^6 -> -1055.0997 | S22: =-'Business Plan - Model Details'!Q548/10^6 -> -1156.699 | ... AI22: =-'Business Plan - Model Details'!AG548/10^6 -> -1045.3193 | AJ22: =SUM(X22:AI22) -> -12543.921
E23: Material - Others | H23: Rp m | I23: =IFERROR((K23-J23)/J23,0) -> 0 | K23: =SUM(L23:W23) -> -2748.1447 | L23: =-'Business Plan - Model Details'!J549/10^6 -> -245.82993 | M23: =-'Business Plan - Model Details'!K549/10^6 -> -186.81427 | N23: =-'Business Plan - Model Details'!L549/10^6 -> -143.26362 | O23: =-'Business Plan - Model Details'!M549/10^6 -> -169.81064 | P23: =-'Business Plan - Model Details'!N549/10^6 -> -250.9403 | Q23: =-'Business Plan - Model Details'!O549/10^6 -> -279.23552 | R23: =-'Business Plan - Model Details'!P549/10^6 -> -212.87493 | S23: =-'Business Plan - Model Details'!Q549/10^6 -> -286.68646 | ... AI23: =-'Business Plan - Model Details'!AG549/10^6 -> -237.45304 | AJ23: =SUM(X23:AI23) -> -2853.5178
E24: Upah Kupas | H24: Rp m | I24: =IFERROR((K24-J24)/J24,0) -> 0 | K24: =SUM(L24:W24) -> -1996.8395 | L24: =-'Business Plan - Model Details'!J550/10^6 -> -219.60534 | M24: =-'Business Plan - Model Details'!K550/10^6 -> -196.80334 | N24: =-'Business Plan - Model Details'!L550/10^6 -> -152.87413 | O24: =-'Business Plan - Model Details'!M550/10^6 -> -144.32887 | P24: =-'Business Plan - Model Details'!N550/10^6 -> -173.63913 | Q24: =-'Business Plan - Model Details'!O550/10^6 -> -174.7875 | R24: =-'Business Plan - Model Details'!P550/10^6 -> -155.36244 | S24: =-'Business Plan - Model Details'!Q550/10^6 -> -110.02163 | ... AI24: =-'Business Plan - Model Details'!AG550/10^6 -> -167.34267 | AJ24: =SUM(X24:AI24) -> -2008.1276
E25: Direct Labour | H25: Rp m | I25: =IFERROR((K25-J25)/J25,0) -> 0 | K25: =SUM(L25:W25) -> -9371.5494 | L25: =-'Business Plan - Model Details'!J551/10^6 -> -763.22929 | M25: =-'Business Plan - Model Details'!K551/10^6 -> -659.60587 | N25: =-'Business Plan - Model Details'!L551/10^6 -> -511.70588 | O25: =-'Business Plan - Model Details'!M551/10^6 -> -783.73635 | P25: =-'Business Plan - Model Details'!N551/10^6 -> -816.78222 | Q25: =-'Business Plan - Model Details'!O551/10^6 -> -799.59033 | R25: =-'Business Plan - Model Details'!P551/10^6 -> -838.00403 | S25: =-'Business Plan - Model Details'!Q551/10^6 -> -837.03787 | ... AI25: =-'Business Plan - Model Details'!AG551/10^6 -> -840.43914 | AJ25: =SUM(X25:AI25) -> -10085.254
E26: Factory overhead | H26: Rp m | I26: =IFERROR((K26-J26)/J26,0) -> 0 | K26: =SUM(L26:W26) -> -8196.9501 | L26: =-'Business Plan - Model Details'!J552/10^6 -> -698.17042 | M26: =-'Business Plan - Model Details'!K552/10^6 -> -778.1585 | N26: =-'Business Plan - Model Details'!L552/10^6 -> -832.79144 | O26: =-'Business Plan - Model Details'!M552/10^6 -> -828.57457 | P26: =-'Business Plan - Model Details'!N552/10^6 -> -619.15107 | Q26: =-'Business Plan - Model Details'!O552/10^6 -> -599.52042 | R26: =-'Business Plan - Model Details'!P552/10^6 -> -625.8779 | S26: =-'Business Plan - Model Details'!Q552/10^6 -> -581.30169 | ... AI26: =-'Business Plan - Model Details'!AG552/10^6 -> -642.52648 | AJ26: =SUM(X26:AI26) -> -7759.4607
D27: Inventory Movement
E28: KW 2 | H28: Rp m | I28: =IFERROR((K28-J28)/J28,0) -> 0 | K28: =SUM(L28:W28) -> 433.84386 | L28: =-'Business Plan - Model Details'!J555/10^6 -> 0 | M28: =-'Business Plan - Model Details'!K555/10^6 -> 0 | N28: =-'Business Plan - Model Details'!L555/10^6 -> 0 | O28: =-'Business Plan - Model Details'!M555/10^6 -> 0 | P28: =-'Business Plan - Model Details'!N555/10^6 -> 0 | Q28: =-'Business Plan - Model Details'!O555/10^6 -> 0 | R28: =-'Business Plan - Model Details'!P555/10^6 -> 0 | S28: =-'Business Plan - Model Details'!Q555/10^6 -> 0 | ... AI28: =-'Business Plan - Model Details'!AG555/10^6 -> 111.90126
E29: WIP - Beginnig Balance | H29: Rp m | I29: =IFERROR((K29-J29)/J29,0) -> 0 | K29: =SUM(L29:W29) -> -34.115454 | L29: =-'Business Plan - Model Details'!J558/10^6 -> 0 | M29: =-'Business Plan - Model Details'!K558/10^6 -> 0 | N29: =-'Business Plan - Model Details'!L558/10^6 -> 0 | O29: =-'Business Plan - Model Details'!M558/10^6 -> 0 | P29: =-'Business Plan - Model Details'!N558/10^6 -> 0 | Q29: =-'Business Plan - Model Details'!O558/10^6 -> 0 | R29: =-'Business Plan - Model Details'!P558/10^6 -> 0 | S29: =-'Business Plan - Model Details'!Q558/10^6 -> 0 | ... AI29: =-'Business Plan - Model Details'!AG558/10^6 -> -8.9797962
E30: WIP - Ending Balance | H30: Rp m | I30: =IFERROR((K30-J30)/J30,0) -> 0 | K30: =SUM(L30:W30) -> 35.713741 | L30: =-'Business Plan - Model Details'!J559/10^6 -> 0 | M30: =-'Business Plan - Model Details'!K559/10^6 -> 0 | N30: =-'Business Plan - Model Details'!L559/10^6 -> 0 | O30: =-'Business Plan - Model Details'!M559/10^6 -> 0 | P30: =-'Business Plan - Model Details'!N559/10^6 -> 0 | Q30: =-'Business Plan - Model Details'!O559/10^6 -> 0 | R30: =-'Business Plan - Model Details'!P559/10^6 -> 0 | S30: =-'Business Plan - Model Details'!Q559/10^6 -> 0 | ... AI30: =-'Business Plan - Model Details'!AG559/10^6 -> 8.9788181 | AJ30: =SUM(X30:AI30) -> 107.82017
E31: FG - Beginnig Balance | H31: Rp m | I31: =IFERROR((K31-J31)/J31,0) -> 0 | K31: =SUM(L31:W31) -> -669.97107 | L31: =-'Business Plan - Model Details'!J561/10^6 -> 0 | M31: =-'Business Plan - Model Details'!K561/10^6 -> 0 | N31: =-'Business Plan - Model Details'!L561/10^6 -> 0 | O31: =-'Business Plan - Model Details'!M561/10^6 -> 0 | P31: =-'Business Plan - Model Details'!N561/10^6 -> 0 | Q31: =-'Business Plan - Model Details'!O561/10^6 -> 0 | R31: =-'Business Plan - Model Details'!P561/10^6 -> 0 | S31: =-'Business Plan - Model Details'!Q561/10^6 -> 0 | ... AI31: =-'Business Plan - Model Details'!AG561/10^6 -> -176.55683 | AJ31: =SUM(X31:AI31) -> -2120.3507
E32: FG - Ending Balance | H32: Rp m | I32: =IFERROR((K32-J32)/J32,0) -> 0 | K32: =SUM(L32:W32) -> 701.39367 | L32: =-'Business Plan - Model Details'!J562/10^6 -> 0 | M32: =-'Business Plan - Model Details'!K562/10^6 -> 0 | N32: =-'Business Plan - Model Details'!L562/10^6 -> 0 | O32: =-'Business Plan - Model Details'!M562/10^6 -> 0 | P32: =-'Business Plan - Model Details'!N562/10^6 -> 0 | Q32: =-'Business Plan - Model Details'!O562/10^6 -> 0 | R32: =-'Business Plan - Model Details'!P562/10^6 -> 0 | S32: =-'Business Plan - Model Details'!Q562/10^6 -> 0 | ... AI32: =-'Business Plan - Model Details'!AG562/10^6 -> 176.53786 | AJ32: =SUM(X32:AI32) -> 2119.9213
C33: Ubi Ungu | H33: Rp m | I33: =IFERROR((K33-J33)/J33,0) -> 0 | K33: =SUM(L33:W33) -> -2951.3293 | L33: =SUM(L34:L41,L43:L47) -> -132.00802 | M33: =SUM(M34:M41,M43:M47) -> -88.08396 | N33: =SUM(N34:N41,N43:N47) -> -44.795944 | O33: =SUM(O34:O41,O43:O47) -> -253.58468 | P33: =SUM(P34:P41,P43:P47) -> -204.31368 | Q33: =SUM(Q34:Q41,Q43:Q47) -> -570.04226 | R33: =SUM(R34:R41,R43:R47) -> -325.14223 | S33: =SUM(S34:S41,S43:S47) -> -458.97133 | ... AI33: =SUM(AI34:AI41,AI43:AI47) -> -223.11707
D34: Manufacturing Cost
E35: Raw Materials | H35: Rp m | I35: =IFERROR((K35-J35)/J35,0) -> 0 | K35: =SUM(L35:W35) -> -1525.4028 | L35: =-'Business Plan - Model Details'!J702/10^6 -> -79.040705 | M35: =-'Business Plan - Model Details'!K702/10^6 -> -37.301 | N35: =-'Business Plan - Model Details'!L702/10^6 -> -23.689 | O35: =-'Business Plan - Model Details'!M702/10^6 -> -113.007 | P35: =-'Business Plan - Model Details'!N702/10^6 -> -102.14103 | Q35: =-'Business Plan - Model Details'!O702/10^6 -> -299.01619 | R35: =-'Business Plan - Model Details'!P702/10^6 -> -147.2659 | S35: =-'Business Plan - Model Details'!Q702/10^6 -> -246.3404 | ... AI35: =-'Business Plan - Model Details'!AG702/10^6 -> -119.4004 | AJ35: =SUM(X35:AI35) -> -1432.8048
E36: OIL | H36: Rp m | I36: =IFERROR((K36-J36)/J36,0) -> 0 | K36: =SUM(L36:W36) -> -521.24658 | L36: =-'Business Plan - Model Details'!J703/10^6 -> -5.9840709 | M36: =-'Business Plan - Model Details'!K703/10^6 -> -13.430525 | N36: =-'Business Plan - Model Details'!L703/10^6 -> -6.4167984 | O36: =-'Business Plan - Model Details'!M703/10^6 -> -46.75069 | P36: =-'Business Plan - Model Details'!N703/10^6 -> -35.684648 | Q36: =-'Business Plan - Model Details'!O703/10^6 -> -105.40289 | R36: =-'Business Plan - Model Details'!P703/10^6 -> -63.822502 | S36: =-'Business Plan - Model Details'!Q703/10^6 -> -71.810529 | ... AI36: =-'Business Plan - Model Details'!AG703/10^6 -> -42.968582
E37: CNG | H37: Rp m | I37: =IFERROR((K37-J37)/J37,0) -> 0 | K37: =SUM(L37:W37) -> -333.76307 | L37: =-'Business Plan - Model Details'!J704/10^6 -> 0 | M37: =-'Business Plan - Model Details'!K704/10^6 -> -10.624045 | N37: =-'Business Plan - Model Details'!L704/10^6 -> -4.2868911 | O37: =-'Business Plan - Model Details'!M704/10^6 -> -29.843052 | P37: =-'Business Plan - Model Details'!N704/10^6 -> -20.710968 | Q37: =-'Business Plan - Model Details'!O704/10^6 -> -62.27375 | R37: =-'Business Plan - Model Details'!P704/10^6 -> -41.031715 | S37: =-'Business Plan - Model Details'!Q704/10^6 -> -51.763471 | ... AI37: =-'Business Plan - Model Details'!AG704/10^6 -> -28.307295 | AJ37: =SUM(X37:AI37) -> -339.68754
E38: Material - Others | H38: Rp m | I38: =IFERROR((K38-J38)/J38,0) -> 0 | K38: =SUM(L38:W38) -> -54.996534 | L38: =-'Business Plan - Model Details'!J705/10^6 -> -0.37099799 | M38: =-'Business Plan - Model Details'!K705/10^6 -> -1.3249985 | N38: =-'Business Plan - Model Details'!L705/10^6 -> -0.6095 | O38: =-'Business Plan - Model Details'!M705/10^6 -> -3.0061594 | P38: =-'Business Plan - Model Details'!N705/10^6 -> -3.7565251 | Q38: =-'Business Plan - Model Details'!O705/10^6 -> -11.554204 | R38: =-'Business Plan - Model Details'!P705/10^6 -> -7.6002766 | S38: =-'Business Plan - Model Details'!Q705/10^6 -> -9.1148042 | ... AI38: =-'Business Plan - Model Details'!AG705/10^6 -> -4.360556 | AJ38: =SUM(X38:AI38) -> -52.340547
E39: Upah Kupas | H39: Rp m | I39: =IFERROR((K39-J39)/J39,0) -> 0 | K39: =SUM(L39:W39) -> 0 | L39: =-'Business Plan - Model Details'!J706/10^6 -> 0 | M39: =-'Business Plan - Model Details'!K706/10^6 -> 0 | N39: =-'Business Plan - Model Details'!L706/10^6 -> 0 | O39: =-'Business Plan - Model Details'!M706/10^6 -> 0 | P39: =-'Business Plan - Model Details'!N706/10^6 -> 0 | Q39: =-'Business Plan - Model Details'!O706/10^6 -> 0 | R39: =-'Business Plan - Model Details'!P706/10^6 -> 0 | S39: =-'Business Plan - Model Details'!Q706/10^6 -> 0 | ... AI39: =-'Business Plan - Model Details'!AG706/10^6 -> 0 | AJ39: =SUM(X39:AI39) -> 0
E40: Direct Labour | H40: Rp m | I40: =IFERROR((K40-J40)/J40,0) -> 0 | K40: =SUM(L40:W40) -> -322.78674 | L40: =-'Business Plan - Model Details'!J707/10^6 -> -21.68941 | M40: =-'Business Plan - Model Details'!K707/10^6 -> -11.358265 | N40: =-'Business Plan - Model Details'!L707/10^6 -> -4.5351858 | O40: =-'Business Plan - Model Details'!M707/10^6 -> -30.206963 | P40: =-'Business Plan - Model Details'!N707/10^6 -> -27.248602 | Q40: =-'Business Plan - Model Details'!O707/10^6 -> -61.897409 | R40: =-'Business Plan - Model Details'!P707/10^6 -> -39.027989 | S40: =-'Business Plan - Model Details'!Q707/10^6 -> -54.419153 | ... AI40: =-'Business Plan - Model Details'!AG707/10^6 -> -18.101547 | AJ40: =SUM(X40:AI40) -> -217.21667
...

Sheet Business Plan - Model Details
A1: PT Boga Makmur Gracia
A2: Business Plan
A3: Oct 2026 to Dec 2027 | J3: Actual | K3: Actual | L3: Actual | M3: Actual | N3: Actual | O3: Actual | P3: Actual | Q3: Actual
I4: Unit | J4: 46053 | K4: =EOMONTH(J4,1) -> 46081 | L4: =EOMONTH(K4,1) -> 46112 | M4: =EOMONTH(L4,1) -> 46142 | N4: =EOMONTH(M4,1) -> 46173 | O4: =EOMONTH(N4,1) -> 46203 | P4: =EOMONTH(O4,1) -> 46234 | Q4: =EOMONTH(P4,1) -> 46265 | R4: =EOMONTH(Q4,1) -> 46295 | ... AG4: =EOMONTH(AF4,1) -> 46752
A6: 1 | B6: General assumptions
B8: 1.1 | C8: Macroeconomics
C9: Inflation rate | I9: % yoy | R9: 0 | S9: 0 | T9: 0 | U9: 0 | V9: 0 | W9: 0 | X9: 0 | Y9: 0 | Z9: 0 | AA9: 0 | AB9: 0 | AC9: 0 | AD9: 0 | AE9: 0 | AF9: 0 | AG9: 0
C10: Index | I10: x | R10: =(1+R9)^(1/12) -> 1 | S10: =R10*(1+S9)^(1/12) -> 1 | T10: =S10*(1+T9)^(1/12) -> 1 | U10: =T10*(1+U9)^(1/12) -> 1 | V10: =U10*(1+V9)^(1/12) -> 1 | W10: =V10*(1+W9)^(1/12) -> 1 | X10: =W10*(1+X9)^(1/12) -> 1 | Y10: =X10*(1+Y9)^(1/12) -> 1 | Z10: =Y10*(1+Z9)^(1/12) -> 1 | ... AG10: =AF10*(1+AG9)^(1/12) -> 1
C11: Minimum Wage adjustment | I11: % yoy | R11: 0 | S11: 0 | T11: 0 | U11: 0 | V11: 0 | W11: 0 | X11: 0 | Y11: 0 | Z11: 0 | AA11: 0 | AB11: 0 | AC11: 0 | AD11: 0 | AE11: 0 | AF11: 0 | AG11: 0
C12: Combined wage adjustment | D12: Indeks upah (kumulatif dari Minimum Wage adjustment, basis Agu-26 = 1) | I12: x | R12: =(1+R11)^(1/12) -> 1 | S12: =R12*(1+S11)^(1/12) -> 1 | T12: =S12*(1+T11)^(1/12) -> 1 | U12: =T12*(1+U11)^(1/12) -> 1 | V12: =U12*(1+V11)^(1/12) -> 1 | W12: =V12*(1+W11)^(1/12) -> 1 | X12: =W12*(1+X11)^(1/12) -> 1 | Y12: =X12*(1+Y11)^(1/12) -> 1 | Z12: =Y12*(1+Z11)^(1/12) -> 1 | ... AG12: =AF12*(1+AG11)^(1/12) -> 1
C13: IDR to USD | I13: IDR | J13: 16786 | K13: 16758 | L13: 16993 | M13: 17324 | N13: 17789 | O13: 17856 | P13: 18078 | Q13: 17703 | R13: ='Input Operasional'!Q156 -> 18000 | S13: ='Input Operasional'!R156 -> 18000 | T13: ='Input Operasional'!S156 -> 18000 | U13: ='Input Operasional'!T156 -> 18000 | V13: ='Input Operasional'!U156 -> 18000 | W13: ='Input Operasional'!V156 -> 18000 | X13: ='Input Operasional'!W156 -> 18000 | Y13: ='Input Operasional'!X156 -> 18000 | ... AG13: ='Input Operasional'!AF156 -> 18000
B15: 1.2 | C15: Growth Assumption
C16: Revenue growth target | I16: % yoy | AC16: 0.045 | AD16: 0.045 | AE16: 0.045 | AF16: 0.045 | AG16: 0.045
C17: Period x | I17: x year | AC17: 1 | AD17: 1 | AE17: 1 | AF17: 1 | AG17: 1
C18: Period cashflow (half period) | I18: x year | AC18: 2.5 | AD18: 3.5 | AE18: 4.5 | AF18: 5.5 | AG18: 6.5
C19: Month in period | I19: x month | AC19: 12 | AD19: 12 | AE19: 12 | AF19: 12 | AG19: 12
A21: 2 | B21: Operational assumptions
B23: 2.1 | C23: Operational Days
C24: Total Days | I24: Days | J24: =DAY(J4) -> 31 | K24: =DAY(K4) -> 28 | L24: =DAY(L4) -> 31 | M24: =DAY(M4) -> 30 | N24: =DAY(N4) -> 31 | O24: =DAY(O4) -> 30 | P24: =DAY(P4) -> 31 | Q24: =DAY(Q4) -> 31 | ... AG24: =DAY(AG4) -> 31
C25: Holidays | I25: Days | J25: 4 | K25: 4 | L25: 4 | M25: 4 | N25: 4 | O25: 4 | P25: 4 | Q25: 4 | R25: ='Input Operasional'!Q157 -> 4 | S25: ='Input Operasional'!R157 -> 4 | T25: ='Input Operasional'!S157 -> 4 | U25: ='Input Operasional'!T157 -> 4 | V25: ='Input Operasional'!U157 -> 4 | W25: ='Input Operasional'!V157 -> 4 | X25: ='Input Operasional'!W157 -> 4 | Y25: ='Input Operasional'!X157 -> 4 | ... AG25: ='Input Operasional'!AF157 -> 4
C26: Production Days | I26: Days | J26: =J24-J25 -> 27 | K26: =K24-K25 -> 24 | L26: =L24-L25 -> 27 | M26: =M24-M25 -> 26 | N26: =N24-N25 -> 27 | O26: =O24-O25 -> 26 | P26: =P24-P25 -> 27 | Q26: =Q24-Q25 -> 27 | ... AG26: =AG24-AG25 -> 27
B28: 2.2 | C28: Production Capacity/Days
C29: Washing | I29: KG - Wet | J29: 48000 | K29: 48000 | L29: 48000 | M29: 48000 | N29: 48000 | O29: 48000 | P29: 48000 | Q29: 48000 | R29: ='Input Operasional'!Q158 -> 48000 | S29: ='Input Operasional'!R158 -> 48000 | T29: ='Input Operasional'!S158 -> 48000 | U29: ='Input Operasional'!T158 -> 48000 | V29: ='Input Operasional'!U158 -> 48000 | W29: ='Input Operasional'!V158 -> 48000 | X29: ='Input Operasional'!W158 -> 48000 | Y29: ='Input Operasional'!X158 -> 48000 | ... AG29: ='Input Operasional'!AF158 -> 48000
C30: Slicing | I30: KG - Wet | J30: =J29 -> 48000 | K30: =K29 -> 48000 | L30: =L29 -> 48000 | M30: =M29 -> 48000 | N30: =N29 -> 48000 | O30: =O29 -> 48000 | P30: =P29 -> 48000 | Q30: =Q29 -> 48000 | ... AG30: =AG29 -> 48000
C31: Fyring | I31: KG - Dry | J31: =J30/3.33 -> 14414.414 | K31: =K30/3.33 -> 14414.414 | L31: =L30/3.33 -> 14414.414 | M31: =M30/3.33 -> 14414.414 | N31: =N30/3.33 -> 14414.414 | O31: =O30/3.33 -> 14414.414 | P31: =P30/3.33 -> 14414.414 | Q31: =Q30/3.33 -> 14414.414 | ... AG31: =AG30/3.33 -> 14414.414
B33: 2.4 | C33: Production Capacity/Month
C34: Washing | I34: Ton - Wet | J34: =J26*J29/10^3 -> 1296 | K34: =K36*3.3 -> 1141.6216 | L34: =L36*3.3 -> 1284.3243 | M34: =M36*3.3 -> 1236.7568 | N34: =N36*3.3 -> 1284.3243 | O34: =O36*3.3 -> 1236.7568 | P34: =P36*3.3 -> 1284.3243 | Q34: =Q36*3.3 -> 1284.3243 | R34: =R36*3.3 -> 1236.7568 | ... AG34: =AG36*3.3 -> 1284.3243
C35: Slicing | I35: Ton - Wet | J35: =J26*J30/10^3 -> 1296 | K35: =K34 -> 1141.6216 | L35: =L34 -> 1284.3243 | M35: =M34 -> 1236.7568 | N35: =N34 -> 1284.3243 | O35: =O34 -> 1236.7568 | P35: =P34 -> 1284.3243 | Q35: =Q34 -> 1284.3243 | R35: =R34 -> 1236.7568 | ... AG35: =AG34 -> 1284.3243
C36: Fyring | I36: Ton - Dry | J36: =J26*J31/10^3 -> 389.18919 | K36: =K26*K31/10^3 -> 345.94595 | L36: =L26*L31/10^3 -> 389.18919 | M36: =M26*M31/10^3 -> 374.77477 | N36: =N26*N31/10^3 -> 389.18919 | O36: =O26*O31/10^3 -> 374.77477 | P36: =P26*P31/10^3 -> 389.18919 | Q36: =Q26*Q31/10^3 -> 389.18919 | ... AG36: =AG26*AG31/10^3 -> 389.18919
B38: 2.4 | C38: Personal
C39: Washing | I39: People
C40: Slicing | I40: People
C41: Fyring | I41: People
B42: 2.5 | C42: Working Hours Mesin & Kapasitas dari Jam Operasi
C43: Jam operasi - Washing | I43: jam | J43: ='Data Aktual'!K43 -> 680 | K43: ='Data Aktual'!L43 -> 656 | L43: ='Data Aktual'!M43 -> 512 | M43: ='Data Aktual'!N43 -> 512 | N43: ='Data Aktual'!O43 -> 688 | O43: ='Data Aktual'!P43 -> 688 | P43: ='Data Aktual'!Q43 -> 688 | Q43: ='Data Aktual'!R43 -> 696 | R43: 632.5 | S43: 632.5 | T43: 632.5 | U43: 632.5 | V43: 632.5 | W43: 632.5 | X43: 632.5 | Y43: 632.5 | Z43: 632.5 | AA43: 632.5 | AB43: 632.5 | AC43: 632.5 | AD43: 632.5 | AE43: 632.5 | AF43: 632.5 | AG43: 632.5
C44: Jam operasi - Slicing | I44: jam | J44: ='Data Aktual'!K43 -> 680 | K44: ='Data Aktual'!L43 -> 656 | L44: ='Data Aktual'!M43 -> 512 | M44: ='Data Aktual'!N43 -> 512 | N44: ='Data Aktual'!O43 -> 688 | O44: ='Data Aktual'!P43 -> 688 | P44: ='Data Aktual'!Q43 -> 688 | Q44: ='Data Aktual'!R43 -> 696 | R44: 632.5 | S44: 632.5 | T44: 632.5 | U44: 632.5 | V44: 632.5 | W44: 632.5 | X44: 632.5 | Y44: 632.5 | Z44: 632.5 | AA44: 632.5 | AB44: 632.5 | AC44: 632.5 | AD44: 632.5 | AE44: 632.5 | AF44: 632.5 | AG44: 632.5
C45: Jam operasi - Frying (tahap penentu) | I45: jam | J45: ='Data Aktual'!K43 -> 680 | K45: ='Data Aktual'!L43 -> 656 | L45: ='Data Aktual'!M43 -> 512 | M45: ='Data Aktual'!N43 -> 512 | N45: ='Data Aktual'!O43 -> 688 | O45: ='Data Aktual'!P43 -> 688 | P45: ='Data Aktual'!Q43 -> 688 | Q45: ='Data Aktual'!R43 -> 696 | R45: 632.5 | S45: 632.5 | T45: 632.5 | U45: 632.5 | V45: 632.5 | W45: 632.5 | X45: 632.5 | Y45: 632.5 | Z45: 632.5 | AA45: 632.5 | AB45: 632.5 | AC45: 632.5 | AD45: 632.5 | AE45: 632.5 | AF45: 632.5 | AG45: 632.5
C46: Kapasitas per jam - Frying (kapasitas/hari baris 31 / jam operasi per hari) | I46: KG - Dry/jam | J46: 600.6006 | K46: 600.6006 | L46: 600.6006 | M46: 600.6006 | N46: 600.6006 | O46: 600.6006 | P46: 600.6006 | Q46: 600.6006 | R46: 600.6006 | S46: 600.6006 | T46: 600.6006 | U46: 600.6006 | V46: 600.6006 | W46: 600.6006 | X46: 600.6006 | Y46: 600.6006 | Z46: 600.6006 | AA46: 600.6006 | AB46: 600.6006 | AC46: 600.6006 | AD46: 600.6006 | AE46: 600.6006 | AF46: 600.6006 | AG46: 600.6006
C47: Kapasitas dari working hours - Frying (jam x kapasitas/jam) | I47: KG - Dry | J47: =J45*J46 -> 408408.41 | K47: =K45*K46 -> 393993.99 | L47: =L45*L46 -> 307507.51 | M47: =M45*M46 -> 307507.51 | N47: =N45*N46 -> 413213.21 | O47: =O45*O46 -> 413213.21 | P47: =P45*P46 -> 413213.21 | Q47: =Q45*Q46 -> 418018.02 | ... AG47: =AG45*AG46 -> 379879.88
C48: Total target volume produksi - 4 blok produk | I48: KG | J48: =J421+J582+J741+J892 -> 350705.13 | K48: =K421+K582+K741+K892 -> 343801.8 | L48: =L421+L582+L741+L892 -> 249392.6 | M48: =M421+M582+M741+M892 -> 259914.75 | N48: =N421+N582+N741+N892 -> 286092.5 | O48: =O421+O582+O741+O892 -> 309896.6 | P48: =P421+P582+P741+P892 -> 310829 | Q48: =Q421+Q582+Q741+Q892 -> 361606.5 | R48: =R421+R581+R741+R892 -> 305038.94 | S48: =S421+S581+S741+S892 -> 305544.12 | T48: =T421+T581+T741+T892 -> 304923.59 | U48: =U421+U581+U741+U892 -> 305168.64 | V48: =V421+V581+V741+V892 -> 305211.9 | W48: =W421+W581+W741+W892 -> 305101.32 | X48: =X421+X581+X741+X892 -> 305160.61 | Y48: =Y421+Y581+Y741+Y892 -> 305157.94 | ... AG48: =AG421+AG581+AG741+AG892 -> 305149.58
...

Sheet Register FA
A1: PT Boga Makmur Gracia
A2: Fixed Assets List
U5: 46053 | V5: 46081 | W5: 46112 | X5: 46142 | Y5: 46173 | Z5: 46203 | AA5: 46234 | AB5: 46265 | AG5: 46295 | AH5: 46326 | AI5: 46356 | AJ5: 46387 | AK5: 46418 | AL5: 46446 | AM5: 46477 | AN5: 46507 | AO5: 46538 | AP5: 46568 | AQ5: 46599 | AR5: 46630 | AS5: 46660 | AT5: 46691 | AU5: 46721 | AV5: 46752
A6: No | B6: Sheet sumber | C6: Baris sumber | D6: Kelas (mapping BS) | E6: Golongan | F6: Akun GL aset | G6: Akun GL akum. penyusutan | H6: Akun GL beban penyusutan | I6: Baris P&L Business Plan | J6: Kode | K6: Kode Accurate | L6: Tanggal perolehan | M6: Nama aset | N6: Keterangan | O6: Status | P6: Qty | Q6: Nilai perolehan (Rp) | R6: Umur (bulan) | S6: Depr/bulan register (Rp) | T6: Akum. penyusutan 31 Des 2025 (Rp) | U6: Aktual Jan-26 | V6: Aktual Feb-26 | W6: Aktual Mar-26 | X6: Aktual Apr-26 | Y6: Aktual May-26 | Z6: Aktual Jun-26 | AA6: Aktual Jul-26 | AB6: Aktual Aug-26 | AC6: Akum. penyusutan 31 Agu 2026 | AD6: Nilai buku 31 Agu 2026 | AE6: Depr/bulan berjalan (= Agu-26) | AF6: Sisa umur (bulan) | AG6: Proyeksi Sep-26 | AH6: Proyeksi Oct-26 | AI6: Proyeksi Nov-26 | AJ6: Proyeksi Dec-26 | AK6: Proyeksi Jan-27 | AL6: Proyeksi Feb-27 | AM6: Proyeksi Mar-27 | AN6: Proyeksi Apr-27 | AO6: Proyeksi May-27 | AP6: Proyeksi Jun-27 | AQ6: Proyeksi Jul-27 | AR6: Proyeksi Aug-27 | AS6: Proyeksi Sep-27 | AT6: Proyeksi Oct-27 | AU6: Proyeksi Nov-27 | AV6: Proyeksi Dec-27 | AW6: Total proyeksi Sep-26 s/d Des-27 | AX6: Nilai buku 31 Des 2027
A7: 1 | B7: FA Bangunan | C7: 8 | D7: Buildings | E7: Bangunan | F7: 1201-001 | G7: 1202-001 | H7: 6500-001 | I7: Depreciation Expenses | J7: BP.01/12 | K7: GD.0001 | L7: 41090 | M7: Pembangunan Parik Boja | N7: Bangun pabrik di Boja, Semarang | O7: Aktif | P7: 1 | Q7: 3175850457 | R7: 240 | S7: 13232710 | T7: 2.1569318e+09 | U7: 13232710 | V7: 13232710 | W7: 13232710 | X7: 13232710 | Y7: 13232710 | Z7: 13232710 | AA7: 13232710 | AB7: 13232710 | AC7: =T7+SUM(U7:AB7) -> 2.2627935e+09 | AD7: =Q7-AC7 -> 9.1305701e+08 | AE7: =IF(O7="Aktif",AB7,0) -> 13232710 | AF7: =IF(AE7>0,MAX(0,AD7)/AE7,0) -> 69 | AG7: =IF($O7="Aktif",MAX(0,MIN($AE7,$AD7-0)),0) -> 13232710 | AH7: =IF($O7="Aktif",MAX(0,MIN($AE7,$AD7-SUM($AG7:AG7))),0) -> 13232710 | AI7: =IF($O7="Aktif",MAX(0,MIN($AE7,$AD7-SUM($AG7:AH7))),0) -> 13232710 | AJ7: =IF($O7="Aktif",MAX(0,MIN($AE7,$AD7-SUM($AG7:AI7))),0) -> 13232710 | AK7: =IF($O7="Aktif",MAX(0,MIN($AE7,$AD7-SUM($AG7:AJ7))),0) -> 13232710 | AL7: =IF($O7="Aktif",MAX(0,MIN($AE7,$AD7-SUM($AG7:AK7))),0) -> 13232710 | AM7: =IF($O7="Aktif",MAX(0,MIN($AE7,$AD7-SUM($AG7:AL7))),0) -> 13232710 | AN7: =IF($O7="Aktif",MAX(0,MIN($AE7,$AD7-SUM($AG7:AM7))),0) -> 13232710 | AO7: =IF($O7="Aktif",MAX(0,MIN($AE7,$AD7-SUM($AG7:AN7))),0) -> 13232710 | ... AV7: =IF($O7="Aktif",MAX(0,MIN($AE7,$AD7-SUM($AG7:AU7))),0) -> 13232710 | AW7: =SUM(AG7:AV7) -> 2.1172336e+08 | AX7: =AD7-AW7 -> 7.0133364e+08
A8: 2 | B8: FA Bangunan | C8: 9 | D8: Buildings | E8: Bangunan | F8: 1201-001 | G8: 1202-001 | H8: 6500-001 | I8: Depreciation Expenses | J8: BP.01/14 | K8: GD.0002 | L8: 41820 | M8: Pembangunan Gedung Pabrik Semarang | N8: Pembangunan gedung pabrik SMG (termasuk pagar dan jalan baru) | O8: Aktif | P8: 1 | Q8: 2649000000 | R8: 240 | S8: 11037500 | T8: 1534212500 | U8: 11037500 | V8: 11037500 | W8: 11037500 | X8: 11037500 | Y8: 11037500 | Z8: 11037500 | AA8: 11037500 | AB8: 11037500 | AC8: =T8+SUM(U8:AB8) -> 1622512500 | AD8: =Q8-AC8 -> 1026487500 | AE8: =IF(O8="Aktif",AB8,0) -> 11037500 | AF8: =IF(AE8>0,MAX(0,AD8)/AE8,0) -> 93 | AG8: =IF($O8="Aktif",MAX(0,MIN($AE8,$AD8-0)),0) -> 11037500 | AH8: =IF($O8="Aktif",MAX(0,MIN($AE8,$AD8-SUM($AG8:AG8))),0) -> 11037500 | AI8: =IF($O8="Aktif",MAX(0,MIN($AE8,$AD8-SUM($AG8:AH8))),0) -> 11037500 | AJ8: =IF($O8="Aktif",MAX(0,MIN($AE8,$AD8-SUM($AG8:AI8))),0) -> 11037500 | AK8: =IF($O8="Aktif",MAX(0,MIN($AE8,$AD8-SUM($AG8:AJ8))),0) -> 11037500 | AL8: =IF($O8="Aktif",MAX(0,MIN($AE8,$AD8-SUM($AG8:AK8))),0) -> 11037500 | AM8: =IF($O8="Aktif",MAX(0,MIN($AE8,$AD8-SUM($AG8:AL8))),0) -> 11037500 | AN8: =IF($O8="Aktif",MAX(0,MIN($AE8,$AD8-SUM($AG8:AM8))),0) -> 11037500 | AO8: =IF($O8="Aktif",MAX(0,MIN($AE8,$AD8-SUM($AG8:AN8))),0) -> 11037500 | ... AV8: =IF($O8="Aktif",MAX(0,MIN($AE8,$AD8-SUM($AG8:AU8))),0) -> 11037500 | AW8: =SUM(AG8:AV8) -> 176600000 | AX8: =AD8-AW8 -> 849887500
A9: 3 | B9: FA Bangunan | C9: 10 | D9: Buildings | E9: Bangunan | F9: 1201-001 | G9: 1202-001 | H9: 6500-001 | I9: Depreciation Expenses | J9: BP.01/16 | K9: GD.0003 | L9: 42582 | M9: Pembangunan Gudang Boja Tahap 3 | N9: Pembangunan Perluasan Gudang Boja Tahap III | O9: Aktif | P9: 1 | Q9: 5353400000 | R9: 240 | S9: 22305833 | T9: 2.542865e+09 | U9: 22305833 | V9: 22305833 | W9: 22305833 | X9: 22305833 | Y9: 22305833 | Z9: 22305833 | AA9: 22305833 | AB9: 22305833 | AC9: =T9+SUM(U9:AB9) -> 2.7213117e+09 | AD9: =Q9-AC9 -> 2.6320883e+09 | AE9: =IF(O9="Aktif",AB9,0) -> 22305833 | AF9: =IF(AE9>0,MAX(0,AD9)/AE9,0) -> 118 | AG9: =IF($O9="Aktif",MAX(0,MIN($AE9,$AD9-0)),0) -> 22305833 | AH9: =IF($O9="Aktif",MAX(0,MIN($AE9,$AD9-SUM($AG9:AG9))),0) -> 22305833 | AI9: =IF($O9="Aktif",MAX(0,MIN($AE9,$AD9-SUM($AG9:AH9))),0) -> 22305833 | AJ9: =IF($O9="Aktif",MAX(0,MIN($AE9,$AD9-SUM($AG9:AI9))),0) -> 22305833 | AK9: =IF($O9="Aktif",MAX(0,MIN($AE9,$AD9-SUM($AG9:AJ9))),0) -> 22305833 | AL9: =IF($O9="Aktif",MAX(0,MIN($AE9,$AD9-SUM($AG9:AK9))),0) -> 22305833 | AM9: =IF($O9="Aktif",MAX(0,MIN($AE9,$AD9-SUM($AG9:AL9))),0) -> 22305833 | AN9: =IF($O9="Aktif",MAX(0,MIN($AE9,$AD9-SUM($AG9:AM9))),0) -> 22305833 | AO9: =IF($O9="Aktif",MAX(0,MIN($AE9,$AD9-SUM($AG9:AN9))),0) -> 22305833 | ... AV9: =IF($O9="Aktif",MAX(0,MIN($AE9,$AD9-SUM($AG9:AU9))),0) -> 22305833 | AW9: =SUM(AG9:AV9) -> 3.5689333e+08 | AX9: =AD9-AW9 -> 2.275195e+09
A10: 4 | B10: FA Bangunan | C10: 11 | D10: Buildings | E10: Bangunan | F10: 1201-001 | G10: 1202-001 | H10: 6500-001 | I10: Depreciation Expenses | J10: BP.01/18 | K10: GD.0004 | L10: 43131 | M10: Instalansi Gas, Minyak, Dan Air | N10: Instalansi gas, minyak, dan air,menunjang produksi Singkong serut di unit 4 | O10: Aktif | P10: 1 | Q10: 85470000 | R10: 240 | S10: 356125 | T10: 34188000 | U10: 356125 | V10: 356125 | W10: 356125 | X10: 356125 | Y10: 356125 | Z10: 356125 | AA10: 356125 | AB10: 356125 | AC10: =T10+SUM(U10:AB10) -> 37037000 | AD10: =Q10-AC10 -> 48433000 | AE10: =IF(O10="Aktif",AB10,0) -> 356125 | AF10: =IF(AE10>0,MAX(0,AD10)/AE10,0) -> 136 | AG10: =IF($O10="Aktif",MAX(0,MIN($AE10,$AD10-0)),0) -> 356125 | AH10: =IF($O10="Aktif",MAX(0,MIN($AE10,$AD10-SUM($AG10:AG10))),0) -> 356125 | AI10: =IF($O10="Aktif",MAX(0,MIN($AE10,$AD10-SUM($AG10:AH10))),0) -> 356125 | AJ10: =IF($O10="Aktif",MAX(0,MIN($AE10,$AD10-SUM($AG10:AI10))),0) -> 356125 | AK10: =IF($O10="Aktif",MAX(0,MIN($AE10,$AD10-SUM($AG10:AJ10))),0) -> 356125 | AL10: =IF($O10="Aktif",MAX(0,MIN($AE10,$AD10-SUM($AG10:AK10))),0) -> 356125 | AM10: =IF($O10="Aktif",MAX(0,MIN($AE10,$AD10-SUM($AG10:AL10))),0) -> 356125 | AN10: =IF($O10="Aktif",MAX(0,MIN($AE10,$AD10-SUM($AG10:AM10))),0) -> 356125 | AO10: =IF($O10="Aktif",MAX(0,MIN($AE10,$AD10-SUM($AG10:AN10))),0) -> 356125 | ... AV10: =IF($O10="Aktif",MAX(0,MIN($AE10,$AD10-SUM($AG10:AU10))),0) -> 356125 | AW10: =SUM(AG10:AV10) -> 5698000 | AX10: =AD10-AW10 -> 42735000
A11: 5 | B11: FA Bangunan | C11: 12 | D11: Buildings | E11: Bangunan | F11: 1201-001 | G11: 1202-001 | H11: 6500-001 | I11: Depreciation Expenses | J11: BP.02/18 | K11: GD.0005 | L11: 43131 | M11: Atap Area Hois & Area Rendam | N11: Atap area Hois & area rendam | O11: Aktif | P11: 1 | Q11: 230000000 | R11: 240 | S11: 958333.33 | T11: 92000000 | U11: 958333.33 | V11: 958333.33 | W11: 958333.33 | X11: 958333.33 | Y11: 958333.33 | Z11: 958333.33 | AA11: 958333.33 | AB11: 958333.33 | AC11: =T11+SUM(U11:AB11) -> 99666667 | AD11: =Q11-AC11 -> 1.3033333e+08 | AE11: =IF(O11="Aktif",AB11,0) -> 958333.33 | AF11: =IF(AE11>0,MAX(0,AD11)/AE11,0) -> 136 | AG11: =IF($O11="Aktif",MAX(0,MIN($AE11,$AD11-0)),0) -> 958333.33 | AH11: =IF($O11="Aktif",MAX(0,MIN($AE11,$AD11-SUM($AG11:AG11))),0) -> 958333.33 | AI11: =IF($O11="Aktif",MAX(0,MIN($AE11,$AD11-SUM($AG11:AH11))),0) -> 958333.33 | AJ11: =IF($O11="Aktif",MAX(0,MIN($AE11,$AD11-SUM($AG11:AI11))),0) -> 958333.33 | AK11: =IF($O11="Aktif",MAX(0,MIN($AE11,$AD11-SUM($AG11:AJ11))),0) -> 958333.33 | AL11: =IF($O11="Aktif",MAX(0,MIN($AE11,$AD11-SUM($AG11:AK11))),0) -> 958333.33 | AM11: =IF($O11="Aktif",MAX(0,MIN($AE11,$AD11-SUM($AG11:AL11))),0) -> 958333.33 | AN11: =IF($O11="Aktif",MAX(0,MIN($AE11,$AD11-SUM($AG11:AM11))),0) -> 958333.33 | AO11: =IF($O11="Aktif",MAX(0,MIN($AE11,$AD11-SUM($AG11:AN11))),0) -> 958333.33 | ... AV11: =IF($O11="Aktif",MAX(0,MIN($AE11,$AD11-SUM($AG11:AU11))),0) -> 958333.33 | AW11: =SUM(AG11:AV11) -> 15333333 | AX11: =AD11-AW11 -> 1.15e+08
A12: 6 | B12: FA Bangunan | C12: 13 | D12: Buildings | E12: Bangunan | F12: 1201-001 | G12: 1202-001 | H12: 6500-001 | I12: Depreciation Expenses | J12: BP.03/18 | K12: GD.0006 | L12: 43131 | M12: Pekerjaan Atap Dan Pagar Area Kupas | N12: Pekerjaan Atap dan pagar area kupas | O12: Aktif | P12: 1 | Q12: 96000000 | R12: 240 | S12: 400000 | T12: 38400000 | U12: 400000 | V12: 400000 | W12: 400000 | X12: 400000 | Y12: 400000 | Z12: 400000 | AA12: 400000 | AB12: 400000 | AC12: =T12+SUM(U12:AB12) -> 41600000 | AD12: =Q12-AC12 -> 54400000 | AE12: =IF(O12="Aktif",AB12,0) -> 400000 | AF12: =IF(AE12>0,MAX(0,AD12)/AE12,0) -> 136 | AG12: =IF($O12="Aktif",MAX(0,MIN($AE12,$AD12-0)),0) -> 400000 | AH12: =IF($O12="Aktif",MAX(0,MIN($AE12,$AD12-SUM($AG12:AG12))),0) -> 400000 | AI12: =IF($O12="Aktif",MAX(0,MIN($AE12,$AD12-SUM($AG12:AH12))),0) -> 400000 | AJ12: =IF($O12="Aktif",MAX(0,MIN($AE12,$AD12-SUM($AG12:AI12))),0) -> 400000 | AK12: =IF($O12="Aktif",MAX(0,MIN($AE12,$AD12-SUM($AG12:AJ12))),0) -> 400000 | AL12: =IF($O12="Aktif",MAX(0,MIN($AE12,$AD12-SUM($AG12:AK12))),0) -> 400000 | AM12: =IF($O12="Aktif",MAX(0,MIN($AE12,$AD12-SUM($AG12:AL12))),0) -> 400000 | AN12: =IF($O12="Aktif",MAX(0,MIN($AE12,$AD12-SUM($AG12:AM12))),0) -> 400000 | AO12: =IF($O12="Aktif",MAX(0,MIN($AE12,$AD12-SUM($AG12:AN12))),0) -> 400000 | ... AV12: =IF($O12="Aktif",MAX(0,MIN($AE12,$AD12-SUM($AG12:AU12))),0) -> 400000 | AW12: =SUM(AG12:AV12) -> 6400000 | AX12: =AD12-AW12 -> 48000000
A13: 7 | B13: FA Bangunan | C13: 14 | D13: Buildings | E13: Bangunan | F13: 1201-001 | G13: 1202-001 | H13: 6500-001 | I13: Depreciation Expenses | J13: BP.04/18 | K13: GD.0007 | L13: 43109 | M13: Pekerjaan Perbaikan Lantai | N13: pekerjaan pengecoran lantai unit 1 goreng ( bongkar lantai cor u.1,beton cor k 300 6,dl),29/12/17 | O13: Aktif | P13: 1 | Q13: 34000000 | R13: 240 | S13: 141666.67 | T13: 13600000 | U13: 141666.67 | V13: 141666.67 | W13: 141666.67 | X13: 141666.67 | Y13: 141666.67 | Z13: 141666.67 | AA13: 141666.67 | AB13: 141666.67 | AC13: =T13+SUM(U13:AB13) -> 14733333 | AD13: =Q13-AC13 -> 19266667 | AE13: =IF(O13="Aktif",AB13,0) -> 141666.67 | AF13: =IF(AE13>0,MAX(0,AD13)/AE13,0) -> 136 | AG13: =IF($O13="Aktif",MAX(0,MIN($AE13,$AD13-0)),0) -> 141666.67 | AH13: =IF($O13="Aktif",MAX(0,MIN($AE13,$AD13-SUM($AG13:AG13))),0) -> 141666.67 | AI13: =IF($O13="Aktif",MAX(0,MIN($AE13,$AD13-SUM($AG13:AH13))),0) -> 141666.67 | AJ13: =IF($O13="Aktif",MAX(0,MIN($AE13,$AD13-SUM($AG13:AI13))),0) -> 141666.67 | AK13: =IF($O13="Aktif",MAX(0,MIN($AE13,$AD13-SUM($AG13:AJ13))),0) -> 141666.67 | AL13: =IF($O13="Aktif",MAX(0,MIN($AE13,$AD13-SUM($AG13:AK13))),0) -> 141666.67 | AM13: =IF($O13="Aktif",MAX(0,MIN($AE13,$AD13-SUM($AG13:AL13))),0) -> 141666.67 | AN13: =IF($O13="Aktif",MAX(0,MIN($AE13,$AD13-SUM($AG13:AM13))),0) -> 141666.67 | AO13: =IF($O13="Aktif",MAX(0,MIN($AE13,$AD13-SUM($AG13:AN13))),0) -> 141666.67 | ... AV13: =IF($O13="Aktif",MAX(0,MIN($AE13,$AD13-SUM($AG13:AU13))),0) -> 141666.67 | AW13: =SUM(AG13:AV13) -> 2266666.7 | AX13: =AD13-AW13 -> 17000000
A14: 8 | B14: FA Bangunan | C14: 15 | D14: Buildings | E14: Bangunan | F14: 1201-001 | G14: 1202-001 | H14: 6500-001 | I14: Depreciation Expenses | J14: BP.05/18 | K14: GD.0008 | L14: 43144 | M14: Pekerjaan Instalasi Listrik R. Angin, R. Bumbu | N14: pekerjaan listrik ( instalansi ), R.aging, R. Bumbu,dll di karya mandiri (pph 23) | O14: Aktif | P14: 1 | Q14: 8340000 | R14: 240 | S14: 34750 | T14: 3301250 | U14: 34750 | V14: 34750 | W14: 34750 | X14: 34750 | Y14: 34750 | Z14: 34750 | AA14: 34750 | AB14: 34750 | AC14: =T14+SUM(U14:AB14) -> 3579250 | AD14: =Q14-AC14 -> 4760750 | AE14: =IF(O14="Aktif",AB14,0) -> 34750 | AF14: =IF(AE14>0,MAX(0,AD14)/AE14,0) -> 137 | AG14: =IF($O14="Aktif",MAX(0,MIN($AE14,$AD14-0)),0) -> 34750 | AH14: =IF($O14="Aktif",MAX(0,MIN($AE14,$AD14-SUM($AG14:AG14))),0) -> 34750 | AI14: =IF($O14="Aktif",MAX(0,MIN($AE14,$AD14-SUM($AG14:AH14))),0) -> 34750 | AJ14: =IF($O14="Aktif",MAX(0,MIN($AE14,$AD14-SUM($AG14:AI14))),0) -> 34750 | AK14: =IF($O14="Aktif",MAX(0,MIN($AE14,$AD14-SUM($AG14:AJ14))),0) -> 34750 | AL14: =IF($O14="Aktif",MAX(0,MIN($AE14,$AD14-SUM($AG14:AK14))),0) -> 34750 | AM14: =IF($O14="Aktif",MAX(0,MIN($AE14,$AD14-SUM($AG14:AL14))),0) -> 34750 | AN14: =IF($O14="Aktif",MAX(0,MIN($AE14,$AD14-SUM($AG14:AM14))),0) -> 34750 | AO14: =IF($O14="Aktif",MAX(0,MIN($AE14,$AD14-SUM($AG14:AN14))),0) -> 34750 | ... AV14: =IF($O14="Aktif",MAX(0,MIN($AE14,$AD14-SUM($AG14:AU14))),0) -> 34750 | AW14: =SUM(AG14:AV14) -> 556000 | AX14: =AD14-AW14 -> 4204750
A15: 9 | B15: FA Bangunan | C15: 16 | D15: Buildings | E15: Bangunan | F15: 1201-001 | G15: 1202-001 | H15: 6500-001 | I15: Depreciation Expenses | J15: BP.06/18 | K15: GD.0009 | L15: 43144 | M15: Pemasangan Pintu Emergency R. Angin & Perbaikan Pipa Aur | N15: pemasangan pintu emergency,R. Anging, Pindah Pipa Aur bersih,dll di karya mandiri (pph 23) | O15: Aktif | P15: 1 | Q15: 51500000 | R15: 240 | S15: 214583.33 | T15: 20385417 | U15: 214583.33 | V15: 214583.33 | W15: 214583.33 | X15: 214583.33 | Y15: 214583.33 | Z15: 214583.33 | AA15: 214583.33 | AB15: 214583.33 | AC15: =T15+SUM(U15:AB15) -> 22102083 | AD15: =Q15-AC15 -> 29397917 | AE15: =IF(O15="Aktif",AB15,0) -> 214583.33 | AF15: =IF(AE15>0,MAX(0,AD15)/AE15,0) -> 137 | AG15: =IF($O15="Aktif",MAX(0,MIN($AE15,$AD15-0)),0) -> 214583.33 | AH15: =IF($O15="Aktif",MAX(0,MIN($AE15,$AD15-SUM($AG15:AG15))),0) -> 214583.33 | AI15: =IF($O15="Aktif",MAX(0,MIN($AE15,$AD15-SUM($AG15:AH15))),0) -> 214583.33 | AJ15: =IF($O15="Aktif",MAX(0,MIN($AE15,$AD15-SUM($AG15:AI15))),0) -> 214583.33 | AK15: =IF($O15="Aktif",MAX(0,MIN($AE15,$AD15-SUM($AG15:AJ15))),0) -> 214583.33 | AL15: =IF($O15="Aktif",MAX(0,MIN($AE15,$AD15-SUM($AG15:AK15))),0) -> 214583.33 | AM15: =IF($O15="Aktif",MAX(0,MIN($AE15,$AD15-SUM($AG15:AL15))),0) -> 214583.33 | AN15: =IF($O15="Aktif",MAX(0,MIN($AE15,$AD15-SUM($AG15:AM15))),0) -> 214583.33 | AO15: =IF($O15="Aktif",MAX(0,MIN($AE15,$AD15-SUM($AG15:AN15))),0) -> 214583.33 | ... AV15: =IF($O15="Aktif",MAX(0,MIN($AE15,$AD15-SUM($AG15:AU15))),0) -> 214583.33 | AW15: =SUM(AG15:AV15) -> 3433333.3 | AX15: =AD15-AW15 -> 25964583
A16: 10 | B16: FA Bangunan | C16: 17 | D16: Buildings | E16: Bangunan | F16: 1201-001 | G16: 1202-001 | H16: 6500-001 | I16: Depreciation Expenses | J16: BP.07/18 | K16: GD.0010 | L16: 43158 | M16: Pekerjaan Ruang & Rak Bumbu | N16: Pekerjaan ruang dan rak bumbu baru unit 1 (gudang bumbu ) di karya mandiri, 19/2/18 ( pph 23 4%) | O16: Aktif | P16: 1 | Q16: 40000000 | R16: 240 | S16: 166666.67 | T16: 15833333 | U16: 166666.67 | V16: 166666.67 | W16: 166666.67 | X16: 166666.67 | Y16: 166666.67 | Z16: 166666.67 | AA16: 166666.67 | AB16: 166666.67 | AC16: =T16+SUM(U16:AB16) -> 17166667 | AD16: =Q16-AC16 -> 22833333 | AE16: =IF(O16="Aktif",AB16,0) -> 166666.67 | AF16: =IF(AE16>0,MAX(0,AD16)/AE16,0) -> 137 | AG16: =IF($O16="Aktif",MAX(0,MIN($AE16,$AD16-0)),0) -> 166666.67 | AH16: =IF($O16="Aktif",MAX(0,MIN($AE16,$AD16-SUM($AG16:AG16))),0) -> 166666.67 | AI16: =IF($O16="Aktif",MAX(0,MIN($AE16,$AD16-SUM($AG16:AH16))),0) -> 166666.67 | AJ16: =IF($O16="Aktif",MAX(0,MIN($AE16,$AD16-SUM($AG16:AI16))),0) -> 166666.67 | AK16: =IF($O16="Aktif",MAX(0,MIN($AE16,$AD16-SUM($AG16:AJ16))),0) -> 166666.67 | AL16: =IF($O16="Aktif",MAX(0,MIN($AE16,$AD16-SUM($AG16:AK16))),0) -> 166666.67 | AM16: =IF($O16="Aktif",MAX(0,MIN($AE16,$AD16-SUM($AG16:AL16))),0) -> 166666.67 | AN16: =IF($O16="Aktif",MAX(0,MIN($AE16,$AD16-SUM($AG16:AM16))),0) -> 166666.67 | AO16: =IF($O16="Aktif",MAX(0,MIN($AE16,$AD16-SUM($AG16:AN16))),0) -> 166666.67 | ... AV16: =IF($O16="Aktif",MAX(0,MIN($AE16,$AD16-SUM($AG16:AU16))),0) -> 166666.67 | AW16: =SUM(AG16:AV16) -> 2666666.7 | AX16: =AD16-AW16 -> 20166667
A17: 11 | B17: FA Bangunan | C17: 18 | D17: Buildings | E17: Bangunan | F17: 1201-001 | G17: 1202-001 | H17: 6500-001 | I17: Depreciation Expenses | J17: BP.08/18 | K17: GD.0011 | L17: 43140 | M17: Radiator, Pipa Steam Gas, Steam Floatin | N17: PT Beta Pramesti Radiator,pipa steam gas,steam floatin,dll(dipotong pph 23) | O17: Aktif | P17: 1 | Q17: 38565000 | R17: 240 | S17: 160687.5 | T17: 15265312 | U17: 160687.5 | V17: 160687.5 | W17: 160687.5 | X17: 160687.5 | Y17: 160687.5 | Z17: 160687.5 | AA17: 160687.5 | AB17: 160687.5 | AC17: =T17+SUM(U17:AB17) -> 16550812 | AD17: =Q17-AC17 -> 22014188 | AE17: =IF(O17="Aktif",AB17,0) -> 160687.5 | AF17: =IF(AE17>0,MAX(0,AD17)/AE17,0) -> 137 | AG17: =IF($O17="Aktif",MAX(0,MIN($AE17,$AD17-0)),0) -> 160687.5 | AH17: =IF($O17="Aktif",MAX(0,MIN($AE17,$AD17-SUM($AG17:AG17))),0) -> 160687.5 | AI17: =IF($O17="Aktif",MAX(0,MIN($AE17,$AD17-SUM($AG17:AH17))),0) -> 160687.5 | AJ17: =IF($O17="Aktif",MAX(0,MIN($AE17,$AD17-SUM($AG17:AI17))),0) -> 160687.5 | AK17: =IF($O17="Aktif",MAX(0,MIN($AE17,$AD17-SUM($AG17:AJ17))),0) -> 160687.5 | AL17: =IF($O17="Aktif",MAX(0,MIN($AE17,$AD17-SUM($AG17:AK17))),0) -> 160687.5 | AM17: =IF($O17="Aktif",MAX(0,MIN($AE17,$AD17-SUM($AG17:AL17))),0) -> 160687.5 | AN17: =IF($O17="Aktif",MAX(0,MIN($AE17,$AD17-SUM($AG17:AM17))),0) -> 160687.5 | AO17: =IF($O17="Aktif",MAX(0,MIN($AE17,$AD17-SUM($AG17:AN17))),0) -> 160687.5 | ... AV17: =IF($O17="Aktif",MAX(0,MIN($AE17,$AD17-SUM($AG17:AU17))),0) -> 160687.5 | AW17: =SUM(AG17:AV17) -> 2571000 | AX17: =AD17-AW17 -> 19443188
A18: 12 | B18: FA Bangunan | C18: 19 | D18: Buildings | E18: Bangunan | F18: 1201-001 | G18: 1202-001 | H18: 6500-001 | I18: Depreciation Expenses | J18: BP.09/18 | K18: GD.0012 | L18: 43186 | M18: Pekerjaan Ruangan QC & Mushola | N18: Pekerjaan ruang qc dan mushola (pph 23 4%)di karya mandiri, 12/3/18 | O18: Aktif | P18: 1 | Q18: 25100000 | R18: 240 | S18: 104583.33 | T18: 9830833.3 | U18: 104583.33 | V18: 104583.33 | W18: 104583.33 | X18: 104583.33 | Y18: 104583.33 | Z18: 104583.33 | AA18: 104583.33 | AB18: 104583.33 | AC18: =T18+SUM(U18:AB18) -> 10667500 | AD18: =Q18-AC18 -> 14432500 | AE18: =IF(O18="Aktif",AB18,0) -> 104583.33 | AF18: =IF(AE18>0,MAX(0,AD18)/AE18,0) -> 138 | AG18: =IF($O18="Aktif",MAX(0,MIN($AE18,$AD18-0)),0) -> 104583.33 | AH18: =IF($O18="Aktif",MAX(0,MIN($AE18,$AD18-SUM($AG18:AG18))),0) -> 104583.33 | AI18: =IF($O18="Aktif",MAX(0,MIN($AE18,$AD18-SUM($AG18:AH18))),0) -> 104583.33 | AJ18: =IF($O18="Aktif",MAX(0,MIN($AE18,$AD18-SUM($AG18:AI18))),0) -> 104583.33 | AK18: =IF($O18="Aktif",MAX(0,MIN($AE18,$AD18-SUM($AG18:AJ18))),0) -> 104583.33 | AL18: =IF($O18="Aktif",MAX(0,MIN($AE18,$AD18-SUM($AG18:AK18))),0) -> 104583.33 | AM18: =IF($O18="Aktif",MAX(0,MIN($AE18,$AD18-SUM($AG18:AL18))),0) -> 104583.33 | AN18: =IF($O18="Aktif",MAX(0,MIN($AE18,$AD18-SUM($AG18:AM18))),0) -> 104583.33 | AO18: =IF($O18="Aktif",MAX(0,MIN($AE18,$AD18-SUM($AG18:AN18))),0) -> 104583.33 | ... AV18: =IF($O18="Aktif",MAX(0,MIN($AE18,$AD18-SUM($AG18:AU18))),0) -> 104583.33 | AW18: =SUM(AG18:AV18) -> 1673333.3 | AX18: =AD18-AW18 -> 12759167
... A24: 18 | B24: FA Bangunan | C24: 25 | D24: Buildings | E24: Bangunan | F24: 1201-001 | G24: 1202-001 | H24: 6500-001 | I24: Depreciation Expenses | J24: BP.15/18 | K24: GD.0018 | L24: 43465 | M24: Perbaikan Bangunan | N24: Karya Mandiri, Pekerjaan Pengecoran lantai R N D Bangunan Unit 4, 4/10/17 | O24: Aktif | P24: 1 | Q24: 24000000 | R24: 240 | S24: 100000 | T24: 8500000 | U24: 100000 | V24: 100000 | W24: 100000 | X24: 100000 | Y24: 100000 | Z24: 100000 | AA24: 100000 | AB24: 100000 | AC24: =T24+SUM(U24:AB24) -> 9300000 | AD24: =Q24-AC24 -> 14700000 | AE24: =IF(O24="Aktif",AB24,0) -> 100000 | AF24: =IF(AE24>0,MAX(0,AD24)/AE24,0) -> 147 | AG24: =IF($O24="Aktif",MAX(0,MIN($AE24,$AD24-0)),0) -> 100000 | AH24: =IF($O24="Aktif",MAX(0,MIN($AE24,$AD24-SUM($AG24:AG24))),0) -> 100000 | AI24: =IF($O24="Aktif",MAX(0,MIN($AE24,$AD24-SUM($AG24:AH24))),0) -> 100000 | AJ24: =IF($O24="Aktif",MAX(0,MIN($AE24,$AD24-SUM($AG24:AI24))),0) -> 100000 | AK24: =IF($O24="Aktif",MAX(0,MIN($AE24,$AD24-SUM($AG24:AJ24))),0) -> 100000 | AL24: =IF($O24="Aktif",MAX(0,MIN($AE24,$AD24-SUM($AG24:AK24))),0) -> 100000 | AM24: =IF($O24="Aktif",MAX(0,MIN($AE24,$AD24-SUM($AG24:AL24))),0) -> 100000 | AN24: =IF($O24="Aktif",MAX(0,MIN($AE24,$AD24-SUM($AG24:AM24))),0) -> 100000 | AO24: =IF($O24="Aktif",MAX(0,MIN($AE24,$AD24-SUM($AG24:AN24))),0) -> 100000 | ... AV24: =IF($O24="Aktif",MAX(0,MIN($AE24,$AD24-SUM($AG24:AU24))),0) -> 100000 | AW24: =SUM(AG24:AV24) -> 1600000 | AX24: =AD24-AW24 -> 13100000
A25: 19 | B25: FA Bangunan | C25: 26 | D25: Buildings | E25: Bangunan | F25: 1201-001 | G25: 1202-001 | H25: 6500-001 | I25: Depreciation Expenses | K25: GD.0019 | L25: 44114 | M25: Material Time line 1 dan 3 | N25: Reimbursement pembelian material time line 1 dan 3 utk area kompressor project Nabati | O25: Aktif | P25: 1 | Q25: 11913500 | R25: 240 | S25: 49639.583 | T25: 3127293.8 | U25: 49639.583 | V25: 49639.583 | W25: 49639.583 | X25: 49639.583 | Y25: 49639.583 | Z25: 49639.583 | AA25: 49639.583 | AB25: 49639.583 | AC25: =T25+SUM(U25:AB25) -> 3524410.4 | AD25: =Q25-AC25 -> 8389089.6 | AE25: =IF(O25="Aktif",AB25,0) -> 49639.583 | AF25: =IF(AE25>0,MAX(0,AD25)/AE25,0) -> 169 | AG25: =IF($O25="Aktif",MAX(0,MIN($AE25,$AD25-0)),0) -> 49639.583 | AH25: =IF($O25="Aktif",MAX(0,MIN($AE25,$AD25-SUM($AG25:AG25))),0) -> 49639.583 | AI25: =IF($O25="Aktif",MAX(0,MIN($AE25,$AD25-SUM($AG25:AH25))),0) -> 49639.583 | AJ25: =IF($O25="Aktif",MAX(0,MIN($AE25,$AD25-SUM($AG25:AI25))),0) -> 49639.583 | AK25: =IF($O25="Aktif",MAX(0,MIN($AE25,$AD25-SUM($AG25:AJ25))),0) -> 49639.583 | AL25: =IF($O25="Aktif",MAX(0,MIN($AE25,$AD25-SUM($AG25:AK25))),0) -> 49639.583 | AM25: =IF($O25="Aktif",MAX(0,MIN($AE25,$AD25-SUM($AG25:AL25))),0) -> 49639.583 | AN25: =IF($O25="Aktif",MAX(0,MIN($AE25,$AD25-SUM($AG25:AM25))),0) -> 49639.583 | AO25: =IF($O25="Aktif",MAX(0,MIN($AE25,$AD25-SUM($AG25:AN25))),0) -> 49639.583 | ... AV25: =IF($O25="Aktif",MAX(0,MIN($AE25,$AD25-SUM($AG25:AU25))),0) -> 49639.583 | AW25: =SUM(AG25:AV25) -> 794233.33 | AX25: =AD25-AW25 -> 7594856.3
A26: 20 | B26: FA Bangunan | C26: 27 | D26: Buildings | E26: Bangunan | F26: 1201-001 | G26: 1202-001 | H26: 6500-001 | I26: Depreciation Expenses | K26: GD.0020 | L26: 44165 | M26: Pembangunan Ruangan Panel | N26: CV Koronka Nusantara, Pembuatan Ruang Panel Project Nabati 23/11/20 | O26: Aktif | P26: 1 | Q26: 99680000 | R26: 240 | S26: 415333.33 | T26: 25750667 | U26: 415333.33 | V26: 415333.33 | W26: 415333.33 | X26: 415333.33 | Y26: 415333.33 | Z26: 415333.33 | AA26: 415333.33 | AB26: 415333.33 | AC26: =T26+SUM(U26:AB26) -> 29073333 | AD26: =Q26-AC26 -> 70606667 | AE26: =IF(O26="Aktif",AB26,0) -> 415333.33 | AF26: =IF(AE26>0,MAX(0,AD26)/AE26,0) -> 170 | AG26: =IF($O26="Aktif",MAX(0,MIN($AE26,$AD26-0)),0) -> 415333.33 | AH26: =IF($O26="Aktif",MAX(0,MIN($AE26,$AD26-SUM($AG26:AG26))),0) -> 415333.33 | AI26: =IF($O26="Aktif",MAX(0,MIN($AE26,$AD26-SUM($AG26:AH26))),0) -> 415333.33 | AJ26: =IF($O26="Aktif",MAX(0,MIN($AE26,$AD26-SUM($AG26:AI26))),0) -> 415333.33 | AK26: =IF($O26="Aktif",MAX(0,MIN($AE26,$AD26-SUM($AG26:AJ26))),0) -> 415333.33 | AL26: =IF($O26="Aktif",MAX(0,MIN($AE26,$AD26-SUM($AG26:AK26))),0) -> 415333.33 | AM26: =IF($O26="Aktif",MAX(0,MIN($AE26,$AD26-SUM($AG26:AL26))),0) -> 415333.33 | AN26: =IF($O26="Aktif",MAX(0,MIN($AE26,$AD26-SUM($AG26:AM26))),0) -> 415333.33 | AO26: =IF($O26="Aktif",MAX(0,MIN($AE26,$AD26-SUM($AG26:AN26))),0) -> 415333.33 | ... AV26: =IF($O26="Aktif",MAX(0,MIN($AE26,$AD26-SUM($AG26:AU26))),0) -> 415333.33 | AW26: =SUM(AG26:AV26) -> 6645333.3 | AX26: =AD26-AW26 -> 63961333
A27: 21 | B27: FA Bangunan | C27: 28 | D27: Buildings | E27: Bangunan | F27: 1201-001 | G27: 1202-001 | H27: 6500-001 | I27: Depreciation Expenses | K27: GD.0021 | L27: 44613 | M27: Pekerjaan pembuatan ruang Decanter | N27: Karya Mandiri, Pekerjaan pembuatan ruang Decanter, 21/2/22 Material | O27: Aktif | P27: 1 | Q27: 12311500 | R27: 240 | S27: 51297.917 | T27: 2411002.1 | U27: 51297.917 | V27: 51297.917 | W27: 51297.917 | X27: 51297.917 | Y27: 51297.917 | Z27: 51297.917 | AA27: 51297.917 | AB27: 51297.917 | AC27: =T27+SUM(U27:AB27) -> 2821385.4 | AD27: =Q27-AC27 -> 9490114.6 | AE27: =IF(O27="Aktif",AB27,0) -> 51297.917 | AF27: =IF(AE27>0,MAX(0,AD27)/AE27,0) -> 185 | AG27: =IF($O27="Aktif",MAX(0,MIN($AE27,$AD27-0)),0) -> 51297.917 | AH27: =IF($O27="Aktif",MAX(0,MIN($AE27,$AD27-SUM($AG27:AG27))),0) -> 51297.917 | AI27: =IF($O27="Aktif",MAX(0,MIN($AE27,$AD27-SUM($AG27:AH27))),0) -> 51297.917 | AJ27: =IF($O27="Aktif",MAX(0,MIN($AE27,$AD27-SUM($AG27:AI27))),0) -> 51297.917 | AK27: =IF($O27="Aktif",MAX(0,MIN($AE27,$AD27-SUM($AG27:AJ27))),0) -> 51297.917 | AL27: =IF($O27="Aktif",MAX(0,MIN($AE27,$AD27-SUM($AG27:AK27))),0) -> 51297.917 | AM27: =IF($O27="Aktif",MAX(0,MIN($AE27,$AD27-SUM($AG27:AL27))),0) -> 51297.917 | AN27: =IF($O27="Aktif",MAX(0,MIN($AE27,$AD27-SUM($AG27:AM27))),0) -> 51297.917 | AO27: =IF($O27="Aktif",MAX(0,MIN($AE27,$AD27-SUM($AG27:AN27))),0) -> 51297.917 | ... AV27: =IF($O27="Aktif",MAX(0,MIN($AE27,$AD27-SUM($AG27:AU27))),0) -> 51297.917 | AW27: =SUM(AG27:AV27) -> 820766.67 | AX27: =AD27-AW27 -> 8669347.9
A28: 22 | B28: FA Bangunan | C28: 29 | D28: Buildings | E28: Bangunan | F28: 1201-001 | G28: 1202-001 | H28: 6500-001 | I28: Depreciation Expenses | K28: GD.0022 | L28: 44623 | M28: Ducting Line CF 1 | N28: Cipta Mandiri,Pembuatan Ducting Line CF 1, -PPh 21 2,5%, 03/03/22 - Material | O28: Aktif | P28: 1 | Q28: 28200000 | R28: 240 | S28: 117500 | T28: 5405000 | U28: 117500 | V28: 117500 | W28: 117500 | X28: 117500 | Y28: 117500 | Z28: 117500 | AA28: 117500 | AB28: 117500 | AC28: =T28+SUM(U28:AB28) -> 6345000 | AD28: =Q28-AC28 -> 21855000 | AE28: =IF(O28="Aktif",AB28,0) -> 117500 | AF28: =IF(AE28>0,MAX(0,AD28)/AE28,0) -> 186 | AG28: =IF($O28="Aktif",MAX(0,MIN($AE28,$AD28-0)),0) -> 117500 | AH28: =IF($O28="Aktif",MAX(0,MIN($AE28,$AD28-SUM($AG28:AG28))),0) -> 117500 | AI28: =IF($O28="Aktif",MAX(0,MIN($AE28,$AD28-SUM($AG28:AH28))),0) -> 117500 | AJ28: =IF($O28="Aktif",MAX(0,MIN($AE28,$AD28-SUM($AG28:AI28))),0) -> 117500 | AK28: =IF($O28="Aktif",MAX(0,MIN($AE28,$AD28-SUM($AG28:AJ28))),0) -> 117500 | AL28: =IF($O28="Aktif",MAX(0,MIN($AE28,$AD28-SUM($AG28:AK28))),0) -> 117500 | AM28: =IF($O28="Aktif",MAX(0,MIN($AE28,$AD28-SUM($AG28:AL28))),0) -> 117500 | AN28: =IF($O28="Aktif",MAX(0,MIN($AE28,$AD28-SUM($AG28:AM28))),0) -> 117500 | AO28: =IF($O28="Aktif",MAX(0,MIN($AE28,$AD28-SUM($AG28:AN28))),0) -> 117500 | ... AV28: =IF($O28="Aktif",MAX(0,MIN($AE28,$AD28-SUM($AG28:AU28))),0) -> 117500 | AW28: =SUM(AG28:AV28) -> 1880000 | AX28: =AD28-AW28 -> 19975000
