Workbook

Sheet RINGKASAN
A1: RINGKASAN WP COSTING
A3: Status kontrol semua sheet + kontrol ke GL/LK (bagian 5) | C3: =IF(AND('REKON & KONTROL'!$D$69="LULUS",$I$50="LULUS"),"LULUS","GAGAL") -> LULUS
A4: di dalamnya: kontrol ke GL, Neraca, Laba Rugi (bagian 5) | C4: =$I$50 -> LULUS
A5: 1. Biaya produksi dan HPP per produk (Rp juta; Rp/kg per kg produksi)
A6: Pos | B6: FCC | C6: Ubi Ungu | D6: Ubi Orange | E6: Lain-lain | F6: Total
A7: Produksi (kg) | B7: ='REKON & KONTROL'!B6 -> 236923 | C7: ='REKON & KONTROL'!C6 -> 467.5 | D7: ='REKON & KONTROL'!D6 -> 6715.5 | E7: ='REKON & KONTROL'!E6 -> 45653.42 | F7: ='REKON & KONTROL'!F6 -> 289759.42
A8: Total biaya produksi | B8: ='REKON & KONTROL'!B12 -> 5562.5685 | C8: ='REKON & KONTROL'!C12 -> 18.227721 | D8: ='REKON & KONTROL'!D12 -> 252.5666 | E8: ='REKON & KONTROL'!E12 -> 870.97808 | F8: ='REKON & KONTROL'!F12 -> 6704.3409
A9: Biaya produksi per kg (Rp) | B9: ='REKON & KONTROL'!B13 -> 23478.381 | C9: ='REKON & KONTROL'!C13 -> 38989.777 | D9: ='REKON & KONTROL'!D13 -> 37609.501 | E9: ='REKON & KONTROL'!E13 -> 19078.047 | F9: ='REKON & KONTROL'!F13 -> 23137.611
A10: HPP | B10: ='REKON & KONTROL'!B14 -> 5106.3121 | C10: ='REKON & KONTROL'!C14 -> 232.70642 | D10: ='REKON & KONTROL'!D14 -> 252.5666 | E10: ='REKON & KONTROL'!E14 -> 871.58173 | F10: ='REKON & KONTROL'!F14 -> 6463.1669
A11: Pendapatan (total = GL) | B11: ='REKON & KONTROL'!B15 -> 5901.3131 | C11: ='REKON & KONTROL'!C15 -> 321.7005 | D11: ='REKON & KONTROL'!D15 -> 321.67245 | E11: ='REKON & KONTROL'!E15 -> 917.67406 | F11: ='REKON & KONTROL'!F15 -> 7462.3602
A12: Margin kotor (%) | B12: ='REKON & KONTROL'!B16 -> 0.13471595 | C12: ='REKON & KONTROL'!C16 -> 0.27663644 | D12: ='REKON & KONTROL'!D16 -> 0.21483297 | E12: ='REKON & KONTROL'!E16 -> 0.050227349 | F12: ='REKON & KONTROL'!F16 -> 0.13389775
A14: 2. FCC, UU, UO: Rp/kg aktual vs budget dan penyebab selisih (Rp/kg)
A15: Produk | B15: Rp/kg aktual | C15: Rp/kg budget | D15: Selisih | E15: Harga / belanja | F15: Pemakaian / yield | G15: Volume | H15: Metode alokasi | I15: Bulan budget
A16: FCC | B16: =FCC!F133 -> 23301.541 | C16: =FCC!G133 -> 0 | D16: =FCC!H133 -> 23301.541 | E16: =FCC!I133 -> 23958.869 | F16: =FCC!J133 -> 40.796406 | G16: =FCC!K133 -> 0 | H16: =FCC!L133 -> -698.12472 | I16: =FCC!$C$5 -> Sep-26
A17: UU | B17: =UU!F126 -> 38989.777 | C17: =UU!G126 -> 0 | D17: =UU!H126 -> 38989.777 | E17: =UU!I126 -> 32383.525 | F17: =UU!J126 -> 74.749813 | G17: =UU!K126 -> 0 | H17: =UU!L126 -> 6531.5017 | I17: =UU!$C$5 -> Sep-26
A18: UO | B18: =UO!F122 -> 37609.501 | C18: =UO!G122 -> 0 | D18: =UO!H122 -> 37609.501 | E18: =UO!I122 -> 31682.571 | F18: =UO!J122 -> 49.472884 | G18: =UO!K122 -> 0 | H18: =UO!L122 -> 5877.4567 | I18: =UO!$C$3 -> Sep-26
A21: 3. Biaya yang tidak terlihat di margin (memo)
A22: Pos | B22: FCC | C22: Ubi Ungu | D22: Ubi Orange | F22: Catatan
A23: Biaya waste (kerugian normal) yang terserap ke HPP (Rp jt) | B23: =FCC!$B$23 -> 155.53505 | C23: =UU!$B$23 -> 0 | D23: =UO!$B$21 -> 0
A24: KW 2 dikreditkan pada NRV (Rp jt) | B24: =FCC!$B$24 -> 74.121493 | C24: =UU!$B$24 -> 0 | D24: =UO!$B$22 -> 0
A25: Kenaikan WIP + FG (Rp jt) | B25: =(FCC!$E$79+FCC!$E$92-FCC!$E$72-FCC!$E$86)/10^6 -> -111.4571 | C25: =UU!$B$25 -> -214.4787 | D25: =(UO!$E$73+UO!$E$85-UO!$E$66-UO!$E$80)/10^6 -> 0
A26: Biaya jam operator tidak terpakai untuk produk (Rp jt; % jam) | B26: ='BIAYA BERSAMA'!$C$109/10^6 -> 61.594633 | C26: ='BIAYA BERSAMA'!$D$107 -> 0.13124381
A28: 4. Rekonsiliasi ke GL (Rp juta)
A29: Total HPP kartu baru | B29: ='REKON & KONTROL'!$C$37 -> 6463.1669
A30: Varian material (GL − kartu) | B30: ='REKON & KONTROL'!$C$38 -> -121.14819
A31: Selisih kenaikan persediaan kartu baru vs GL | B31: ='REKON & KONTROL'!$C$47 -> 82.766047
A32: Kenaikan persediaan KW 2 pada NRV | B32: ='REKON & KONTROL'!$C$41 -> -25.596896
A33: Jam menganggur dibebankan ke periode | B33: ='REKON & KONTROL'!$C$43 -> 0
A34: HPP menurut GL | B34: ='REKON & KONTROL'!$C$45 -> 6375.4123
A35: Cek (harus nol) | B35: ='REKON & KONTROL'!$C$46 -> 7.2142293e-06
A37: 5. Kontrol ke GL Accurate dan LK: Laba Rugi dan Neraca (Rp juta; toleransi Rp 0,001 jt)
A38: Pos | B38: Menurut WP | C38: GL Accurate | D38: LK (LR / Neraca) | E38: Selisih WP − GL | F38: Dijelaskan pos rekon | G38: Sisa WP − GL | H38: Selisih GL − LK | I38: Status | J38: Penjelasan / sumber
A39: Laba rugi bulan ini
A40: Pendapatan | B40: ='REKON & KONTROL'!$F$15 -> 7462.3602 | C40: ='REKON & KONTROL'!$C$73/10^6 -> 7462.3602 | D40: =$B$58/10^6 -> 7462.3602 | E40: =B40-C40 -> 0 | F40: 0 | G40: =E40-F40 -> 0 | H40: =C40-D40 -> 0 | I40: =IF(OR(ISERROR(G40),ISERROR(H40)),"GAGAL",IF(AND(ABS(G40)<=0.001,ABS(H40)<=0.001),"LULUS","GAGAL")) -> LULUS | J40: WP: REKON F15 (pendapatan per produk). GL: 4101-007 (REKON C72).
A41: Pemakaian bahan baku | B41: ='REKON & KONTROL'!$B$28 -> 4496.3664 | C41: ='REKON MATERIAL'!$C$69/10^6 -> 4375.2182 | D41: =$B$59/10^6 -> 4375.2182 | E41: =B41-C41 -> 121.14818 | F41: =-'REKON & KONTROL'!$B$30 -> 121.14819 | G41: =E41-F41 -> -7.2142302e-06 | H41: =C41-D41 -> 7.2100001e-06 | I41: =IF(OR(ISERROR(G41),ISERROR(H41)),"GAGAL",IF(AND(ABS(G41)<=0.001,ABS(H41)<=0.001),"LULUS","GAGAL")) -> LULUS | J41: WP: material kartu semua produk (REKON B28). GL: 1106-001 Penyesuaian Persediaan neto (REKON MATERIAL). Sisa dijelaskan varian material GL − kartu (REKON B30; rincian per item di REKON MATERIAL).
A42: Biaya konversi (DL + FOH) | B42: ='REKON & KONTROL'!$F$9+'REKON & KONTROL'!$F$10+'REKON & KONTROL'!$F$11+'BIAYA BERSAMA'!$C$111/10^6 -> 1572.7667 | C42: ='BIAYA BERSAMA'!$C$23/10^6 -> 1590.8886 | D42: =$B$60/10^6 -> 1590.8886 | E42: =B42-C42 -> -18.121908 | F42: =('BIAYA BERSAMA'!$C$157+'BIAYA BERSAMA'!$C$158)/10^6 -> -18.121908 | G42: =E42-F42 -> 1.7053026e-13 | H42: =C42-D42 -> 0 | I42: =IF(OR(ISERROR(G42),ISERROR(H42)),"GAGAL",IF(AND(ABS(G42)<=0.001,ABS(H42)<=0.001),"LULUS","GAGAL")) -> LULUS | J42: WP: upah kupas + DL + FOH di semua kartu (REKON F9:F11) + jam menganggur dibebankan ke periode. GL: 16 akun (BIAYA BERSAMA C23). Dijelaskan: penyesuaian BIAYA BERSAMA bagian 8 ke pool dan THR (reklas opex pabrik, THR tertukar, tali asih per bulan jasa, ongkos kirim singkong keluar ke material, pisau Urschel).
A43: HPP | B43: ='REKON & KONTROL'!$F$14 -> 6463.1669 | C43: ='REKON & KONTROL'!$C$45 -> 6375.4123 | D43: =$B$61/10^6 -> 6375.4123 | E43: =B43-C43 -> 87.754589 | F43: =-SUM('REKON & KONTROL'!$C$38:$C$43) -> 87.754597 | G43: =E43-F43 -> -7.2142289e-06 | H43: =C43-D43 -> 0 | I43: =IF(OR(ISERROR(G43),ISERROR(H43)),"GAGAL",IF(AND(ABS(G43)<=0.001,ABS(H43)<=0.001),"LULUS","GAGAL")) -> LULUS | J43: WP: HPP semua kartu (REKON F14). GL: 5101/5102/6500-006/007 (REKON C44). Pos rekon: REKON C38:C42 (varian material, beda kenaikan persediaan kartu vs GL, KW 2 pada NRV, jam menganggur). Ditambah REKON C42: penyesuaian bagian 8 yang masuk kartu (tanda dibalik).
A44: Laba kotor | B44: ='REKON & KONTROL'!$F$15-'REKON & KONTROL'!$F$14 -> 999.19326 | C44: ='REKON & KONTROL'!$C$73/10^6-'REKON & KONTROL'!$C$45 -> 1086.9478 | D44: =$B$58/10^6-$B$61/10^6 -> 1086.9478 | E44: =B44-C44 -> -87.754589 | F44: =SUM('REKON & KONTROL'!$C$38:$C$43) -> -87.754597 | G44: =E44-F44 -> 7.2142298e-06 | H44: =C44-D44 -> 0 | I44: =IF(OR(ISERROR(G44),ISERROR(H44)),"GAGAL",IF(AND(ABS(G44)<=0.001,ABS(H44)<=0.001),"LULUS","GAGAL")) -> LULUS | J44: Pendapatan − HPP. Pos rekon sama dengan baris HPP, tanda dibalik.
A45: Neraca akhir bulan
A46: Persediaan bahan baku 1106-001 | B46: ='REKON MATERIAL'!$N$62/10^6 -> 826.03128 | C46: ='REKON MATERIAL'!$C$70/10^6 -> 947.17946 | D46: =$B$62/10^6 -> 947.1794 | E46: =B46-C46 -> -121.14818 | F46: ='REKON & KONTROL'!$B$30 -> -121.14819 | G46: =E46-F46 -> 7.2289072e-06 | H46: =C46-D46 -> 5.58e-05 | I46: =IF(OR(ISERROR(G46),ISERROR(H46)),"GAGAL",IF(AND(ABS(G46)<=0.001,ABS(H46)<=0.001),"LULUS","GAGAL")) -> LULUS | J46: WP: saldo awal + penerimaan GL − pemakaian kartu (REKON MATERIAL kolom N). GL: saldo awal + penerimaan − penyesuaian. Sisa dijelaskan varian material.
...

Sheet FCC
A1: KARTU BIAYA PRODUKSI - FCC (Flat Cassava Chips)
A5: Bulan budget pembanding | C5: Sep-26 | D5: posisi: | E5: =MATCH(C5,BUDGET!$C$4:$R$4,0) -> 1
A6: Status kontrol (bagian 6) | C6: =IF(COUNTIF(D159:D169,"GAGAL")=0,"LULUS","GAGAL") -> LULUS
A8: 1. Ringkasan (Rp juta; Rp/kg per kg produksi bulan ini)
A9: Komponen | B9: Aktual (Rp jt) | C9: Aktual Rp/kg | D9: Budget Rp/kg | E9: Selisih Rp/kg | F9: Harga / belanja | G9: Pemakaian / yield | H9: Volume | I9: Metode alokasi
A10: Raw materials | B10: =E44/10^6 -> 2351.873 | C10: =F44 -> 9926.7401 | D10: =G112 -> 0 | E10: =H112 -> 9749.9001 | F10: =I112 -> 9749.9001 | G10: =J112 -> 0 | H10: =K112 -> 0 | I10: =L112 -> 0
A11: Oil | B11: =E46/10^6 -> 1013.4281 | C11: =F46 -> 4277.4576 | D11: =G114 -> 0 | E11: =H114 -> 4277.4576 | F11: =I114 -> 4277.4576 | G11: =J114 -> 0 | H11: =K114 -> 0 | I11: =L114 -> 0
A12: CNG | B12: =E47/10^6 -> 774.66226 | C12: =F47 -> 3269.6794 | D12: =G116 -> 0 | E12: =H116 -> 3269.6794 | F12: =I116 -> 3269.6794 | G12: =J116 -> 0 | H12: =K116 -> 0 | I12: =L116 -> 0
A13: Material - others | B13: =E55/10^6 -> 135.57866 | C13: =F55 -> 572.24777 | D13: =G123 -> 0 | E13: =H123 -> 572.24777 | F13: =I123 -> 531.45136 | G13: =J123 -> 40.796406 | H13: =K123 -> 0 | I13: =L123 -> 0
A14: Upah kupas | B14: =E58/10^6 -> 53.598625 | C14: =F58 -> 226.22804 | D14: =G125 -> 0 | E14: =H125 -> 226.22804 | F14: =I125 -> 226.22804 | G14: =J125 -> 0 | H14: =K125 -> 0 | I14: =L125 -> 0
A15: Direct labour (Grup A) | B15: =E59/10^6 -> 384.85655 | C15: =F59 -> 1624.3951 | D15: =G127 -> 0 | E15: =H127 -> 1624.3951 | F15: =I127 -> 1922.5851 | G15: =J127 -> 0 | H15: =K127 -> 0 | I15: =L127 -> -298.19004
A16: Factory overhead (Grup B–E) | B16: =E64/10^6 -> 848.57125 | C16: =F64 -> 3581.633 | D16: =G132 -> 0 | E16: =H132 -> 3581.633 | F16: =I132 -> 3981.5677 | G16: =J132 -> 0 | H16: =K132 -> 0 | I16: =L132 -> -399.93468
A17: Total biaya produksi | B17: =E66/10^6 -> 5562.5685 | C17: =F66 -> 23478.381 | D17: =G133 -> 0 | E17: =H133 -> 23301.541 | F17: =I133 -> 23958.869 | G17: =J133 -> 40.796406 | H17: =K133 -> 0 | I17: =L133 -> -698.12472
A18: Produksi bulan ini (kg; aktual, budget) | C18: =$B$30 -> 236923 | D18: =$D$30 -> 0
A19: Biaya konversi per kg (aktual, budget) | C19: =F65 -> 5432.2561 | D19: =G125+G127+G132 -> 0
A20: HPP (Rp jt) dan HPP per kg terjual (aktual, budget) | B20: =E104/10^6 -> 5106.3121 | C20: =D105 -> 24631.839 | D20: =F105 -> 0
A21: Pendapatan (Rp jt; aktual) | B21: =$C$211/10^6 -> 5901.3131
A22: Margin kotor (Rp jt; %) | B22: =B21-B20 -> 795.00099 | C22: =IF(B21=0,0,B22/B21) -> 0.13471595
A23: biaya waste (kerugian normal) yang masuk HPP (Rp jt; % biaya produksi) | B23: =E78/10^6 -> 155.53505 | C23: =IF(E66=0,0,E78/E66) -> 0.027961013
A24: KW 2 dikreditkan pada NRV (Rp jt) | B24: =-E74/10^6 -> 74.121493
A26: 2. Laporan biaya produksi
A27: 2a. Kuantitas (kg)
A28: Pos | B28: Aktual kg | C28: % dari produksi | D28: Budget kg | E28: % budget
A29: WIP awal | B29: =$C$191 -> 357.5
A30: Produksi bulan ini (masuk proses) | B30: =$C$192 -> 236923 | D30: =INDEX(BUDGET!$C$14:$R$14,$E$5) -> 0
A31: Total untuk dipertanggungjawabkan | B31: =B29+B30 -> 237280.5
A32: Premium ke barang jadi | B32: =B31-B33-B34-B35 -> 221027 | C32: =IF(B30=0,0,B32/B30) -> 0.93290647 | D32: =INDEX(BUDGET!$C$10:$R$10,$E$5) -> 0 | E32: =IF(D30=0,0,D32/D30) -> 0
A33: KW 2 (produk sampingan) | B33: =$C$194 -> 7581 | C33: =IF(B30=0,0,B33/B30) -> 0.031997738 | D33: =INDEX(BUDGET!$C$11:$R$11,$E$5) -> 0 | E33: =IF(D30=0,0,D33/D30) -> 0
A34: Keripik waste (kerugian normal) | B34: =$C$195 -> 6500 | C34: =IF(B30=0,0,B34/B30) -> 0.027435074 | D34: =INDEX(BUDGET!$C$12:$R$12,$E$5) -> 0 | E34: =IF(D30=0,0,D34/D30) -> 0
A35: WIP akhir | B35: =$C$193 -> 2172.5 | C35: =IF(B30=0,0,B35/B30) -> 0.0091696458 | D35: =INDEX(BUDGET!$C$13:$R$13,$E$5) -> 0 | E35: =IF(D30=0,0,D35/D30) -> 0
A36: Total dipertanggungjawabkan | B36: =SUM(B32:B35) -> 237280.5
A38: 2b. Biaya produksi bulan ini (aktual)
A39: Komponen | B39: Qty | C39: Satuan | D39: Harga | E39: Nilai (Rp) | F39: Rp/kg
A40: Raw materials
A41: Singkong kulit premium | B41: =D215 -> 347092.26 | C41: kg | D41: =F215 -> 2942.8302 | E41: =G215 -> 1.0214336e+09 | F41: =IF($B$30=0,0,E41/$B$30) -> 4311.247
A42: Singkong daging premium | B42: =D216 -> 280280 | C42: kg | D42: =F216 -> 4597.3384 | E42: =G216 -> 1.288542e+09 | F42: =IF($B$30=0,0,E42/$B$30) -> 5438.6531
A43: Ongkos kirim singkong (5101-016 per tanggal kirim; BIAYA BERSAMA bagian 8) | C43: Rp | E43: ='BIAYA BERSAMA'!$C$159 -> 41897465 | F43: =IF($B$30=0,0,E43/$B$30) -> 176.84001
A44: Subtotal raw materials | E44: =E41+E42+E43 -> 2.351873e+09 | F44: =IF($B$30=0,0,E44/$B$30) -> 9926.7401
A45: Oil & CNG
A46: Minyak olein | B46: =D217 -> 57870 | C46: kg | D46: =F217 -> 17512.15 | E46: =G217 -> 1.0134281e+09 | F46: =IF($B$30=0,0,E46/$B$30) -> 4277.4576
...

Sheet UU
A1: KARTU BIAYA PRODUKSI - UBI UNGU IFM (QKSP)
A5: Bulan budget pembanding | C5: Sep-26 | D5: posisi: | E5: =MATCH(C5,BUDGET!$C$4:$R$4,0) -> 1
A6: Status kontrol (bagian 6) | C6: =IF(COUNTIF(D148:D158,"GAGAL")=0,"LULUS","GAGAL") -> LULUS
A8: 1. Ringkasan (Rp juta; Rp/kg per kg produksi bulan ini)
A9: Komponen | B9: Aktual (Rp jt) | C9: Aktual Rp/kg | D9: Budget Rp/kg | E9: Selisih Rp/kg | F9: Harga / belanja | G9: Pemakaian / yield | H9: Volume | I9: Metode alokasi
A10: Raw materials | B10: =E44/10^6 -> 8.4016 | C10: =F44 -> 17971.337 | D10: =G105 -> 0 | E10: =H105 -> 17971.337 | F10: =I105 -> 17971.337 | G10: =J105 -> 0 | H10: =K105 -> 0 | I10: =L105 -> 0
A11: Oil | B11: =E46/10^6 -> 2.2415551 | C11: =F46 -> 4794.7703 | D11: =G107 -> 0 | E11: =H107 -> 4794.7703 | F11: =I107 -> 4794.7703 | G11: =J107 -> 0 | H11: =K107 -> 0 | I11: =L107 -> 0
A12: CNG | B12: =E47/10^6 -> 1.4432029 | C12: =F47 -> 3087.065 | D12: =G109 -> 0 | E12: =H109 -> 3087.065 | F12: =I109 -> 3087.065 | G12: =J109 -> 0 | H12: =K109 -> 0 | I12: =L109 -> 0
A13: Material - others | B13: =E55/10^6 -> 0.36109135 | C13: =F55 -> 772.38791 | D13: =G116 -> 0 | E13: =H116 -> 772.38791 | F13: =I116 -> 697.6381 | G13: =J116 -> 74.749813 | H13: =K116 -> 0 | I13: =L116 -> 0
A14: Upah kupas | B14: =E58/10^6 -> 0 | C14: =F58 -> 0 | D14: =G118 -> 0 | E14: =H118 -> 0 | F14: =I118 -> 0 | G14: =J118 -> 0 | H14: =K118 -> 0 | I14: =L118 -> 0
A15: Direct labour (Grup A) | B15: =E59/10^6 -> 1.9761847 | C15: =F59 -> 4227.1331 | D15: =G120 -> 0 | E15: =H120 -> 4227.1331 | F15: =I120 -> 1922.5851 | G15: =J120 -> 0 | H15: =K120 -> 0 | I15: =L120 -> 2304.548
A16: Factory overhead (Grup B–E) | B16: =E64/10^6 -> 3.8040866 | C16: =F64 -> 8137.0837 | D16: =G125 -> 0 | E16: =H125 -> 8137.0837 | F16: =I125 -> 3910.1301 | G16: =J125 -> 0 | H16: =K125 -> 0 | I16: =L125 -> 4226.9537
A17: Total biaya produksi | B17: =E66/10^6 -> 18.227721 | C17: =F66 -> 38989.777 | D17: =G126 -> 0 | E17: =H126 -> 38989.777 | F17: =I126 -> 32383.525 | G17: =J126 -> 74.749813 | H17: =K126 -> 0 | I17: =L126 -> 6531.5017
A18: Produksi bulan ini (kg; aktual, budget) | C18: =$B$32 -> 467.5 | D18: =$D$32 -> 0
A19: Biaya konversi per kg (aktual, budget) | C19: =F65 -> 12364.217 | D19: =G118+G120+G125 -> 0
A20: HPP (Rp jt) dan HPP per kg terjual (aktual, budget) | B20: =E98/10^6 -> 232.70642 | C20: =D99 -> 35083.132 | D20: =F99 -> 0
A21: Pendapatan (Rp jt; aktual) | B21: =$C$207/10^6 -> 321.7005
A22: Margin kotor (Rp jt; %) | B22: =B21-B20 -> 88.994083 | C22: =IF(B21=0,0,B22/B21) -> 0.27663644
A23: biaya waste (kerugian normal) yang masuk HPP (Rp jt; % biaya produksi) | B23: =E76/10^6 -> 0 | C23: =IF(E66=0,0,E76/E66) -> 0
A24: KW 2 dikreditkan pada NRV (Rp jt) | B24: =-E72/10^6 -> 0
A25: kenaikan WIP + FG (Rp jt) dan porsi biaya konversi di dalamnya | B25: =(E77+E89-E70-E84)/10^6 -> -214.4787 | C25: =IF(E66=0,0,B25*E65/E66) -> -68.014267
A28: 2. Laporan biaya produksi
A29: 2a. Kuantitas (kg)
A30: Pos | B30: Aktual kg | C30: % dari produksi | D30: Budget kg | E30: % budget
A31: WIP awal | B31: =$C$191 -> 4042.5
A32: Produksi bulan ini (masuk proses) | B32: =$C$192 -> 467.5 | D32: =INDEX(BUDGET!$C$99:$R$99,$E$5) -> 0
A33: Total untuk dipertanggungjawabkan | B33: =B31+B32 -> 4510
A34: Premium ke barang jadi | B34: =B33-B35-B36-B37 -> 4510 | C34: =IF(B32=0,0,B34/B32) -> 9.6470588 | D34: =INDEX(BUDGET!$C$95:$R$95,$E$5) -> 0 | E34: =IF(D32=0,0,D34/D32) -> 0
A35: KW 2 (produk sampingan) | B35: =$C$194 -> 0 | C35: =IF(B32=0,0,B35/B32) -> 0 | D35: =INDEX(BUDGET!$C$96:$R$96,$E$5) -> 0 | E35: =IF(D32=0,0,D35/D32) -> 0
A36: Keripik waste (kerugian normal) | B36: =$C$195 -> 0 | C36: =IF(B32=0,0,B36/B32) -> 0 | D36: =INDEX(BUDGET!$C$97:$R$97,$E$5) -> 0 | E36: =IF(D32=0,0,D36/D32) -> 0
A37: WIP akhir | B37: =$C$193 -> 0 | C37: =IF(B32=0,0,B37/B32) -> 0 | D37: =INDEX(BUDGET!$C$98:$R$98,$E$5) -> 0 | E37: =IF(D32=0,0,D37/D32) -> 0
A38: Total dipertanggungjawabkan | B38: =SUM(B34:B37) -> 4510
A40: 2b. Biaya produksi bulan ini (aktual)
A41: Komponen | B41: Qty | C41: Satuan | D41: Harga | E41: Nilai (Rp) | F41: Rp/kg
A42: Raw materials
A43: Ubi ungu | B43: =D211 -> 1424 | C43: kg | D43: =F211 -> 5900 | E43: =G211 -> 8401600 | F43: =IF($B$32=0,0,E43/$B$32) -> 17971.337
A44: Subtotal raw materials | E44: =E43 -> 8401600 | F44: =IF($B$32=0,0,E44/$B$32) -> 17971.337
A45: Oil & CNG
A46: Minyak olein | B46: =D212 -> 128 | C46: kg | D46: =F212 -> 17512.15 | E46: =G212 -> 2241555.1 | F46: =IF($B$32=0,0,E46/$B$32) -> 4794.7703
A47: CNG | B47: =D213/$C$206 -> 6.3808475 | C47: MMBTU | D47: =IF(B47=0,0,E47/B47) -> 226177.3 | E47: =G213 -> 1443202.9 | F47: =IF($B$32=0,0,E47/$B$32) -> 3087.065
...

Sheet UO
A1: KARTU BIAYA PRODUKSI - UBI ORANGE IFM (QKSO)
A3: Bulan budget pembanding | C3: Sep-26 | D3: posisi: | E3: =MATCH(C3,BUDGET!$C$4:$R$4,0) -> 1
A4: Status kontrol (bagian 6) | C4: =IF(COUNTIF(D144:D154,"GAGAL")=0,"LULUS","GAGAL") -> LULUS
A6: 1. Ringkasan (Rp juta; Rp/kg per kg produksi bulan ini)
A7: Komponen | B7: Aktual (Rp jt) | C7: Aktual Rp/kg | D7: Budget Rp/kg | E7: Selisih Rp/kg | F7: Harga / belanja | G7: Pemakaian / yield | H7: Volume | I7: Metode alokasi
A8: Raw materials | B8: =E40/10^6 -> 113.0153 | C8: =F40 -> 16829.022 | D8: =G101 -> 0 | E8: =H101 -> 16829.022 | F8: =I101 -> 16829.022 | G8: =J101 -> 0 | H8: =K101 -> 0 | I8: =L101 -> 0
A9: Oil | B9: =E42/10^6 -> 32.502549 | C9: =F42 -> 4839.9299 | D9: =G103 -> 0 | E9: =H103 -> 4839.9299 | F9: =I103 -> 4839.9299 | G9: =J103 -> 0 | H9: =K103 -> 0 | I9: =L103 -> 0
A10: CNG | B10: =E43/10^6 -> 23.315035 | C10: =F43 -> 3471.8241 | D10: =G105 -> 0 | E10: =H105 -> 3471.8241 | F10: =I105 -> 3471.8241 | G10: =J105 -> 0 | H10: =K105 -> 0 | I10: =L105 -> 0
A11: Material - others | B11: =E51/10^6 -> 4.7678182 | C11: =F51 -> 709.97218 | D11: =G112 -> 0 | E11: =H112 -> 709.97218 | F11: =I112 -> 660.4993 | G11: =J112 -> 49.472884 | H11: =K112 -> 0 | I11: =L112 -> 0
A12: Upah kupas | B12: =E54/10^6 -> 0 | C12: =F54 -> 0 | D12: =G114 -> 0 | E12: =H114 -> 0 | F12: =I114 -> 0 | G12: =J114 -> 0 | H12: =K114 -> 0 | I12: =L114 -> 0
A13: Direct labour (Grup A) | B13: =E55/10^6 -> 24.083394 | C13: =F55 -> 3586.2399 | D13: =G116 -> 0 | E13: =H116 -> 3586.2399 | F13: =I116 -> 1922.5851 | G13: =J116 -> 0 | H13: =K116 -> 0 | I13: =L116 -> 1663.6548
A14: Factory overhead (Grup B–E) | B14: =E60/10^6 -> 54.882506 | C14: =F60 -> 8172.5123 | D14: =G121 -> 0 | E14: =H121 -> 8172.5123 | F14: =I121 -> 3958.7104 | G14: =J121 -> 0 | H14: =K121 -> 0 | I14: =L121 -> 4213.8019
A15: Total biaya produksi | B15: =E62/10^6 -> 252.5666 | C15: =F62 -> 37609.501 | D15: =G122 -> 0 | E15: =H122 -> 37609.501 | F15: =I122 -> 31682.571 | G15: =J122 -> 49.472884 | H15: =K122 -> 0 | I15: =L122 -> 5877.4567
A16: Produksi bulan ini (kg; aktual, budget) | C16: =$B$28 -> 6715.5 | D16: =$D$28 -> 0
A17: Biaya konversi per kg (aktual, budget) | C17: =F61 -> 11758.752 | D17: =G114+G116+G121 -> 0
A18: HPP (Rp jt) dan HPP per kg terjual (aktual, budget) | B18: =E94/10^6 -> 252.5666 | C18: =D95 -> 37609.501 | D18: =F95 -> 0
A19: Pendapatan (Rp jt; aktual) | B19: =$C$203/10^6 -> 321.67245
A20: Margin kotor (Rp jt; %) | B20: =B19-B18 -> 69.105847 | C20: =IF(B19=0,0,B20/B19) -> 0.21483297
A21: Biaya waste (kerugian normal) yang masuk HPP (Rp jt; % biaya produksi) | B21: =E72/10^6 -> 0 | C21: =IF(E62=0,0,E72/E62) -> 0
A22: KW 2 dikreditkan pada NRV (Rp jt) | B22: =-E68/10^6 -> 0
A24: 2. Laporan biaya produksi
A25: 2a. Kuantitas (kg)
A26: Pos | B26: Aktual kg | C26: % dari produksi | D26: Budget kg | E26: % budget
A27: WIP awal | B27: =$C$187 -> 0
A28: Produksi bulan ini (masuk proses) | B28: =$C$188 -> 6715.5 | D28: =INDEX(BUDGET!$C$152:$R$152,$E$3) -> 0
A29: Total untuk dipertanggungjawabkan | B29: =B27+B28 -> 6715.5
A30: Premium ke barang jadi | B30: =B29-B31-B32-B33 -> 6715.5 | C30: =IF(B28=0,0,B30/B28) -> 1 | D30: =INDEX(BUDGET!$C$148:$R$148,$E$3) -> 0 | E30: =IF(D28=0,0,D30/D28) -> 0
A31: KW 2 (produk sampingan) | B31: =$C$190 -> 0 | C31: =IF(B28=0,0,B31/B28) -> 0 | D31: =INDEX(BUDGET!$C$149:$R$149,$E$3) -> 0 | E31: =IF(D28=0,0,D31/D28) -> 0
A32: Keripik waste (kerugian normal) | B32: =$C$191 -> 0 | C32: =IF(B28=0,0,B32/B28) -> 0 | D32: =INDEX(BUDGET!$C$150:$R$150,$E$3) -> 0 | E32: =IF(D28=0,0,D32/D28) -> 0
A33: WIP akhir | B33: =$C$189 -> 0 | C33: =IF(B28=0,0,B33/B28) -> 0 | D33: =INDEX(BUDGET!$C$151:$R$151,$E$3) -> 0 | E33: =IF(D28=0,0,D33/D28) -> 0
A34: Total dipertanggungjawabkan | B34: =SUM(B30:B33) -> 6715.5
A36: 2b. Biaya produksi bulan ini (aktual)
A37: Komponen | B37: Qty | C37: Satuan | D37: Harga | E37: Nilai (Rp) | F37: Rp/kg
A38: Raw materials
A39: Ubi orange | B39: =D207 -> 24028 | C39: kg | D39: =F207 -> 4703.4834 | E39: =G207 -> 1.130153e+08 | F39: =IF($B$28=0,0,E39/$B$28) -> 16829.022
A40: Subtotal raw materials | E40: =E39 -> 1.130153e+08 | F40: =IF($B$28=0,0,E40/$B$28) -> 16829.022
A41: Oil & CNG
A42: Minyak olein | B42: =D208 -> 1856 | C42: kg | D42: =F208 -> 17512.15 | E42: =G208 -> 32502549 | F42: =IF($B$28=0,0,E42/$B$28) -> 4839.9299
A43: CNG | B43: =D209/$C$202 -> 103.083 | C43: MMBTU | D43: =IF(B43=0,0,E43/B43) -> 226177.3 | E43: =G209 -> 23315035 | F43: =IF($B$28=0,0,E43/$B$28) -> 3471.8241
A44: Material - others
...

Sheet LAIN-LAIN
A1: KARTU BIAYA PRODUKSI – LAIN-LAIN (retail, koperasi, maklon), September 2026
A5: Bulan budget pembanding | C5: Sep-26 | D5: posisi: | E5: =MATCH(C5,BUDGET!$C$4:$R$4,0) -> 1
A6: Status kontrol (bagian 4) | C6: =IF(AND(COUNTIF(D72:D75,"GAGAL")=0,COUNTIF(D107:D110,"GAGAL")=0),"LULUS","GAGAL") -> LULUS
A7: Nilai KW 2 ubi (Rp/kg) | C7: 0
A9: 1. Ringkasan (Rp juta)
A10: Pos | B10: Aktual (Rp jt) | C10: Budget (Rp jt) | D10: Selisih
A11: Material eksternal + konversi (tanpa bahan antarproduk) | B11: =(D68+E68+F68)/10^6 -> 277.66776 | C11: =INDEX(BUDGET!$C$198:$R$198,$E$5)/10^6 -> 0 | D11: =B11-C11 -> 277.66776
A12: Bahan antarproduk (FCC premium, KW 2) | B12: =(B68+C68)/10^6 -> 593.31031
A13: di dalamnya: konversi (DL + FOH) | B13: =(E68+F68)/10^6 -> 200.99415
A14: Total biaya produksi Lain-lain | B14: =G68/10^6 -> 870.97808 | C14: =INDEX(BUDGET!$C$199:$R$199,$E$5)/10^6 -> 0 | D14: =B14-C14 -> 870.97808
A15: Output (kg) | B15: =C43 -> 45653.42
A16: Biaya per kg (Rp) | B16: =H68 -> 19078.047
A17: Pendapatan Others: retail & maklon + KW 2 berbumbu (Rp jt; BP Data Aktual P68 + P65) | B17: ='REKON & KONTROL'!$C$74/10^6 -> 917.67406
A18: Margin kotor Others (Rp jt; %) | B18: =B17-B19 -> 46.092335 | C18: =IF(B17=0,0,B18/B17) -> 0.050227349
A19: HPP Lain-lain (biaya produksi − kenaikan barang jadi; bagian 5) | B19: =G93/10^6 -> 871.58173
A20: 2. Input per kelompok produk – ditautkan dari sheet per SKU (sel hijau)
A21: Kelompok produk | B21: Lini bahan utama (akun varian) | C21: Output (kg) | D21: Input FCC premium (kg) | E21: Input KW 2 FCC (kg) | F21: Input KW 2 ubi (kg) | G21: Material eksternal (Rp) | H21: Man-hour | I21: kWh | J21: Sumber
A22: Cem-cem ORI | B22: Singkong | C22: ='CEM-CEM ORI'!$B$21 -> 11035.8 | D22: ='CEM-CEM ORI'!$B$23 -> 10411.5 | E22: ='CEM-CEM ORI'!$B$24 -> 0 | F22: ='CEM-CEM ORI'!$B$25 -> 0 | G22: ='CEM-CEM ORI'!$E$34 -> 712800 | H22: ='CEM-CEM ORI'!$C$106 -> 882.2823 | I22: ='CEM-CEM ORI'!$C$107 -> 3936.4737 | J22: Tautan ke sheet CEM-CEM ORI
A23: Cem-cem BBQ | B23: Singkong | C23: ='CEM-CEM BBQ'!$B$21 -> 10305 | D23: ='CEM-CEM BBQ'!$B$23 -> 9669 | E23: ='CEM-CEM BBQ'!$B$24 -> 0 | F23: ='CEM-CEM BBQ'!$B$25 -> 0 | G23: ='CEM-CEM BBQ'!$E$34 -> 0 | H23: ='CEM-CEM BBQ'!$C$106 -> 787.7177 | I23: ='CEM-CEM BBQ'!$C$107 -> 3528.262 | J23: Tautan ke sheet CEM-CEM BBQ
A24: Koperasi (KW 2 berbumbu, 11 SKU) | B24: Singkong | C24: =KOPERASI!$M$7 -> 2967.5 | D24: =KOPERASI!$M$9 -> 10 | E24: =KOPERASI!$M$10 -> 2002 | F24: =KOPERASI!$M$11 -> 770 | G24: =KOPERASI!$M$15 -> 6333602.8 | H24: =KOPERASI!$M$12 -> 89.3397 | I24: 0 | J24: Tautan ke sheet KOPERASI
A25: Maicih basreng (maklon, 3 SKU) | B25: Singkong (maklon) | C25: ='MCH BASRENG L0'!$B$21+'MCH BASRENG L5'!$B$21+'MCH BASRENG L10'!$B$21 -> 926.56 | D25: ='MCH BASRENG L0'!$B$23+'MCH BASRENG L5'!$B$23+'MCH BASRENG L10'!$B$23 -> 0 | E25: ='MCH BASRENG L0'!$B$24+'MCH BASRENG L5'!$B$24+'MCH BASRENG L10'!$B$24 -> 0 | F25: ='MCH BASRENG L0'!$B$25+'MCH BASRENG L5'!$B$25+'MCH BASRENG L10'!$B$25 -> 0 | G25: ='MCH BASRENG L0'!$E$34+'MCH BASRENG L5'!$E$34+'MCH BASRENG L10'!$E$34 -> 42696.287 | H25: ='MCH BASRENG L0'!$C$106+'MCH BASRENG L5'!$C$106+'MCH BASRENG L10'!$C$106 -> 61.9399 | I25: ='MCH BASRENG L0'!$C$107+'MCH BASRENG L5'!$C$107+'MCH BASRENG L10'!$C$107 -> 342.8894 | J25: Tautan ke sheet MCH BASRENG L0, MCH BASRENG L5, MCH BASRENG L10
A26: Maicih keripik (LV 3 & 10) | B26: Singkong | C26: ='MCH KERIPIK LV3'!$B$21+'MCH KERIPIK LV10'!$B$21 -> 4015.04 | D26: ='MCH KERIPIK LV3'!$B$23+'MCH KERIPIK LV10'!$B$23 -> 2123 | E26: ='MCH KERIPIK LV3'!$B$24+'MCH KERIPIK LV10'!$B$24 -> 1627.7814 | F26: ='MCH KERIPIK LV3'!$B$25+'MCH KERIPIK LV10'!$B$25 -> 0 | G26: ='MCH KERIPIK LV3'!$E$34+'MCH KERIPIK LV10'!$E$34 -> 604941.04 | H26: ='MCH KERIPIK LV3'!$C$106+'MCH KERIPIK LV10'!$C$106 -> 257.6489 | I26: ='MCH KERIPIK LV3'!$C$107+'MCH KERIPIK LV10'!$C$107 -> 1557.5873 | J26: Tautan ke sheet MCH KERIPIK LV3, MCH KERIPIK LV10
A27: Maicih keripik LV 5 | B27: Singkong | C27: ='MCH KERIPIK LV5'!$B$21 -> 1601.04 | D27: ='MCH KERIPIK LV5'!$B$23 -> 902 | E27: ='MCH KERIPIK LV5'!$B$24 -> 612.21865 | F27: ='MCH KERIPIK LV5'!$B$25 -> 0 | G27: ='MCH KERIPIK LV5'!$E$34 -> 231126.4 | H27: ='MCH KERIPIK LV5'!$C$106 -> 145.2214 | I27: ='MCH KERIPIK LV5'!$C$107 -> 617.8482 | J27: Tautan ke sheet MCH KERIPIK LV5
A28: FCC Maicih | B28: Singkong | C28: 0 | D28: 0 | E28: 0 | F28: 0 | G28: 0 | H28: 0 | I28: 0
A29: FCC Putih | B29: Singkong | C29: 0 | D29: 0 | E29: 0 | F29: 0 | G29: 0 | H29: 0 | I29: 0
A30: Kecimpring (goreng & bagging) | B30: Singkong | C30: 0 | D30: 0 | E30: 0 | F30: 0 | G30: 0 | H30: 0 | I30: 0
A31: Whole chips rempah 15/90 gr | B31: Singkong | C31: 0 | D31: 0 | E31: 0 | F31: 0 | G31: 0 | H31: 0 | I31: 0
A32: Maxi (pellet & goreng) | B32: Singkong – cek bahan | C32: 0 | D32: 0 | E32: 0 | F32: 0 | G32: 0 | H32: 0 | I32: 0
A33: Pellet ubi ungu FG (1,2x1,5 & 3x3) | B33: Ubi Ungu | C33: 0 | D33: 0 | E33: 0 | F33: 0 | G33: 0 | H33: 0 | I33: 0
A34: Keripik ubi ungu retail (goreng, bagging bakar/ori, NYEE) | B34: Ubi Ungu | C34: 0 | D34: 0 | E34: 0 | F34: 0 | G34: 0 | H34: 0 | I34: 0
A35: Whole chips ubi ungu 15/90 gr | B35: Ubi Ungu | C35: 0 | D35: 0 | E35: 0 | F35: 0 | G35: 0 | H35: 0 | I35: 0
A36: Umbiis (goreng & bagging) | B36: Ubi Ungu – cek bahan | C36: 0 | D36: 0 | E36: 0 | F36: 0 | G36: 0 | H36: 0 | I36: 0
A37: Ubi ungu chips | B37: Ubi Ungu | C37: 0 | D37: 0 | E37: 0 | F37: 0 | G37: 0 | H37: 0 | I37: 0
A38: Pellet ubi orange FG 3x3 | B38: Ubi Orange | C38: 0 | D38: 0 | E38: 0 | F38: 0 | G38: 0 | H38: 0 | I38: 0
A39: Ubi orange chips | B39: Ubi Orange | C39: 0 | D39: 0 | E39: 0 | F39: 0 | G39: 0 | H39: 0 | I39: 0
A40: Pellet lainnya | B40: Cek bahan | C40: 0 | D40: 0 | E40: 0 | F40: 0 | G40: 0 | H40: 0 | I40: 0
A41: Ubi putih ACE (Sweet Potato N110), ubi putih & talas chips | B41: Singkong (lain) | C41: ='UBI PUTIH ACE'!$B$21 -> 14802.48 | D41: ='UBI PUTIH ACE'!$B$23 -> 0 | E41: ='UBI PUTIH ACE'!$B$24 -> 0 | F41: ='UBI PUTIH ACE'!$B$25 -> 0 | G41: ='UBI PUTIH ACE'!$E$34 -> 68748452 | H41: ='UBI PUTIH ACE'!$C$106 -> 465 | I41: ='UBI PUTIH ACE'!$C$107 -> 134.9986 | J41: Tautan ke sheet UBI PUTIH ACE
A42: WRP (Delichips, Mixfruit, chips) – maklon | B42: Singkong (maklon) | C42: 0 | D42: 0 | E42: 0 | F42: 0 | G42: 0 | H42: 0 | I42: 0
A43: Total | C43: =SUM(C22:C42) -> 45653.42 | D43: =SUM(D22:D42) -> 23115.5 | E43: =SUM(E22:E42) -> 4242 | F43: =SUM(F22:F42) -> 770 | G43: =SUM(G22:G42) -> 76673619 | H43: =SUM(H22:H42) -> 2689.1499 | I43: =SUM(I22:I42) -> 10118.059
A45: 3. Biaya produksi per kelompok (Rp)
...

Sheet CEM-CEM ORI
A1: KARTU BIAYA PRODUKSI – Cem-cem ORI (Keripik Singkong Original, Cem-Cem Cazva), September 2026
A2: Sumber: kartu 'LAP BAG CEMCEM ORI' di WP CoGM September 2026; driver man-hour & kWh: sheet Labor & Overhead Allocation; barang jadi: Inventory Valuation Accurate FG-180; pendapatan: LK Sales By Item.
A4: Status kontrol (bagian 5) | C4: =IF(COUNTIF(C70:C75,"GAGAL")=0,"LULUS","GAGAL") -> LULUS
A5: 1. Ringkasan (Rp juta; Rp/kg per kg produksi bulan ini)
A6: Komponen | B6: Aktual (Rp jt) | C6: Rp/kg | D6: Porsi
A7: FCC premium (antarproduk) | B7: =E31/10^6 -> 248.5532 | C7: =F31 -> 22522.445 | D7: =IF($B$12=0,0,B7/$B$12) -> 0.78048182
A8: KW 2 (antarproduk, NRV) | B8: =(E32+E33)/10^6 -> 0 | C8: =F32+F33 -> 0 | D8: =IF($B$12=0,0,B8/$B$12) -> 0
A9: Material eksternal | B9: =E34/10^6 -> 0.7128 | C9: =F34 -> 64.58979 | D9: =IF($B$12=0,0,B9/$B$12) -> 0.0022382631
A10: Direct labour (Grup A) | B10: =E37/10^6 -> 19.159921 | C10: =F37 -> 1736.1606 | D10: =IF($B$12=0,0,B10/$B$12) -> 0.060164063
A11: Factory overhead (Grup B–E) | B11: =E41/10^6 -> 50.035306 | C11: =F41 -> 4533.9084 | D11: =IF($B$12=0,0,B11/$B$12) -> 0.15711585
A12: Total biaya produksi | B12: =E43/10^6 -> 318.46122 | C12: =F43 -> 28857.104 | D12: =IF($B$12=0,0,B12/$B$12) -> 1
A13: Produksi (kg; satuan FG) | B13: =B21 -> 11035.8 | C13: =C21 -> 183930
A14: HPP (Rp jt) dan HPP per satuan terjual | B14: =D54/10^6 -> 332.36029 | C14: =C55 -> 1725.6505
A15: Pendapatan (Rp jt) dan harga per satuan | B15: =$C$118/10^6 -> 329.346 | C15: =IF($C$117=0,0,$C$118/$C$117) -> 1710
A16: Margin kotor (Rp jt; %) | B16: =B15-B14 -> -3.0142886 | C16: =IF(B15=0,0,B16/B15) -> -0.0091523462
A18: 2. Laporan biaya produksi
A19: 2a. Kuantitas
A20: Pos | B20: Kg | C20: Satuan FG (bag) | D20: Keterangan
A21: Output produksi | B21: =$C$102 -> 11035.8 | C21: =$C$103 -> 183930
A22: Sampel | B22: =$C$104 -> 19.44 | C22: =$C$105 -> 324 | D22: memo, tidak masuk barang jadi
A23: Input FCC premium | B23: =SUMIF($B$128:$B$130,"FCC",$C$128:$C$130) -> 10411.5 | D23: Lampiran B
A24: Input KW 2 FCC | B24: =SUMIF($B$128:$B$130,"KW2",$C$128:$C$130) -> 0 | D24: Lampiran B
A25: Input KW 2 ubi | B25: =SUMIF($B$128:$B$130,"KW2UBI",$C$128:$C$130) -> 0 | D25: Lampiran B
A26: Rendemen output ÷ input keripik (kg/kg) | B26: =IF(SUM(B23:B25)=0,0,B21/SUM(B23:B25)) -> 1.0599625
A28: 2b. Biaya produksi bulan ini (aktual)
A29: Komponen | B29: Qty / driver | C29: Satuan | D29: Harga / porsi | E29: Nilai (Rp) | F29: Rp/kg | G29: Dasar
A30: Bahan
A31: FCC premium (antarproduk) | B31: =B23 -> 10411.5 | C31: kg | D31: =FCC!$D$89 -> 23872.948 | E31: =B31*D31 -> 2.485532e+08 | F31: =IF($B$21=0,0,E31/$B$21) -> 22522.445 | G31: Biaya rata-rata FG FCC kartu baru (FCC D88)
A32: KW 2 FCC (antarproduk, NRV) | B32: =B24 -> 0 | C32: kg | D32: =FCC!$C$209 -> 9777.2712 | E32: =B32*D32 -> 0 | F32: =IF($B$21=0,0,E32/$B$21) -> 0 | G32: NRV KW 2 (FCC C208)
A33: KW 2 ubi (antarproduk) | B33: =B25 -> 0 | C33: kg | D33: ='LAIN-LAIN'!$C$7 -> 0 | E33: =B33*D33 -> 0 | F33: =IF($B$21=0,0,E33/$B$21) -> 0 | G33: Nilai KW 2 ubi (LAIN-LAIN C7)
A34: Material eksternal (Lampiran B) | E34: =SUMIF($B$128:$B$130,"EXT",$F$128:$F$130) -> 712800 | F34: =IF($B$21=0,0,E34/$B$21) -> 64.58979 | G34: Nilai kartu per baris material
A35: Subtotal bahan | E35: =SUM(E31:E34) -> 2.49266e+08 | F35: =IF($B$21=0,0,E35/$B$21) -> 22587.035
A36: Konversi (pool BIAYA BERSAMA, porsi Lain-lain dibagi dengan driver yang sama dengan sheet LAIN-LAIN)
A37: Grup A – DL operator | B37: =$C$106 -> 882.2823 | C37: jam | D37: =IF('LAIN-LAIN'!$H$43=0,0,B37/'LAIN-LAIN'!$H$43) -> 0.32808967 | E37: =D37*'BIAYA BERSAMA'!$F$115 -> 19159921 | F37: =IF($B$21=0,0,E37/$B$21) -> 1736.1606 | G37: Man-hour ÷ total man-hour Lain-lain × pool Grup A Lain-lain
A38: Grup B – IDL (support, staf, THR, BPJS) | B38: =$C$106 -> 882.2823 | C38: jam | D38: =IF('LAIN-LAIN'!$H$43=0,0,B38/'LAIN-LAIN'!$H$43) -> 0.32808967 | E38: =D38*'BIAYA BERSAMA'!$F$117 -> 17128969 | F38: =IF($B$21=0,0,E38/$B$21) -> 1552.1276 | G38: Man-hour
A39: Grup C + D – energi (kWh) dan mesin (bagging: kWh; Ubi putih ACE: jam mesin) | B39: =$C$107 -> 3936.4737 | C39: kWh | D39: =IF('LAIN-LAIN'!$I$43=0,0,B39/'LAIN-LAIN'!$I$43) -> 0.38905423 | E39: =D39*'BIAYA BERSAMA'!$F$118+IF('BIAYA BERSAMA'!$F$172=0,0,B39/'BIAYA BERSAMA'!$F$172)*'BIAYA BERSAMA'!$F$176 -> 32863524 | F39: =IF($B$21=0,0,E39/$B$21) -> 2977.9014 | G39: kWh
A40: Grup E – pabrik umum | B40: =E34 -> 712800 | C40: Rp | D40: =IF('LAIN-LAIN'!$G$43=0,0,B40/'LAIN-LAIN'!$G$43) -> 0.0092965483 | E40: =D40*'BIAYA BERSAMA'!$F$120 -> 42812.599 | F40: =IF($B$21=0,0,E40/$B$21) -> 3.8794287 | G40: Nilai material eksternal
A41: Subtotal factory overhead (Grup B–E) | E41: =SUM(E38:E40) -> 50035306 | F41: =IF($B$21=0,0,E41/$B$21) -> 4533.9084
A42: Total konversi | E42: =E37+E41 -> 69195227 | F42: =IF($B$21=0,0,E42/$B$21) -> 6270.069
A43: TOTAL BIAYA PRODUKSI BULAN INI | E43: =E35+E42 -> 3.1846122e+08 | F43: =IF($B$21=0,0,E43/$B$21) -> 28857.104
...

Sheet CEM-CEM BBQ
A1: KARTU BIAYA PRODUKSI – Cem-cem BBQ (Keripik Singkong BBQ, Cem-Cem Cazva), September 2026
A2: Sumber: kartu 'LAP BAG CEMCEM BBQ' di WP CoGM September 2026; driver man-hour & kWh: sheet Labor & Overhead Allocation; barang jadi: Inventory Valuation Accurate FG-181; pendapatan: LK Sales By Item.
A4: Status kontrol (bagian 5) | C4: =IF(COUNTIF(C70:C75,"GAGAL")=0,"LULUS","GAGAL") -> LULUS
A5: 1. Ringkasan (Rp juta; Rp/kg per kg produksi bulan ini)
A6: Komponen | B6: Aktual (Rp jt) | C6: Rp/kg | D6: Porsi
A7: FCC premium (antarproduk) | B7: =E31/10^6 -> 230.82753 | C7: =F31 -> 22399.567 | D7: =IF($B$12=0,0,B7/$B$12) -> 0.7886619
A8: KW 2 (antarproduk, NRV) | B8: =(E32+E33)/10^6 -> 0 | C8: =F32+F33 -> 0 | D8: =IF($B$12=0,0,B8/$B$12) -> 0
A9: Material eksternal | B9: =E34/10^6 -> 0 | C9: =F34 -> 0 | D9: =IF($B$12=0,0,B9/$B$12) -> 0
A10: Direct labour (Grup A) | B10: =E37/10^6 -> 17.106326 | C10: =F37 -> 1660.0026 | D10: =IF($B$12=0,0,B10/$B$12) -> 0.058446701
A11: Factory overhead (Grup B–E) | B11: =E41/10^6 -> 44.748638 | C11: =F41 -> 4342.4199 | D11: =IF($B$12=0,0,B11/$B$12) -> 0.1528914
A12: Total biaya produksi | B12: =E43/10^6 -> 292.6825 | C12: =F43 -> 28401.989 | D12: =IF($B$12=0,0,B12/$B$12) -> 1
A13: Produksi (kg; satuan FG) | B13: =B21 -> 10305 | C13: =C21 -> 171750
A14: HPP (Rp jt) dan HPP per satuan terjual | B14: =D54/10^6 -> 279.38708 | C14: =C55 -> 1704.0993
A15: Pendapatan (Rp jt) dan harga per satuan | B15: =$C$118/10^6 -> 277.89525 | C15: =IF($C$117=0,0,$C$118/$C$117) -> 1695
A16: Margin kotor (Rp jt; %) | B16: =B15-B14 -> -1.4918321 | C16: =IF(B15=0,0,B16/B15) -> -0.0053683253
A18: 2. Laporan biaya produksi
A19: 2a. Kuantitas
A20: Pos | B20: Kg | C20: Satuan FG (bag) | D20: Keterangan
A21: Output produksi | B21: =$C$102 -> 10305 | C21: =$C$103 -> 171750
A22: Sampel | B22: =$C$104 -> 12.24 | C22: =$C$105 -> 204 | D22: memo, tidak masuk barang jadi
A23: Input FCC premium | B23: =SUMIF($B$128:$B$130,"FCC",$C$128:$C$130) -> 9669 | D23: Lampiran B
A24: Input KW 2 FCC | B24: =SUMIF($B$128:$B$130,"KW2",$C$128:$C$130) -> 0 | D24: Lampiran B
A25: Input KW 2 ubi | B25: =SUMIF($B$128:$B$130,"KW2UBI",$C$128:$C$130) -> 0 | D25: Lampiran B
A26: Rendemen output ÷ input keripik (kg/kg) | B26: =IF(SUM(B23:B25)=0,0,B21/SUM(B23:B25)) -> 1.0657772
A28: 2b. Biaya produksi bulan ini (aktual)
A29: Komponen | B29: Qty / driver | C29: Satuan | D29: Harga / porsi | E29: Nilai (Rp) | F29: Rp/kg | G29: Dasar
A30: Bahan
A31: FCC premium (antarproduk) | B31: =B23 -> 9669 | C31: kg | D31: =FCC!$D$89 -> 23872.948 | E31: =B31*D31 -> 2.3082753e+08 | F31: =IF($B$21=0,0,E31/$B$21) -> 22399.567 | G31: Biaya rata-rata FG FCC kartu baru (FCC D88)
A32: KW 2 FCC (antarproduk, NRV) | B32: =B24 -> 0 | C32: kg | D32: =FCC!$C$209 -> 9777.2712 | E32: =B32*D32 -> 0 | F32: =IF($B$21=0,0,E32/$B$21) -> 0 | G32: NRV KW 2 (FCC C208)
A33: KW 2 ubi (antarproduk) | B33: =B25 -> 0 | C33: kg | D33: ='LAIN-LAIN'!$C$7 -> 0 | E33: =B33*D33 -> 0 | F33: =IF($B$21=0,0,E33/$B$21) -> 0 | G33: Nilai KW 2 ubi (LAIN-LAIN C7)
A34: Material eksternal (Lampiran B) | E34: =SUMIF($B$128:$B$130,"EXT",$F$128:$F$130) -> 0 | F34: =IF($B$21=0,0,E34/$B$21) -> 0 | G34: Nilai kartu per baris material
A35: Subtotal bahan | E35: =SUM(E31:E34) -> 2.3082753e+08 | F35: =IF($B$21=0,0,E35/$B$21) -> 22399.567
A36: Konversi (pool BIAYA BERSAMA, porsi Lain-lain dibagi dengan driver yang sama dengan sheet LAIN-LAIN)
A37: Grup A – DL operator | B37: =$C$106 -> 787.7177 | C37: jam | D37: =IF('LAIN-LAIN'!$H$43=0,0,B37/'LAIN-LAIN'!$H$43) -> 0.29292443 | E37: =D37*'BIAYA BERSAMA'!$F$115 -> 17106326 | F37: =IF($B$21=0,0,E37/$B$21) -> 1660.0026 | G37: Man-hour ÷ total man-hour Lain-lain × pool Grup A Lain-lain
A38: Grup B – IDL (support, staf, THR, BPJS) | B38: =$C$106 -> 787.7177 | C38: jam | D38: =IF('LAIN-LAIN'!$H$43=0,0,B38/'LAIN-LAIN'!$H$43) -> 0.29292443 | E38: =D38*'BIAYA BERSAMA'!$F$117 -> 15293056 | F38: =IF($B$21=0,0,E38/$B$21) -> 1484.0423 | G38: Man-hour
A39: Grup C + D – energi (kWh) dan mesin (bagging: kWh; Ubi putih ACE: jam mesin) | B39: =$C$107 -> 3528.262 | C39: kWh | D39: =IF('LAIN-LAIN'!$I$43=0,0,B39/'LAIN-LAIN'!$I$43) -> 0.34870937 | E39: =D39*'BIAYA BERSAMA'!$F$118+IF('BIAYA BERSAMA'!$F$172=0,0,B39/'BIAYA BERSAMA'!$F$172)*'BIAYA BERSAMA'!$F$176 -> 29455582 | F39: =IF($B$21=0,0,E39/$B$21) -> 2858.3777 | G39: kWh
A40: Grup E – pabrik umum | B40: =E34 -> 0 | C40: Rp | D40: =IF('LAIN-LAIN'!$G$43=0,0,B40/'LAIN-LAIN'!$G$43) -> 0 | E40: =D40*'BIAYA BERSAMA'!$F$120 -> 0 | F40: =IF($B$21=0,0,E40/$B$21) -> 0 | G40: Nilai material eksternal
A41: Subtotal factory overhead (Grup B–E) | E41: =SUM(E38:E40) -> 44748638 | F41: =IF($B$21=0,0,E41/$B$21) -> 4342.4199
A42: Total konversi | E42: =E37+E41 -> 61854964 | F42: =IF($B$21=0,0,E42/$B$21) -> 6002.4225
A43: TOTAL BIAYA PRODUKSI BULAN INI | E43: =E35+E42 -> 2.926825e+08 | F43: =IF($B$21=0,0,E43/$B$21) -> 28401.989
...

Sheet KOPERASI
A1: KARTU BIAYA PRODUKSI – Koperasi – KW 2 berbumbu (per SKU), September 2026
A2: Sumber: kartu 'Bagging Kop' di WP CoGM September 2026 (satu kolom per SKU); driver man-hour: Labor 'Koperasi' dibagi per SKU dengan porsi man-hour kartu; barang jadi: Inventory Valuation; pendapatan: LK Sales By Item.
A4: Status kontrol (bagian 5) | C4: =IF(COUNTIF(C56:C60,"GAGAL")=0,"LULUS","GAGAL") -> LULUS
A5: 1–2. Kuantitas dan biaya produksi per SKU (Rp)
A6: Pos | B6: FCC Kw 2 Bumbu BBQ 1kg | C6: FCC Kw 2 Bumbu Balado 1kg | D6: FCC Kw 2 Bumbu Jagung Manis 1kg | E6: FCC Kw 2 Bumbu Asin 1kg | F6: FCC Kw2 Suka-Suka Bumbu BBQ 2,5kg | G6: FCC Kw2 Suka-suka Bumbu Balado 2,5kg | H6: FCC Kw2 Suka-suka Bumbu Jagung Manis 2,5kg | I6: FCC KW2 Suka-suka Bumbu Asin 2,5kg | J6: FCC Premium Bumbu Asin 250gr | K6: Keripik Ubi Mix Kw2 Rasa Balado 1 Kg | L6: Keripik Ubi Mix Kw2 Rasa BBQ 1 Kg | M6: Total | N6: Dasar
A7: Output produksi (kg) | B7: =B122 -> 434 | C7: =C122 -> 808 | D7: =D122 -> 209 | E7: =E122 -> 70 | F7: =F122 -> 150 | G7: =G122 -> 452.5 | H7: =H122 -> 7.5 | I7: =I122 -> 7.5 | ... L7: =L122 -> 404 | M7: =SUM(B7:L7) -> 2967.5
A8: Output produksi (satuan FG) | B8: =IF(B123=0,0,B7/B123) -> 434 | C8: =IF(C123=0,0,C7/C123) -> 808 | D8: =IF(D123=0,0,D7/D123) -> 209 | E8: =IF(E123=0,0,E7/E123) -> 70 | F8: =IF(F123=0,0,F7/F123) -> 60 | G8: =IF(G123=0,0,G7/G123) -> 181 | H8: =IF(H123=0,0,H7/H123) -> 3 | I8: =IF(I123=0,0,I7/I123) -> 3 | ... L8: =IF(L123=0,0,L7/L123) -> 404 | M8: =SUM(B8:L8) -> 2597
A9: Input FCC premium (kg) | B9: =SUMIF($N$143:$N$167,"FCC",B$143:B$167) -> 0 | C9: =SUMIF($N$143:$N$167,"FCC",C$143:C$167) -> 0 | D9: =SUMIF($N$143:$N$167,"FCC",D$143:D$167) -> 0 | E9: =SUMIF($N$143:$N$167,"FCC",E$143:E$167) -> 0 | F9: =SUMIF($N$143:$N$167,"FCC",F$143:F$167) -> 0 | G9: =SUMIF($N$143:$N$167,"FCC",G$143:G$167) -> 0 | H9: =SUMIF($N$143:$N$167,"FCC",H$143:H$167) -> 0 | I9: =SUMIF($N$143:$N$167,"FCC",I$143:I$167) -> 0 | ... L9: =SUMIF($N$143:$N$167,"FCC",L$143:L$167) -> 0 | M9: =SUM(B9:L9) -> 10 | N9: Lampiran B
A10: Input KW 2 FCC (kg) | B10: =SUMIF($N$143:$N$167,"KW2",B$143:B$167) -> 406 | C10: =SUMIF($N$143:$N$167,"KW2",C$143:C$167) -> 756 | D10: =SUMIF($N$143:$N$167,"KW2",D$143:D$167) -> 195.5 | E10: =SUMIF($N$143:$N$167,"KW2",E$143:E$167) -> 70 | F10: =SUMIF($N$143:$N$167,"KW2",F$143:F$167) -> 140 | G10: =SUMIF($N$143:$N$167,"KW2",G$143:G$167) -> 420 | H10: =SUMIF($N$143:$N$167,"KW2",H$143:H$167) -> 7 | I10: =SUMIF($N$143:$N$167,"KW2",I$143:I$167) -> 7.5 | ... L10: =SUMIF($N$143:$N$167,"KW2",L$143:L$167) -> 0 | M10: =SUM(B10:L10) -> 2002 | N10: Lampiran B
A11: Input KW 2 ubi (kg) | B11: =SUMIF($N$143:$N$167,"KW2UBI",B$143:B$167) -> 0 | C11: =SUMIF($N$143:$N$167,"KW2UBI",C$143:C$167) -> 0 | D11: =SUMIF($N$143:$N$167,"KW2UBI",D$143:D$167) -> 0 | E11: =SUMIF($N$143:$N$167,"KW2UBI",E$143:E$167) -> 0 | F11: =SUMIF($N$143:$N$167,"KW2UBI",F$143:F$167) -> 0 | G11: =SUMIF($N$143:$N$167,"KW2UBI",G$143:G$167) -> 0 | H11: =SUMIF($N$143:$N$167,"KW2UBI",H$143:H$167) -> 0 | I11: =SUMIF($N$143:$N$167,"KW2UBI",I$143:I$167) -> 0 | ... L11: =SUMIF($N$143:$N$167,"KW2UBI",L$143:L$167) -> 378 | M11: =SUM(B11:L11) -> 770 | N11: Lampiran B
A12: Man-hour (driver) | B12: =B125 -> 14.763 | C12: =C125 -> 27.4851 | D12: =D125 -> 7.1094 | E12: =E125 -> 2.3811 | F12: =F125 -> 2.041 | G12: =G125 -> 6.1569 | H12: =H125 -> 0.102 | I12: =I125 -> 0.102 | ... L12: =L125 -> 13.7426 | M12: =SUM(B12:L12) -> 89.3397
A13: FCC premium (antarproduk) – Rp | B13: =B9*FCC!$D$89 -> 0 | C13: =C9*FCC!$D$89 -> 0 | D13: =D9*FCC!$D$89 -> 0 | E13: =E9*FCC!$D$89 -> 0 | F13: =F9*FCC!$D$89 -> 0 | G13: =G9*FCC!$D$89 -> 0 | H13: =H9*FCC!$D$89 -> 0 | I13: =I9*FCC!$D$89 -> 0 | ... L13: =L9*FCC!$D$89 -> 0 | M13: =SUM(B13:L13) -> 238729.48 | N13: Kg × biaya rata-rata FG FCC (FCC D88)
A14: KW 2 (antarproduk, NRV) – Rp | B14: =B10*FCC!$C$209+B11*'LAIN-LAIN'!$C$7 -> 3969572.1 | C14: =C10*FCC!$C$209+C11*'LAIN-LAIN'!$C$7 -> 7391617 | D14: =D10*FCC!$C$209+D11*'LAIN-LAIN'!$C$7 -> 1911456.5 | E14: =E10*FCC!$C$209+E11*'LAIN-LAIN'!$C$7 -> 684408.98 | F14: =F10*FCC!$C$209+F11*'LAIN-LAIN'!$C$7 -> 1368818 | G14: =G10*FCC!$C$209+G11*'LAIN-LAIN'!$C$7 -> 4106453.9 | H14: =H10*FCC!$C$209+H11*'LAIN-LAIN'!$C$7 -> 68440.898 | I14: =I10*FCC!$C$209+I11*'LAIN-LAIN'!$C$7 -> 73329.534 | ... L14: =L10*FCC!$C$209+L11*'LAIN-LAIN'!$C$7 -> 0 | M14: =SUM(B14:L14) -> 19574097 | N14: KW 2 FCC × NRV (FCC C208) + KW 2 ubi × LAIN-LAIN C7
A15: Material eksternal – Rp | B15: =SUMIF($N$170:$N$194,"EXT",B$170:B$194) -> 842769.4 | C15: =SUMIF($N$170:$N$194,"EXT",C$170:C$194) -> 1634122.6 | D15: =SUMIF($N$170:$N$194,"EXT",D$170:D$194) -> 416489.31 | E15: =SUMIF($N$170:$N$194,"EXT",E$170:E$194) -> 20360.126 | F15: =SUMIF($N$170:$N$194,"EXT",F$170:F$194) -> 379194.36 | G15: =SUMIF($N$170:$N$194,"EXT",G$170:G$194) -> 1319934.6 | H15: =SUMIF($N$170:$N$194,"EXT",H$170:H$194) -> 17899.059 | I15: =SUMIF($N$170:$N$194,"EXT",I$170:I$194) -> 213.75 | ... L15: =SUMIF($N$170:$N$194,"EXT",L$170:L$194) -> 796250.69 | M15: =SUM(B15:L15) -> 6333602.8 | N15: Lampiran B kelompok EXT
A16: Subtotal bahan | B16: =SUM(B13:B15) -> 4812341.5 | C16: =SUM(C13:C15) -> 9025739.6 | D16: =SUM(D13:D15) -> 2327945.8 | E16: =SUM(E13:E15) -> 704769.11 | F16: =SUM(F13:F15) -> 1748012.3 | G16: =SUM(G13:G15) -> 5426388.5 | H16: =SUM(H13:H15) -> 86339.957 | I16: =SUM(I13:I15) -> 73543.284 | ... L16: =SUM(L13:L15) -> 796250.69 | M16: =SUM(B16:L16) -> 26146429
A17: Grup A – DL operator | B17: =IF('LAIN-LAIN'!$H$43=0,0,B12/'LAIN-LAIN'!$H$43)*'BIAYA BERSAMA'!$F$115 -> 320597.97 | C17: =IF('LAIN-LAIN'!$H$43=0,0,C12/'LAIN-LAIN'!$H$43)*'BIAYA BERSAMA'!$F$115 -> 596875.11 | D17: =IF('LAIN-LAIN'!$H$43=0,0,D12/'LAIN-LAIN'!$H$43)*'BIAYA BERSAMA'!$F$115 -> 154389.98 | E17: =IF('LAIN-LAIN'!$H$43=0,0,E12/'LAIN-LAIN'!$H$43)*'BIAYA BERSAMA'!$F$115 -> 51708.72 | F17: =IF('LAIN-LAIN'!$H$43=0,0,F12/'LAIN-LAIN'!$H$43)*'BIAYA BERSAMA'!$F$115 -> 44323.001 | G17: =IF('LAIN-LAIN'!$H$43=0,0,G12/'LAIN-LAIN'!$H$43)*'BIAYA BERSAMA'!$F$115 -> 133705.18 | H17: =IF('LAIN-LAIN'!$H$43=0,0,H12/'LAIN-LAIN'!$H$43)*'BIAYA BERSAMA'!$F$115 -> 2215.0642 | I17: =IF('LAIN-LAIN'!$H$43=0,0,I12/'LAIN-LAIN'!$H$43)*'BIAYA BERSAMA'!$F$115 -> 2215.0642 | ... L17: =IF('LAIN-LAIN'!$H$43=0,0,L12/'LAIN-LAIN'!$H$43)*'BIAYA BERSAMA'!$F$115 -> 298438.64 | M17: =SUM(B17:L17) -> 1940129.1 | N17: Man-hour ÷ total man-hour Lain-lain × pool
A18: Grup B – IDL | B18: =IF('LAIN-LAIN'!$H$43=0,0,B12/'LAIN-LAIN'!$H$43)*'BIAYA BERSAMA'!$F$117 -> 286614.59 | C18: =IF('LAIN-LAIN'!$H$43=0,0,C12/'LAIN-LAIN'!$H$43)*'BIAYA BERSAMA'!$F$117 -> 533606.35 | D18: =IF('LAIN-LAIN'!$H$43=0,0,D12/'LAIN-LAIN'!$H$43)*'BIAYA BERSAMA'!$F$117 -> 138024.64 | E18: =IF('LAIN-LAIN'!$H$43=0,0,E12/'LAIN-LAIN'!$H$43)*'BIAYA BERSAMA'!$F$117 -> 46227.595 | F18: =IF('LAIN-LAIN'!$H$43=0,0,F12/'LAIN-LAIN'!$H$43)*'BIAYA BERSAMA'!$F$117 -> 39624.763 | G18: =IF('LAIN-LAIN'!$H$43=0,0,G12/'LAIN-LAIN'!$H$43)*'BIAYA BERSAMA'!$F$117 -> 119532.44 | H18: =IF('LAIN-LAIN'!$H$43=0,0,H12/'LAIN-LAIN'!$H$43)*'BIAYA BERSAMA'!$F$117 -> 1980.2674 | I18: =IF('LAIN-LAIN'!$H$43=0,0,I12/'LAIN-LAIN'!$H$43)*'BIAYA BERSAMA'!$F$117 -> 1980.2674 | ... L18: =IF('LAIN-LAIN'!$H$43=0,0,L12/'LAIN-LAIN'!$H$43)*'BIAYA BERSAMA'!$F$117 -> 266804.15 | M18: =SUM(B18:L18) -> 1734475.5 | N18: Man-hour
A19: Grup C + D – energi & mesin | B19: =0 -> 0 | C19: =0 -> 0 | D19: =0 -> 0 | E19: =0 -> 0 | F19: =0 -> 0 | G19: =0 -> 0 | H19: =0 -> 0 | I19: =0 -> 0 | ... L19: =0 -> 0 | M19: =SUM(B19:L19) -> 0 | N19: kWh Koperasi = 0 (sesuai Overhead Allocation)
A20: Grup E – pabrik umum | B20: =IF('LAIN-LAIN'!$G$43=0,0,B15/'LAIN-LAIN'!$G$43)*'BIAYA BERSAMA'!$F$120 -> 50618.895 | C20: =IF('LAIN-LAIN'!$G$43=0,0,C15/'LAIN-LAIN'!$G$43)*'BIAYA BERSAMA'!$F$120 -> 98149.601 | D20: =IF('LAIN-LAIN'!$G$43=0,0,D15/'LAIN-LAIN'!$G$43)*'BIAYA BERSAMA'!$F$120 -> 25015.418 | E20: =IF('LAIN-LAIN'!$G$43=0,0,E15/'LAIN-LAIN'!$G$43)*'BIAYA BERSAMA'!$F$120 -> 1222.8814 | F20: =IF('LAIN-LAIN'!$G$43=0,0,F15/'LAIN-LAIN'!$G$43)*'BIAYA BERSAMA'!$F$120 -> 22775.387 | G20: =IF('LAIN-LAIN'!$G$43=0,0,G15/'LAIN-LAIN'!$G$43)*'BIAYA BERSAMA'!$F$120 -> 79278.66 | H20: =IF('LAIN-LAIN'!$G$43=0,0,H15/'LAIN-LAIN'!$G$43)*'BIAYA BERSAMA'!$F$120 -> 1075.0635 | I20: =IF('LAIN-LAIN'!$G$43=0,0,I15/'LAIN-LAIN'!$G$43)*'BIAYA BERSAMA'!$F$120 -> 12.838374 | ... L20: =IF('LAIN-LAIN'!$G$43=0,0,L15/'LAIN-LAIN'!$G$43)*'BIAYA BERSAMA'!$F$120 -> 47824.862 | M20: =SUM(B20:L20) -> 380412.46 | N20: Nilai material eksternal
A21: Subtotal factory overhead (Grup B–E) | B21: =SUM(B18:B20) -> 337233.48 | C21: =SUM(C18:C20) -> 631755.95 | D21: =SUM(D18:D20) -> 163040.06 | E21: =SUM(E18:E20) -> 47450.477 | F21: =SUM(F18:F20) -> 62400.15 | G21: =SUM(G18:G20) -> 198811.1 | H21: =SUM(H18:H20) -> 3055.3309 | I21: =SUM(I18:I20) -> 1993.1058 | ... L21: =SUM(L18:L20) -> 314629.01 | M21: =SUM(B21:L21) -> 2114887.9
A22: TOTAL BIAYA PRODUKSI | B22: =B16+B17+B21 -> 5470173 | C22: =C16+C17+C21 -> 10254371 | D22: =D16+D17+D21 -> 2645375.9 | E22: =E16+E17+E21 -> 803928.3 | F22: =F16+F17+F21 -> 1854735.5 | G22: =G16+G17+G21 -> 5758904.7 | H22: =H16+H17+H21 -> 91610.352 | I22: =I16+I17+I21 -> 77751.454 | ... L22: =L16+L17+L21 -> 1409318.3 | M22: =SUM(B22:L22) -> 30201446
A23: Biaya per kg | B23: =IF(B7=0,0,B22/B7) -> 12604.085 | C23: =IF(C7=0,0,C22/C7) -> 12691.053 | D23: =IF(D7=0,0,D22/D7) -> 12657.301 | E23: =IF(E7=0,0,E22/E7) -> 11484.69 | F23: =IF(F7=0,0,F22/F7) -> 12364.903 | G23: =IF(G7=0,0,G22/G7) -> 12726.861 | H23: =IF(H7=0,0,H22/H7) -> 12214.714 | I23: =IF(I7=0,0,I22/I7) -> 10366.861 | ... M23: =IF(M7=0,0,M22/M7) -> 10177.404
A25: 3. Barang jadi dan HPP per SKU (qty dalam satuan FG)
A26: Pos | B26: FCC Kw 2 Bumbu BBQ 1kg | C26: FCC Kw 2 Bumbu Balado 1kg | D26: FCC Kw 2 Bumbu Jagung Manis 1kg | E26: FCC Kw 2 Bumbu Asin 1kg | F26: FCC Kw2 Suka-Suka Bumbu BBQ 2,5kg | G26: FCC Kw2 Suka-suka Bumbu Balado 2,5kg | H26: FCC Kw2 Suka-suka Bumbu Jagung Manis 2,5kg | I26: FCC KW2 Suka-suka Bumbu Asin 2,5kg | J26: FCC Premium Bumbu Asin 250gr | K26: Keripik Ubi Mix Kw2 Rasa Balado 1 Kg | L26: Keripik Ubi Mix Kw2 Rasa BBQ 1 Kg | M26: Total | N26: Dasar
A27: Saldo awal – qty | B27: =B126 -> 0 | C27: =C126 -> 0 | D27: =D126 -> 0 | E27: =E126 -> 0 | F27: =F126 -> 0 | G27: =G126 -> 0 | H27: =H126 -> 0 | I27: =I126 -> 0 | ... L27: =L126 -> 0 | M27: =SUM(B27:L27) -> 0
A28: Saldo awal – nilai WP | B28: =B127 -> 0 | C28: =C127 -> 0 | D28: =D127 -> 0 | E28: =E127 -> 0 | F28: =F127 -> 0 | G28: =G127 -> 0 | H28: =H127 -> 0 | I28: =I127 -> 0 | ... L28: =L127 -> 0 | M28: =SUM(B28:L28) -> 0
A29: Masuk dari produksi – qty | B29: =B8 -> 434 | C29: =C8 -> 808 | D29: =D8 -> 209 | E29: =E8 -> 70 | F29: =F8 -> 60 | G29: =G8 -> 181 | H29: =H8 -> 3 | I29: =I8 -> 3 | ... L29: =L8 -> 404 | M29: =SUM(B29:L29) -> 2597
A30: Masuk dari produksi – nilai | B30: =B22 -> 5470173 | C30: =C22 -> 10254371 | D30: =D22 -> 2645375.9 | E30: =E22 -> 803928.3 | F30: =F22 -> 1854735.5 | G30: =G22 -> 5758904.7 | H30: =H22 -> 91610.352 | I30: =I22 -> 77751.454 | ... L30: =L22 -> 1409318.3 | M30: =SUM(B30:L30) -> 30201446
A31: Biaya rata-rata per satuan | B31: =IF(B27+B29=0,0,(B28+B30)/(B27+B29)) -> 12604.085 | C31: =IF(C27+C29=0,0,(C28+C30)/(C27+C29)) -> 12691.053 | D31: =IF(D27+D29=0,0,(D28+D30)/(D27+D29)) -> 12657.301 | E31: =IF(E27+E29=0,0,(E28+E30)/(E27+E29)) -> 11484.69 | F31: =IF(F27+F29=0,0,(F28+F30)/(F27+F29)) -> 30912.258 | G31: =IF(G27+G29=0,0,(G28+G30)/(G27+G29)) -> 31817.153 | H31: =IF(H27+H29=0,0,(H28+H30)/(H27+H29)) -> 30536.784 | I31: =IF(I27+I29=0,0,(I28+I30)/(I27+I29)) -> 25917.151 | ... L31: =IF(L27+L29=0,0,(L28+L30)/(L27+L29)) -> 3488.4117
A32: Keluar: penjualan – qty | B32: =B131 -> 434 | C32: =C131 -> 808 | D32: =D131 -> 209 | E32: =E131 -> 70 | F32: =F131 -> 59 | G32: =G131 -> 179 | H32: =H131 -> 3 | I32: =I131 -> 3 | ... L32: =L131 -> 404 | M32: =SUM(B32:L32) -> 2584 | N32: Pengiriman pesanan (Accurate)
A33: Keluar: penjualan – nilai | B33: =B32*B31 -> 5470173 | C33: =C32*C31 -> 10254371 | D33: =D32*D31 -> 2645375.9 | E33: =E32*E31 -> 803928.3 | F33: =F32*F31 -> 1823823.2 | G33: =G32*G31 -> 5695270.4 | H33: =H32*H31 -> 91610.352 | I33: =I32*I31 -> 77751.454 | ... L33: =L32*L31 -> 1409318.3 | M33: =SUM(B33:L33) -> 29812757
A34: Saldo akhir – qty (Accurate) | B34: =B133 -> 0 | C34: =C133 -> 0 | D34: =D133 -> 0 | E34: =E133 -> 0 | F34: =F133 -> 0 | G34: =G133 -> 0 | H34: =H133 -> 0 | I34: =I133 -> 0 | ... L34: =L133 -> 0 | M34: =SUM(B34:L34) -> 0
A35: Saldo akhir – nilai WP | B35: =B34*B31 -> 0 | C35: =C34*C31 -> 0 | D35: =D34*D31 -> 0 | E35: =E34*E31 -> 0 | F35: =F34*F31 -> 0 | G35: =G34*G31 -> 0 | H35: =H34*H31 -> 0 | I35: =I34*I31 -> 0 | ... L35: =L34*L31 -> 0 | M35: =SUM(B35:L35) -> 0
A36: Selisih kuantitas ke HPP – qty | B36: =B27+B29-B32-B34 -> 0 | C36: =C27+C29-C32-C34 -> 0 | D36: =D27+D29-D32-D34 -> 0 | E36: =E27+E29-E32-E34 -> 0 | F36: =F27+F29-F32-F34 -> 1 | G36: =G27+G29-G32-G34 -> 2 | H36: =H27+H29-H32-H34 -> 0 | I36: =I27+I29-I32-I34 -> 0 | ... L36: =L27+L29-L32-L34 -> 0 | M36: =SUM(B36:L36) -> 13
A37: Selisih kuantitas ke HPP – nilai | B37: =B36*B31 -> 0 | C37: =C36*C31 -> 0 | D37: =D36*D31 -> 0 | E37: =E36*E31 -> 0 | F37: =F36*F31 -> 30912.258 | G37: =G36*G31 -> 63634.306 | H37: =H36*H31 -> 0 | I37: =I36*I31 -> 0 | ... L37: =L36*L31 -> 0 | M37: =SUM(B37:L37) -> 388689.19
A38: HPP (penjualan + selisih kuantitas) | B38: =B33+B37 -> 5470173 | C38: =C33+C37 -> 10254371 | D38: =D33+D37 -> 2645375.9 | E38: =E33+E37 -> 803928.3 | F38: =F33+F37 -> 1854735.5 | G38: =G33+G37 -> 5758904.7 | H38: =H33+H37 -> 91610.352 | I38: =I33+I37 -> 77751.454 | ... L38: =L33+L37 -> 1409318.3 | M38: =SUM(B38:L38) -> 30201446
A39: Pendapatan | B39: =B136 -> 3518915.4 | C39: =C136 -> 6551344.8 | D39: =D136 -> 1694592.9 | E39: =E136 -> 567567 | F39: =F136 -> 1594594.2 | G39: =G136 -> 4837836.6 | H39: =H136 -> 81081.06 | I39: =I136 -> 81081.06 | ... L39: =L136 -> 4731530.8 | M39: =SUM(B39:L39) -> 28518903
A40: Margin kotor | B40: =B39-B38 -> -1951257.6 | C40: =C39-C38 -> -3703025.9 | D40: =D39-D38 -> -950782.95 | E40: =E39-E38 -> -236361.3 | F40: =F39-F38 -> -260141.29 | G40: =G39-G38 -> -921068.15 | H40: =H39-H38 -> -10529.292 | I40: =I39-I38 -> 3329.6061 | ... L40: =L39-L38 -> 3322212.5 | M40: =SUM(B40:L40) -> -1682542.8
A41: Margin kotor (%) | B41: =IF(B39=0,0,B40/B39) -> -0.55450539 | C41: =IF(C39=0,0,C40/C39) -> -0.56523141 | D41: =IF(D39=0,0,D40/D39) -> -0.56106865 | E41: =IF(E39=0,0,E40/E39) -> -0.41644652 | F41: =IF(F39=0,0,F40/F39) -> -0.1631395 | G41: =IF(G39=0,0,G40/G39) -> -0.19038844 | H41: =IF(H39=0,0,H40/H39) -> -0.12986131 | I41: =IF(I39=0,0,I40/I39) -> 0.041065153 | ... M41: =IF(M39=0,0,M40/M39) -> -0.058997458
A42: Memo: HPP menurut Accurate (nilai pengiriman) | B42: =B132 -> 1129237.5 | C42: =C132 -> 2163993.3 | D42: =D132 -> 552711.22 | E42: =E132 -> 66714.18 | F42: =F132 -> 408859.57 | G42: =G132 -> 1414524.8 | H42: =H132 -> 19728.81 | I42: =I132 -> 2043.5 | ... L42: =L132 -> 1042657.2 | M42: =SUM(B42:L42) -> 7959669.7
...

Sheet MCH BASRENG L0
A1: KARTU BIAYA PRODUKSI – Maicih Basreng 80 gr Level 0 (maklon), September 2026
A2: Sumber: kartu 'LAP BAG MAICIH BASRENG L.0 LOK' di WP CoGM September 2026; driver man-hour & kWh: sheet Labor & Overhead Allocation; barang jadi: Inventory Valuation Accurate FG-138; pendapatan: LK Sales By Item.
A3: Tidak ada kartu / produksi bulan ini – hanya pergerakan barang jadi.
A4: Status kontrol (bagian 5) | C4: =IF(COUNTIF(C70:C75,"GAGAL")=0,"LULUS","GAGAL") -> LULUS
A5: 1. Ringkasan (Rp juta; Rp/kg per kg produksi bulan ini)
A6: Komponen | B6: Aktual (Rp jt) | C6: Rp/kg | D6: Porsi
A7: FCC premium (antarproduk) | B7: =E31/10^6 -> 0 | C7: =F31 -> 0 | D7: =IF($B$12=0,0,B7/$B$12) -> 0
A8: KW 2 (antarproduk, NRV) | B8: =(E32+E33)/10^6 -> 0 | C8: =F32+F33 -> 0 | D8: =IF($B$12=0,0,B8/$B$12) -> 0
A9: Material eksternal | B9: =E34/10^6 -> 0 | C9: =F34 -> 0 | D9: =IF($B$12=0,0,B9/$B$12) -> 0
A10: Direct labour (Grup A) | B10: =E37/10^6 -> 0 | C10: =F37 -> 0 | D10: =IF($B$12=0,0,B10/$B$12) -> 0
A11: Factory overhead (Grup B–E) | B11: =E41/10^6 -> 0 | C11: =F41 -> 0 | D11: =IF($B$12=0,0,B11/$B$12) -> 0
A12: Total biaya produksi | B12: =E43/10^6 -> 0 | C12: =F43 -> 0 | D12: =IF($B$12=0,0,B12/$B$12) -> 0
A13: Produksi (kg; satuan FG) | B13: =B21 -> 0 | C13: =C21 -> 0
A14: HPP (Rp jt) dan HPP per satuan terjual | B14: =D54/10^6 -> 0 | C14: =C55 -> 0
A15: Pendapatan (Rp jt) dan harga per satuan | B15: =$C$118/10^6 -> 0 | C15: =IF($C$117=0,0,$C$118/$C$117) -> 0
A16: Margin kotor (Rp jt; %) | B16: =B15-B14 -> 0 | C16: =IF(B15=0,0,B16/B15) -> 0
A18: 2. Laporan biaya produksi
A19: 2a. Kuantitas
A20: Pos | B20: Kg | C20: Satuan FG (bag) | D20: Keterangan
A21: Output produksi | B21: =$C$102 -> 0 | C21: =$C$103 -> 0
A22: Sampel | B22: =$C$104 -> 0 | C22: =$C$105 -> 0 | D22: memo, tidak masuk barang jadi
A23: Input FCC premium | B23: =SUMIF($B$128:$B$128,"FCC",$C$128:$C$128) -> 0 | D23: Lampiran B
A24: Input KW 2 FCC | B24: =SUMIF($B$128:$B$128,"KW2",$C$128:$C$128) -> 0 | D24: Lampiran B
A25: Input KW 2 ubi | B25: =SUMIF($B$128:$B$128,"KW2UBI",$C$128:$C$128) -> 0 | D25: Lampiran B
A26: Rendemen output ÷ input keripik (kg/kg) | B26: =IF(SUM(B23:B25)=0,0,B21/SUM(B23:B25)) -> 0
A28: 2b. Biaya produksi bulan ini (aktual)
A29: Komponen | B29: Qty / driver | C29: Satuan | D29: Harga / porsi | E29: Nilai (Rp) | F29: Rp/kg | G29: Dasar
A30: Bahan
A31: FCC premium (antarproduk) | B31: =B23 -> 0 | C31: kg | D31: =FCC!$D$89 -> 23872.948 | E31: =B31*D31 -> 0 | F31: =IF($B$21=0,0,E31/$B$21) -> 0 | G31: Biaya rata-rata FG FCC kartu baru (FCC D88)
A32: KW 2 FCC (antarproduk, NRV) | B32: =B24 -> 0 | C32: kg | D32: =FCC!$C$209 -> 9777.2712 | E32: =B32*D32 -> 0 | F32: =IF($B$21=0,0,E32/$B$21) -> 0 | G32: NRV KW 2 (FCC C208)
A33: KW 2 ubi (antarproduk) | B33: =B25 -> 0 | C33: kg | D33: ='LAIN-LAIN'!$C$7 -> 0 | E33: =B33*D33 -> 0 | F33: =IF($B$21=0,0,E33/$B$21) -> 0 | G33: Nilai KW 2 ubi (LAIN-LAIN C7)
A34: Material eksternal (Lampiran B) | E34: =SUMIF($B$128:$B$128,"EXT",$F$128:$F$128) -> 0 | F34: =IF($B$21=0,0,E34/$B$21) -> 0 | G34: Nilai kartu per baris material
A35: Subtotal bahan | E35: =SUM(E31:E34) -> 0 | F35: =IF($B$21=0,0,E35/$B$21) -> 0
A36: Konversi (pool BIAYA BERSAMA, porsi Lain-lain dibagi dengan driver yang sama dengan sheet LAIN-LAIN)
A37: Grup A – DL operator | B37: =$C$106 -> 0 | C37: jam | D37: =IF('LAIN-LAIN'!$H$43=0,0,B37/'LAIN-LAIN'!$H$43) -> 0 | E37: =D37*'BIAYA BERSAMA'!$F$115 -> 0 | F37: =IF($B$21=0,0,E37/$B$21) -> 0 | G37: Man-hour ÷ total man-hour Lain-lain × pool Grup A Lain-lain
A38: Grup B – IDL (support, staf, THR, BPJS) | B38: =$C$106 -> 0 | C38: jam | D38: =IF('LAIN-LAIN'!$H$43=0,0,B38/'LAIN-LAIN'!$H$43) -> 0 | E38: =D38*'BIAYA BERSAMA'!$F$117 -> 0 | F38: =IF($B$21=0,0,E38/$B$21) -> 0 | G38: Man-hour
A39: Grup C + D – energi (kWh) dan mesin (bagging: kWh; Ubi putih ACE: jam mesin) | B39: =$C$107 -> 0 | C39: kWh | D39: =IF('LAIN-LAIN'!$I$43=0,0,B39/'LAIN-LAIN'!$I$43) -> 0 | E39: =D39*'BIAYA BERSAMA'!$F$118+IF('BIAYA BERSAMA'!$F$172=0,0,B39/'BIAYA BERSAMA'!$F$172)*'BIAYA BERSAMA'!$F$176 -> 0 | F39: =IF($B$21=0,0,E39/$B$21) -> 0 | G39: kWh
A40: Grup E – pabrik umum | B40: =E34 -> 0 | C40: Rp | D40: =IF('LAIN-LAIN'!$G$43=0,0,B40/'LAIN-LAIN'!$G$43) -> 0 | E40: =D40*'BIAYA BERSAMA'!$F$120 -> 0 | F40: =IF($B$21=0,0,E40/$B$21) -> 0 | G40: Nilai material eksternal
A41: Subtotal factory overhead (Grup B–E) | E41: =SUM(E38:E40) -> 0 | F41: =IF($B$21=0,0,E41/$B$21) -> 0
A42: Total konversi | E42: =E37+E41 -> 0 | F42: =IF($B$21=0,0,E42/$B$21) -> 0
...

Sheet MCH BASRENG L5
A1: KARTU BIAYA PRODUKSI – Maicih Basreng 80 gr Level 5 (maklon), September 2026
A2: Sumber: kartu 'LAP BAG MAICIH BASRENG L.5 LOK' di WP CoGM September 2026; driver man-hour & kWh: sheet Labor & Overhead Allocation; barang jadi: Inventory Valuation Accurate FG-137; pendapatan: LK Sales By Item.
A4: Status kontrol (bagian 5) | C4: =IF(COUNTIF(C70:C75,"GAGAL")=0,"LULUS","GAGAL") -> LULUS
A5: 1. Ringkasan (Rp juta; Rp/kg per kg produksi bulan ini)
A6: Komponen | B6: Aktual (Rp jt) | C6: Rp/kg | D6: Porsi
A7: FCC premium (antarproduk) | B7: =E31/10^6 -> 0 | C7: =F31 -> 0 | D7: =IF($B$12=0,0,B7/$B$12) -> 0
A8: KW 2 (antarproduk, NRV) | B8: =(E32+E33)/10^6 -> 0 | C8: =F32+F33 -> 0 | D8: =IF($B$12=0,0,B8/$B$12) -> 0
A9: Material eksternal | B9: =E34/10^6 -> 0.01615023 | C9: =F34 -> 45.7151 | D9: =IF($B$12=0,0,B9/$B$12) -> 0.0073844752
A10: Direct labour (Grup A) | B10: =E37/10^6 -> 0.53139825 | C10: =F37 -> 1504.1844 | D10: =IF($B$12=0,0,B10/$B$12) -> 0.24297469
A11: Factory overhead (Grup B–E) | B11: =E41/10^6 -> 1.6395034 | C11: =F41 -> 4640.8045 | D11: =IF($B$12=0,0,B11/$B$12) -> 0.74964084
A12: Total biaya produksi | B12: =E43/10^6 -> 2.1870519 | C12: =F43 -> 6190.7039 | D12: =IF($B$12=0,0,B12/$B$12) -> 1
A13: Produksi (kg; satuan FG) | B13: =B21 -> 353.28 | C13: =C21 -> 4416
A14: HPP (Rp jt) dan HPP per satuan terjual | B14: =D54/10^6 -> 2.1870519 | C14: =C55 -> 495.25631
A15: Pendapatan (Rp jt) dan harga per satuan | B15: =$C$118/10^6 -> 1.7664 | C15: =IF($C$117=0,0,$C$118/$C$117) -> 400
A16: Margin kotor (Rp jt; %) | B16: =B15-B14 -> -0.42065188 | C16: =IF(B15=0,0,B16/B15) -> -0.23814079
A18: 2. Laporan biaya produksi
A19: 2a. Kuantitas
A20: Pos | B20: Kg | C20: Satuan FG (bag) | D20: Keterangan
A21: Output produksi | B21: =$C$102 -> 353.28 | C21: =$C$103 -> 4416
A22: Sampel | B22: =$C$104 -> 0.96 | C22: =$C$105 -> 12 | D22: memo, tidak masuk barang jadi
A23: Input FCC premium | B23: =SUMIF($B$128:$B$131,"FCC",$C$128:$C$131) -> 0 | D23: Lampiran B
