Workbook

Sheet RINGKASAN
A1: RINGKASAN WP COSTING
A3: Status kontrol semua sheet | C3: ='REKON & KONTROL'!$D$68 -> LULUS
A5: 1. Biaya produksi dan HPP per produk (Rp juta; Rp/kg per kg produksi)
A6: Pos | B6: FCC | C6: Ubi Ungu | D6: Ubi Orange | E6: Lain-lain | F6: Total
A7: Produksi (kg) | B7: ='REKON & KONTROL'!B6 -> 338754 | C7: ='REKON & KONTROL'!C6 -> 13376 | D7: ='REKON & KONTROL'!D6 -> 7403 | E7: ='REKON & KONTROL'!E6 -> 17571.48 | F7: ='REKON & KONTROL'!F6 -> 377104.48
A8: Total biaya produksi | B8: ='REKON & KONTROL'!B12 -> 7327.4407 | C8: ='REKON & KONTROL'!C12 -> 465.30971 | D8: ='REKON & KONTROL'!D12 -> 238.93443 | E8: ='REKON & KONTROL'!E12 -> 355.58196 | F8: ='REKON & KONTROL'!F12 -> 8387.2668
A9: Biaya produksi per kg (Rp) | B9: ='REKON & KONTROL'!B13 -> 21630.566 | C9: ='REKON & KONTROL'!C13 -> 34786.91 | D9: ='REKON & KONTROL'!D13 -> 32275.352 | E9: ='REKON & KONTROL'!E13 -> 20236.313 | F9: ='REKON & KONTROL'!F13 -> 22241.228
A10: HPP | B10: ='REKON & KONTROL'!B14 -> 6925.005 | C10: ='REKON & KONTROL'!C14 -> 250.83102 | D10: ='REKON & KONTROL'!D14 -> 238.93443 | E10: ='REKON & KONTROL'!E14 -> 355.58196 | F10: ='REKON & KONTROL'!F14 -> 7770.3524
A11: Pendapatan (total = GL) | B11: ='REKON & KONTROL'!B15 -> 8672.0977 | C11: ='REKON & KONTROL'!C15 -> 349.70925 | D11: ='REKON & KONTROL'!D15 -> 354.6037 | E11: ='REKON & KONTROL'!E15 -> 416.7148 | F11: ='REKON & KONTROL'!F15 -> 9793.1255
A12: Margin kotor (%) | B12: ='REKON & KONTROL'!B16 -> 0.20146138 | C12: ='REKON & KONTROL'!C16 -> 0.28274411 | D12: ='REKON & KONTROL'!D16 -> 0.32619307 | E12: ='REKON & KONTROL'!E16 -> 0.14670186 | F12: ='REKON & KONTROL'!F16 -> 0.20655031
A14: 2. FCC, UU, UO: Rp/kg aktual vs budget dan penyebab selisih (Rp/kg)
A15: Produk | B15: Rp/kg aktual | C15: Rp/kg budget | D15: Selisih | E15: Harga / belanja | F15: Pemakaian / yield | G15: Volume | H15: Metode alokasi | I15: Bulan budget
A16: FCC | B16: =FCC!F132 -> 21630.566 | C16: =FCC!G132 -> 24247.024 | D16: =FCC!H132 -> -2616.4585 | E16: =FCC!I132 -> -975.29969 | F16: =FCC!J132 -> -783.96977 | G16: =FCC!K132 -> -571.13798 | H16: =FCC!L132 -> -286.05103 | I16: =FCC!$C$5 -> Okt-26
A17: UU | B17: =UU!F126 -> 34786.91 | C17: =UU!G126 -> 35657.071 | D17: =UU!H126 -> -870.16049 | E17: =UU!I126 -> 1410.2109 | F17: =UU!J126 -> -1899.4098 | G17: =UU!K126 -> -2805.881 | H17: =UU!L126 -> 2424.9195 | I17: =UU!$C$5 -> Okt-26
A18: UO | B18: =UO!F126 -> 32275.352 | C18: =UO!G126 -> 33916.194 | D18: =UO!H126 -> -1640.8416 | E18: =UO!I126 -> 977.27671 | F18: =UO!J126 -> -3689.6167 | G18: =UO!K126 -> -1144.747 | H18: =UO!L126 -> 2216.2455 | I18: =UO!$C$5 -> Okt-26
A21: 3. Biaya yang tidak terlihat di margin (memo)
A22: Pos | B22: FCC | C22: Ubi Ungu | D22: Ubi Orange | F22: Catatan
A23: Biaya waste (kerugian normal) yang terserap ke HPP (Rp jt) | B23: =FCC!$B$23 -> 207.1095 | C23: =UU!$B$23 -> 0 | D23: =UO!$B$23 -> 0
A24: KW 2 dikreditkan pada NRV (Rp jt) | B24: =FCC!$B$24 -> 134.48637 | C24: =UU!$B$24 -> 0 | D24: =UO!$B$24 -> 0
A25: Kenaikan WIP + FG (Rp jt) | B25: =FCC!#REF! -> #REF! | C25: =UU!$B$25 -> 214.4787 | D25: =UO!$B$25 -> 0
A26: Biaya jam operator tidak terpakai untuk produk (Rp jt; % jam) | B26: ='BIAYA BERSAMA'!$C$109/10^6 -> 61.206618 | C26: ='BIAYA BERSAMA'!$D$107 -> 0.094074868
A28: 4. Rekonsiliasi ke GL (Rp juta)
A29: Total HPP kartu baru | B29: ='REKON & KONTROL'!$C$37 -> 7770.3524
A30: Varian material (GL − kartu) | B30: ='REKON & KONTROL'!$C$38 -> 203.73054
A31: Selisih kenaikan persediaan kartu baru vs GL | B31: ='REKON & KONTROL'!$C$46 -> -152.227
A32: Kenaikan persediaan KW 2 pada NRV | B32: ='REKON & KONTROL'!$C$41 -> 20.289793
A33: Jam menganggur dibebankan ke periode | B33: ='REKON & KONTROL'!$C$42 -> 0
A34: HPP menurut GL | B34: ='REKON & KONTROL'!$C$44 -> 7842.1457
A35: Cek (harus nol) | B35: ='REKON & KONTROL'!$C$45 -> 0

Sheet FCC
A1: KARTU BIAYA PRODUKSI - FCC (Flat Cassava Chips)
A5: Bulan budget pembanding | C5: Okt-26 | D5: posisi: | E5: =MATCH(C5,BUDGET!$C$4:$R$4,0) -> 2
A6: Status kontrol (bagian 6) | C6: =IF(COUNTIF(D158:D168,"GAGAL")=0,"LULUS","GAGAL") -> LULUS
A8: 1. Ringkasan (Rp juta; Rp/kg per kg produksi bulan ini)
A9: Komponen | B9: Aktual (Rp jt) | C9: Aktual Rp/kg | D9: Budget Rp/kg | E9: Selisih Rp/kg | F9: Harga / belanja | G9: Pemakaian / yield | H9: Volume | I9: Metode alokasi
A10: Raw materials | B10: =E43/10^6 -> 3103.9859 | C10: =F43 -> 9162.9499 | D10: =G111 -> 9668.1757 | E10: =H111 -> -505.22578 | F10: =I111 -> -764.45659 | G10: =J111 -> 259.23081 | H10: =K111 -> 0 | I10: =L111 -> 0
A11: Oil | B11: =E45/10^6 -> 1362.1392 | C11: =F45 -> 4021.0278 | D11: =G113 -> 4729.8946 | E11: =H113 -> -708.86683 | F11: =I113 -> 112.62136 | G11: =J113 -> -821.48819 | H11: =K113 -> 0 | I11: =L113 -> 0
A12: CNG | B12: =E46/10^6 -> 1156.699 | C12: =F46 -> 3414.5694 | D12: =G115 -> 3489.2225 | E12: =H115 -> -74.653111 | F12: =I115 -> -40.154776 | G12: =J115 -> -34.498335 | H12: =K115 -> 0 | I12: =L115 -> 0
A13: Material - others | B13: =E54/10^6 -> 301.40266 | C13: =F54 -> 889.73903 | D13: =G122 -> 814.07396 | E13: =H122 -> 75.665076 | F13: =I122 -> 31.547097 | G13: =J122 -> 44.117978 | H13: =K122 -> 0 | I13: =L122 -> 0
A14: Upah kupas | B14: =E57/10^6 -> 110.02163 | C14: =F57 -> 324.78325 | D14: =G124 -> 555.87748 | E14: =H124 -> -231.09423 | F14: =I124 -> 0.23780258 | G14: =J124 -> -231.33203 | H14: =K124 -> 0 | I14: =L124 -> 0
A15: Direct labour (Grup A) | B15: =E58/10^6 -> 554.72766 | C15: =F58 -> 1637.5531 | D15: =G126 -> 2105.5178 | E15: =H126 -> -467.96476 | F15: =I126 -> -54.902774 | G15: =J126 -> 0 | H15: =K126 -> -241.00084 | I15: =L126 -> -172.06115
A16: Factory overhead (Grup B–E) | B16: =E63/10^6 -> 738.46455 | C16: =F63 -> 2179.9434 | D16: =G131 -> 2884.2623 | E16: =H131 -> -704.31884 | F16: =I131 -> -260.19181 | G16: =J131 -> 0 | H16: =K131 -> -330.13714 | I16: =L131 -> -113.98989
A17: Total biaya produksi | B17: =E65/10^6 -> 7327.4407 | C17: =F65 -> 21630.566 | D17: =G132 -> 24247.024 | E17: =H132 -> -2616.4585 | F17: =I132 -> -975.29969 | G17: =J132 -> -783.96977 | H17: =K132 -> -571.13798 | I17: =L132 -> -286.05103
A18: Produksi bulan ini (kg; aktual, budget) | C18: =$B$30 -> 338754 | D18: =$D$30 -> 299979.69
A19: Biaya konversi per kg (aktual, budget) | C19: =F64 -> 4142.2797 | D19: =G124+G126+G131 -> 5545.6576
A20: HPP (Rp jt) dan HPP per kg terjual (aktual, budget) | B20: =E103/10^6 -> 6925.005 | C20: =D104 -> 22814.982 | D20: =F104 -> 25736.788
A21: Pendapatan (Rp jt; aktual) | B21: =$C$210/10^6 -> 8672.0977
A22: Margin kotor (Rp jt; %) | B22: =B21-B20 -> 1747.0927 | C22: =IF(B21=0,0,B22/B21) -> 0.20146138
A23: biaya waste (kerugian normal) yang masuk HPP (Rp jt; % biaya produksi) | B23: =E77/10^6 -> 207.1095 | C23: =IF(E65=0,0,E77/E65) -> 0.028264916
A24: KW 2 dikreditkan pada NRV (Rp jt) | B24: =-E73/10^6 -> 134.48637
A26: 2. Laporan biaya produksi
A27: 2a. Kuantitas (kg)
A28: Pos | B28: Aktual kg | C28: % dari produksi | D28: Budget kg | E28: % budget
A29: WIP awal | B29: =$C$190 -> 2431
A30: Produksi bulan ini (masuk proses) | B30: =$C$191 -> 338754 | D30: =INDEX(BUDGET!$C$14:$R$14,$E$5) -> 299979.69
A31: Total untuk dipertanggungjawabkan | B31: =B29+B30 -> 341185
A32: Premium ke barang jadi | B32: =B31-B33-B34-B35 -> 317712.5 | C32: =IF(B30=0,0,B32/B30) -> 0.9378856 | D32: =INDEX(BUDGET!$C$10:$R$10,$E$5) -> 278373.52 | E32: =IF(D30=0,0,D32/D30) -> 0.92797454
A33: KW 2 (produk sampingan) | B33: =$C$193 -> 13755 | C33: =IF(B30=0,0,B33/B30) -> 0.040604687 | D33: =INDEX(BUDGET!$C$11:$R$11,$E$5) -> 10970.782 | E33: =IF(D30=0,0,D33/D30) -> 0.036571749
A34: Keripik waste (kerugian normal) | B34: =$C$194 -> 9360 | C34: =IF(B30=0,0,B34/B30) -> 0.02763067 | D34: =INDEX(BUDGET!$C$12:$R$12,$E$5) -> 10635.392 | E34: =IF(D30=0,0,D34/D30) -> 0.035453707
A35: WIP akhir | B35: =$C$192 -> 357.5 | C35: =IF(B30=0,0,B35/B30) -> 0.0010553381 | D35: =INDEX(BUDGET!$C$13:$R$13,$E$5) -> 0 | E35: =IF(D30=0,0,D35/D30) -> 0
A36: Total dipertanggungjawabkan | B36: =SUM(B32:B35) -> 341185
A38: 2b. Biaya produksi bulan ini (aktual)
A39: Komponen | B39: Qty | C39: Satuan | D39: Harga | E39: Nilai (Rp) | F39: Rp/kg
A40: Raw materials
A41: Singkong kulit premium | B41: =D214 -> 625461.89 | C41: kg | D41: =F214 -> 2673.5489 | E41: =G214 -> 1.6722029e+09 | F41: =IF($B$30=0,0,E41/$B$30) -> 4936.3341
A42: Singkong daging premium | B42: =D215 -> 316290 | C42: kg | D42: =F215 -> 4526.8045 | E42: =G215 -> 1.431783e+09 | F42: =IF($B$30=0,0,E42/$B$30) -> 4226.6158
A43: Subtotal raw materials | E43: =E41+E42 -> 3.1039859e+09 | F43: =IF($B$30=0,0,E43/$B$30) -> 9162.9499
A44: Oil & CNG
A45: Minyak olein | B45: =D216 -> 78928 | C45: kg | D45: =F216 -> 17257.998 | E45: =G216 -> 1.3621392e+09 | F45: =IF($B$30=0,0,E45/$B$30) -> 4021.0278
A46: CNG | B46: =D217/$C$209 -> 5099.3535 | C46: MMBTU | D46: =IF(B46=0,0,E46/B46) -> 226832.49 | E46: =G217 -> 1.156699e+09 | F46: =IF($B$30=0,0,E46/$B$30) -> 3414.5694
...

Sheet UU
A1: KARTU BIAYA PRODUKSI - UBI UNGU IFM (QKSP)
A5: Bulan budget pembanding | C5: Okt-26 | D5: posisi: | E5: =MATCH(C5,BUDGET!$C$4:$R$4,0) -> 2
A6: Status kontrol (bagian 6) | C6: =IF(COUNTIF(D148:D158,"GAGAL")=0,"LULUS","GAGAL") -> LULUS
A8: 1. Ringkasan (Rp juta; Rp/kg per kg produksi bulan ini)
A9: Komponen | B9: Aktual (Rp jt) | C9: Aktual Rp/kg | D9: Budget Rp/kg | E9: Selisih Rp/kg | F9: Harga / belanja | G9: Pemakaian / yield | H9: Volume | I9: Metode alokasi
A10: Raw materials | B10: =E44/10^6 -> 246.3404 | C10: =F44 -> 18416.597 | D10: =G105 -> 18504.445 | E10: =H105 -> -87.848212 | F10: =I105 -> -87.848212 | G10: =J105 -> -7.8768592e-11 | H10: =K105 -> 0 | I10: =L105 -> 0
A11: Oil | B11: =E46/10^6 -> 71.810529 | C11: =F46 -> 5368.6101 | D11: =G107 -> 6660.2 | E11: =H107 -> -1291.5899 | F11: =I107 -> 150.36459 | G11: =J107 -> -1441.9545 | H11: =K107 -> 0 | I11: =L107 -> 0
A12: CNG | B12: =E47/10^6 -> 51.763471 | C12: =F47 -> 3869.8767 | D12: =G109 -> 4387.0104 | E12: =H109 -> -517.13365 | F12: =I109 -> -45.509116 | G12: =J109 -> -471.62453 | H12: =K109 -> 0 | I12: =L109 -> 0
A13: Material - others | B13: =E55/10^6 -> 9.7718105 | C13: =F55 -> 730.54803 | D13: =G116 -> 684.51551 | E13: =H116 -> 46.032524 | F13: =I116 -> 31.863332 | G13: =J116 -> 14.169192 | H13: =K116 -> 0 | I13: =L116 -> 0
A14: Upah kupas | B14: =E58/10^6 -> 0 | C14: =F58 -> 0 | D14: =G118 -> 0 | E14: =H118 -> 0 | F14: =I118 -> 0 | G14: =J118 -> 0 | H14: =K118 -> 0 | I14: =L118 -> 0
A15: Direct labour (Grup A) | B15: =E59/10^6 -> 45.171801 | C15: =F59 -> 3377.0785 | D15: =G120 -> 2105.5178 | E15: =H120 -> 1271.5606 | F15: =I120 -> 793.92141 | G15: =J120 -> 0 | H15: =K120 -> -1089.825 | I15: =L120 -> 1567.4642
A16: Factory overhead (Grup B–E) | B16: =E64/10^6 -> 40.451703 | C16: =F64 -> 3024.2003 | D16: =G125 -> 3315.3821 | E16: =H125 -> -291.18187 | F16: =I125 -> 567.41886 | G16: =J125 -> 0 | H16: =K125 -> -1716.056 | I16: =L125 -> 857.45524
A17: Total biaya produksi | B17: =E66/10^6 -> 465.30971 | C17: =F66 -> 34786.91 | D17: =G126 -> 35657.071 | E17: =H126 -> -870.16049 | F17: =I126 -> 1410.2109 | G17: =J126 -> -1899.4098 | H17: =K126 -> -2805.881 | I17: =L126 -> 2424.9195
A18: Produksi bulan ini (kg; aktual, budget) | C18: =$B$32 -> 13376 | D18: =$D$32 -> 6452.5253
A19: Biaya konversi per kg (aktual, budget) | C19: =F65 -> 6401.2787 | D19: =G118+G120+G125 -> 5420.9
A20: HPP (Rp jt) dan HPP per kg terjual (aktual, budget) | B20: =E98/10^6 -> 250.83102 | C20: =D99 -> 34786.91 | D20: =F99 -> 34950.461
A21: Pendapatan (Rp jt; aktual) | B21: =$C$207/10^6 -> 349.70925
A22: Margin kotor (Rp jt; %) | B22: =B21-B20 -> 98.878232 | C22: =IF(B21=0,0,B22/B21) -> 0.28274411
A23: biaya waste (kerugian normal) yang masuk HPP (Rp jt; % biaya produksi) | B23: =E76/10^6 -> 0 | C23: =IF(E66=0,0,E76/E66) -> 0
A24: KW 2 dikreditkan pada NRV (Rp jt) | B24: =-E72/10^6 -> 0
A25: kenaikan WIP + FG (Rp jt) dan porsi biaya konversi di dalamnya | B25: =(E77+E89-E70-E84)/10^6 -> 214.4787 | C25: =IF(E66=0,0,B25*E65/E66) -> 39.467084
A28: 2. Laporan biaya produksi
A29: 2a. Kuantitas (kg)
A30: Pos | B30: Aktual kg | C30: % dari produksi | D30: Budget kg | E30: % budget
A31: WIP awal | B31: =$C$191 -> 0
A32: Produksi bulan ini (masuk proses) | B32: =$C$192 -> 13376 | D32: =INDEX(BUDGET!$C$99:$R$99,$E$5) -> 6452.5253
A33: Total untuk dipertanggungjawabkan | B33: =B31+B32 -> 13376
A34: Premium ke barang jadi | B34: =B33-B35-B36-B37 -> 9333.5 | C34: =IF(B32=0,0,B34/B32) -> 0.69777961 | D34: =INDEX(BUDGET!$C$95:$R$95,$E$5) -> 6388 | E34: =IF(D32=0,0,D34/D32) -> 0.99
A35: KW 2 (produk sampingan) | B35: =$C$194 -> 0 | C35: =IF(B32=0,0,B35/B32) -> 0 | D35: =INDEX(BUDGET!$C$96:$R$96,$E$5) -> 0 | E35: =IF(D32=0,0,D35/D32) -> 0
A36: Keripik waste (kerugian normal) | B36: =$C$195 -> 0 | C36: =IF(B32=0,0,B36/B32) -> 0 | D36: =INDEX(BUDGET!$C$97:$R$97,$E$5) -> 64.525253 | E36: =IF(D32=0,0,D36/D32) -> 0.01
A37: WIP akhir | B37: =$C$193 -> 4042.5 | C37: =IF(B32=0,0,B37/B32) -> 0.30222039 | D37: =INDEX(BUDGET!$C$98:$R$98,$E$5) -> 0 | E37: =IF(D32=0,0,D37/D32) -> 0
A38: Total dipertanggungjawabkan | B38: =SUM(B34:B37) -> 13376
A40: 2b. Biaya produksi bulan ini (aktual)
A41: Komponen | B41: Qty | C41: Satuan | D41: Harga | E41: Nilai (Rp) | F41: Rp/kg
A42: Raw materials
A43: Ubi ungu | B43: =D211 -> 41864 | C43: kg | D43: =F211 -> 5884.3015 | E43: =G211 -> 2.463404e+08 | F43: =IF($B$32=0,0,E43/$B$32) -> 18416.597
A44: Subtotal raw materials | E44: =E43 -> 2.463404e+08 | F44: =IF($B$32=0,0,E44/$B$32) -> 18416.597
A45: Oil & CNG
A46: Minyak olein | B46: =D212 -> 4161 | C46: kg | D46: =F212 -> 17257.998 | E46: =G212 -> 71810529 | F46: =IF($B$32=0,0,E46/$B$32) -> 5368.6101
A47: CNG | B47: =D213/$C$206 -> 228.20131 | C47: MMBTU | D47: =IF(B47=0,0,E47/B47) -> 226832.49 | E47: =G213 -> 51763471 | F47: =IF($B$32=0,0,E47/$B$32) -> 3869.8767
...

Sheet UO
A1: KARTU BIAYA PRODUKSI – UBI ORANGE IFM (QKSO), Agustus 2026
A2: Sistem biaya: biaya aktual, penyerapan penuh. Material ditelusuri per produk dari laporan produksi; biaya konversi dialokasikan dari BIAYA BERSAMA dengan driver aktual bulan berjalan. WIP/FG dinilai rata-rata tertimbang; KW 2 pada NRV.
A3: Biru = input (lampiran), hijau = tautan antarsheet, hitam = rumus. Ringkasan dalam Rp juta; rincian dalam Rp.
A5: Bulan budget pembanding | C5: Okt-26 | D5: posisi: | E5: =MATCH(C5,BUDGET!$C$4:$R$4,0) -> 2
A6: Status kontrol (bagian 6) | C6: =IF(COUNTIF(D149:D159,"GAGAL")=0,"LULUS","GAGAL") -> LULUS
A8: 1. Ringkasan (Rp juta; Rp/kg per kg produksi bulan ini)
A9: Komponen | B9: Aktual (Rp jt) | C9: Aktual Rp/kg | D9: Budget Rp/kg | E9: Selisih Rp/kg | F9: Harga / belanja | G9: Pemakaian / yield | H9: Volume | I9: Metode alokasi
A10: Raw materials | B10: =E44/10^6 -> 122.5183 | C10: =F44 -> 16549.818 | D10: =G105 -> 17002.503 | E10: =H105 -> -452.68502 | F10: =I105 -> 512.35428 | G10: =J105 -> -965.0393 | H10: =K105 -> 0 | I10: =L105 -> 0
A11: Oil | B11: =E46/10^6 -> 35.620507 | C11: =F46 -> 4811.6314 | D11: =G107 -> 7164.2475 | E11: =H107 -> -2352.616 | F11: =I107 -> 134.76467 | G11: =J107 -> -2487.3807 | H11: =K107 -> 0 | I11: =L107 -> 0
A12: CNG | B12: =E47/10^6 -> 29.661172 | C12: =F47 -> 4006.6422 | D12: =G109 -> 4275.0389 | E12: =H109 -> -268.39671 | F12: =I109 -> -47.117456 | G12: =J109 -> -221.27925 | H12: =K109 -> 0 | I12: =L109 -> 0
A13: Material - others | B13: =E55/10^6 -> 5.4466894 | C13: =F55 -> 735.74084 | D13: =G116 -> 719.74157 | E13: =H116 -> 15.999269 | F13: =I116 -> 31.91672 | G13: =J116 -> -15.917452 | H13: =K116 -> 0 | I13: =L116 -> 0
A14: Upah kupas | B14: =E58/10^6 -> 0 | C14: =F58 -> 0 | D14: =G118 -> 0 | E14: =H118 -> 0 | F14: =I118 -> 0 | G14: =J118 -> 0 | H14: =K118 -> 0 | I14: =L118 -> 0
A15: Direct labour (Grup A) | B15: =E59/10^6 -> 24.009429 | C15: =F59 -> 3243.2026 | D15: =G120 -> 2105.5178 | E15: =H120 -> 1137.6848 | F15: =I120 -> 211.02723 | G15: =J120 -> 0 | H15: =K120 -> -506.93085 | I15: =L120 -> 1433.5884
A16: Factory overhead (Grup B–E) | B16: =E64/10^6 -> 21.678333 | C16: =F64 -> 2928.3172 | D16: =G125 -> 2649.1451 | E16: =H125 -> 279.17215 | F16: =I125 -> 134.33127 | G16: =J125 -> 0 | H16: =K125 -> -637.81619 | I16: =L125 -> 782.65708
A17: Total biaya produksi | B17: =E66/10^6 -> 238.93443 | C17: =F66 -> 32275.352 | D17: =G126 -> 33916.194 | E17: =H126 -> -1640.8416 | F17: =I126 -> 977.27671 | G17: =J126 -> -3689.6167 | H17: =K126 -> -1144.747 | I17: =L126 -> 2216.2455
A18: Produksi bulan ini (kg; aktual, budget) | C18: =$B$32 -> 7403 | D18: =$D$32 -> 5620.6313
A19: Biaya konversi per kg (aktual, budget) | C19: =F65 -> 6171.5199 | D19: =G118+G120+G125 -> 4754.6629
A20: HPP (Rp jt) dan HPP per kg terjual (aktual, budget) | B20: =E98/10^6 -> 238.93443 | C20: =D99 -> 32275.352 | D20: =F99 -> 34110.89
A21: Pendapatan (Rp jt; aktual) | B21: =$C$208/10^6 -> 354.6037 | F21: Sumber: Lampiran A. Pendapatan dikelompokkan sejalan dengan biayanya
A22: Margin kotor (Rp jt; %) | B22: =B21-B20 -> 115.66927 | C22: =IF(B21=0,0,B22/B21) -> 0.32619307
A23: Memo: biaya waste (kerugian normal) yang masuk HPP (Rp jt; % biaya produksi) | B23: =E76/10^6 -> 0 | C23: =IF(E66=0,0,E76/E66) -> 0
A24: Memo: KW 2 dikreditkan pada NRV (Rp jt) | B24: =-E72/10^6 -> 0
A25: Memo: kenaikan WIP + FG (Rp jt) dan porsi biaya konversi di dalamnya | B25: =(E77+E89-E70-E84)/10^6 -> 0 | C25: =IF(E66=0,0,B25*E65/E66) -> 0 | F25: Biaya konversi yang tertahan di neraca bila produksi > penjualan
A26: Pemilik efek: harga → Purchasing; pemakaian/yield → Produksi; volume → PPIC; belanja pool → pemilik pool (Produksi/Engineering/HR); metode alokasi → Finance (costing).
A28: 2. Laporan biaya produksi
A29: 2a. Kuantitas (kg)
A30: Pos | B30: Aktual kg | C30: % dari produksi | D30: Budget kg | E30: % budget
A31: WIP awal | B31: =$C$192 -> 0
A32: Produksi bulan ini (masuk proses) | B32: =$C$193 -> 7403 | D32: =INDEX(BUDGET!$C$152:$R$152,$E$5) -> 5620.6313
A33: Total untuk dipertanggungjawabkan | B33: =B31+B32 -> 7403
A34: Premium ke barang jadi | B34: =B33-B35-B36-B37 -> 7403 | C34: =IF(B32=0,0,B34/B32) -> 1 | D34: =INDEX(BUDGET!$C$148:$R$148,$E$5) -> 5564.425 | E34: =IF(D32=0,0,D34/D32) -> 0.99
A35: KW 2 (produk sampingan) | B35: =$C$195 -> 0 | C35: =IF(B32=0,0,B35/B32) -> 0 | D35: =INDEX(BUDGET!$C$149:$R$149,$E$5) -> 0 | E35: =IF(D32=0,0,D35/D32) -> 0
A36: Keripik waste (kerugian normal) | B36: =$C$196 -> 0 | C36: =IF(B32=0,0,B36/B32) -> 0 | D36: =INDEX(BUDGET!$C$150:$R$150,$E$5) -> 56.206313 | E36: =IF(D32=0,0,D36/D32) -> 0.01
A37: WIP akhir | B37: =$C$194 -> 0 | C37: =IF(B32=0,0,B37/B32) -> 0 | D37: =INDEX(BUDGET!$C$151:$R$151,$E$5) -> 0 | E37: =IF(D32=0,0,D37/D32) -> 0
A38: Total dipertanggungjawabkan | B38: =SUM(B34:B37) -> 7403
A40: 2b. Biaya produksi bulan ini (aktual)
A41: Komponen | B41: Qty | C41: Satuan | D41: Harga | E41: Nilai (Rp) | F41: Rp/kg
A42: Raw materials
A43: Ubi orange | B43: =D212 -> 26039 | C43: kg | D43: =F212 -> 4705.1845 | E43: =G212 -> 1.225183e+08 | F43: =IF($B$32=0,0,E43/$B$32) -> 16549.818
A44: Subtotal raw materials | E44: =E43 -> 1.225183e+08 | F44: =IF($B$32=0,0,E44/$B$32) -> 16549.818
...

Sheet LAIN-LAIN
A1: KARTU BIAYA PRODUKSI – LAIN-LAIN (retail, koperasi, maklon), Agustus 2026
A2: Satu baris per kelompok produk. Bahan antarproduk (FCC premium, KW 2) dinilai dari sheet FCC. Konversi dari BIAYA BERSAMA kolom Lain-lain. HPP = biaya produksi (belum ada roll-forward persediaan Lain-lain).
A3: Biru = input (lampiran), hijau = tautan antarsheet, hitam = rumus. Ringkasan dalam Rp juta; rincian dalam Rp.
A5: Bulan budget pembanding | C5: Okt-26 | D5: posisi: | E5: =MATCH(C5,BUDGET!$C$4:$R$4,0) -> 2
A6: Status kontrol (bagian 4) | C6: =IF(COUNTIF(D72:D75,"GAGAL")=0,"LULUS","GAGAL") -> LULUS
A7: Nilai KW 2 ubi (Rp/kg) | C7: 0 | D7: ASUMSI no. 7: UU/UO tidak mencatat KW 2, jadi belum ada NRV; nol konsisten dengan tidak adanya kredit KW 2 di UU/UO
A9: 1. Ringkasan (Rp juta)
A10: Pos | B10: Aktual (Rp jt) | C10: Budget (Rp jt) | D10: Selisih
A11: Material eksternal + konversi (tanpa bahan antarproduk) | B11: =(D68+E68+F68)/10^6 -> 84.76126 | C11: =INDEX(BUDGET!$C$198:$R$198,$E$5)/10^6 -> 41.069007 | D11: =B11-C11 -> 43.692253 | E11: Budget Lain-lain di BP masih nilai beku dan tidak memuat bahan antarproduk
A12: Bahan antarproduk (FCC premium, KW 2) | B12: =(B68+C68)/10^6 -> 270.8207
A13: di dalamnya: konversi (DL + FOH) | B13: =(E68+F68)/10^6 -> 72.12766
A14: Total biaya produksi = HPP Lain-lain | B14: =G68/10^6 -> 355.58196 | C14: =INDEX(BUDGET!$C$199:$R$199,$E$5)/10^6 -> 41.069007 | D14: =B14-C14 -> 314.51296
A15: Output (kg) | B15: =C43 -> 17571.48
A16: Biaya per kg (Rp) | B16: =H68 -> 20236.313
A17: Pendapatan Others: retail & maklon + KW 2 berbumbu (Rp jt; BP Data Aktual P68 + P65) | B17: =416714799.61/10^6 -> 416.7148
A18: Margin kotor Others (Rp jt; %) | B18: =B17-B14 -> 61.132836 | C18: =IF(B17=0,0,B18/B17) -> 0.14670186
A20: 2. Input per kelompok produk (Lampiran: kartu LAP di WP lama)
A21: Kelompok produk | B21: Lini bahan utama (akun varian) | C21: Output (kg) | D21: Input FCC premium (kg) | E21: Input KW 2 FCC (kg) | F21: Input KW 2 ubi (kg) | G21: Material eksternal (Rp) | H21: Man-hour | I21: kWh | J21: Bulan aktif Jan–Agu | K21: Kartu sumber | L21: Catatan
A22: Cem-cem ORI | B22: Singkong | C22: 5124.6 | D22: 4950 | E22: 0 | F22: 0 | G22: 257400 | H22: 421.02738 | I22: 1982.0326 | J22: Agu | K22: LAP BAG CEMCEM ORI | L22: Bumbu Seors 295,83 kg belum berharga (harga 0)
A23: Cem-cem BBQ | B23: Singkong | C23: 5047.2 | D23: 4807 | E23: 0 | F23: 0 | G23: 316800 | H23: 414.97262 | I23: 1982.0326 | J23: Agu | K23: LAP BAG CEMCEM BBQ | L23: Bumbu BBQ 335,2 kg belum berharga; kWh sama persis dengan ORI
A24: Koperasi (KW 2 berbumbu, 11 SKU) | B24: Singkong | C24: 5874 | D24: 0 | E24: 4784.8 | F24: 740.94 | G24: 11730364 | H24: 237 | I24: 0 | J24: Jan–Agu | K24: Bagging Kop | L24: Input KW 2 di kartu lama bernilai nol
A25: Maicih basreng (maklon, 3 SKU) | B25: Singkong (maklon) | C25: 626 | D25: 0 | E25: 0 | F25: 0 | G25: 23956.193 | H25: 44.762947 | I25: 369.94888 | J25: Jan–Agu, tidak tiap bulan | K25: LAP BAG MAICIH BASRENG L.0/5/10 LOK | L25: Basreng, polyfilm, karton dari pelanggan
A26: Maicih keripik (LV 3 & 10) | B26: Singkong | C26: 899.68 | D26: 0 | E26: 833 | F26: 0 | G26: 305079.82 | H26: 73.575359 | I26: 423.79847 | J26: Jan–Agu kecuali Jun | K26: LAP BAG MAICIH KERIPIK LV 3/10 | L26: Nama kartu di Labor (M) dan Overhead Allocation (SA) berbeda
A27: Maicih keripik LV 5 | B27: Singkong | C27: 0 | D27: 0 | E27: 0 | F27: 0 | G27: 0 | H27: 0 | I27: 0 | J27: Jan–Jul kecuali Jun | K27: LAP BAG MAICIH KERIPIK LV 5 | L27: Tidak aktif di Agustus
A28: FCC Maicih | B28: Singkong | C28: 0 | D28: 0 | E28: 0 | F28: 0 | G28: 0 | H28: 0 | I28: 0 | J28: Jan, Feb, Jul | K28: FCC MAICIH | L28: Tidak aktif di Agustus
A29: FCC Putih | B29: Singkong | C29: 0 | D29: 0 | E29: 0 | F29: 0 | G29: 0 | H29: 0 | I29: 0 | J29: - | K29: FCCPUTIH | L29: Tidak aktif di Agustus
A30: Kecimpring (goreng & bagging) | B30: Singkong | C30: 0 | D30: 0 | E30: 0 | F30: 0 | G30: 0 | H30: 0 | I30: 0 | J30: Jan, Feb | K30: LAP GORENG/BAGGING KECIMPRING, KECIMPRING BMG/Sani | L30: Tidak aktif di Agustus
A31: Whole chips rempah 15/90 gr | B31: Singkong | C31: 0 | D31: 0 | E31: 0 | F31: 0 | G31: 0 | H31: 0 | I31: 0 | J31: Jul | K31: LAP WHOLE CHIPS REMPAH 15GR/90GR | L31: Tidak aktif di Agustus
A32: Maxi (pellet & goreng) | B32: Singkong – cek bahan | C32: 0 | D32: 0 | E32: 0 | F32: 0 | G32: 0 | H32: 0 | I32: 0 | J32: Jul | K32: PELELT MAXI BIONIC, LAP GORENG MAXI 3X3 | L32: Tidak aktif di Agustus
A33: Pellet ubi ungu FG (1,2x1,5 & 3x3) | B33: Ubi Ungu | C33: 0 | D33: 0 | E33: 0 | F33: 0 | G33: 0 | H33: 0 | I33: 0 | J33: Jan, Jun | K33: PELELT UBI UNGU FG 1.2x1.5 / 3x3 | L33: Tidak aktif di Agustus
... A42: WRP (Delichips, Mixfruit, chips) – maklon | B42: Singkong (maklon) | C42: 0 | D42: 0 | E42: 0 | F42: 0 | G42: 0 | H42: 0 | I42: 0 | J42: Apr, Jun, Jul | K42: LAP BAG WRP DELICHIPS/MIXFRUIT, WRP Chips | L42: Tidak aktif di Agustus
A43: Total | C43: =SUM(C22:C42) -> 17571.48 | D43: =SUM(D22:D42) -> 9757 | E43: =SUM(E22:E42) -> 5617.8 | F43: =SUM(F22:F42) -> 740.94 | G43: =SUM(G22:G42) -> 12633600 | H43: =SUM(H22:H42) -> 1191.3383 | I43: =SUM(I22:I42) -> 4757.8126
A45: 3. Biaya produksi per kelompok (Rp)
A46: Kelompok produk | B46: FCC premium | C46: KW 2 | D46: Material eksternal | E46: DL (Grup A) | F46: FOH (Grup B–E) | G46: Total biaya | H46: Rp/kg
A47: =A22 -> Cem-cem ORI | B47: =D22*FCC!$D$88 -> 1.0952906e+08 | C47: =E22*FCC!$C$208+F22*$C$7 -> 0 | D47: =G22 -> 257400 | E47: =IF($H$43=0,0,H22/$H$43)*'BIAYA BERSAMA'!$F$115 -> 9438493.9 | F47: =IF($H$43=0,0,H22/$H$43)*'BIAYA BERSAMA'!$F$117+IF($I$43=0,0,I22/$I$43)*('BIAYA BERSAMA'!$F$118+'BIAYA BERSAMA'!$F$119)+IF($G$43=0,0,G22/$G$43)*'BIAYA BERSAMA'!$F$120 -> 17796195 | G47: =SUM(B47:F47) -> 1.3702115e+08 | H47: =IF(C22=0,0,G47/C22) -> 26737.921
A48: =A23 -> Cem-cem BBQ | B48: =D23*FCC!$D$88 -> 1.0636489e+08 | C48: =E23*FCC!$C$208+F23*$C$7 -> 0 | D48: =G23 -> 316800 | E48: =IF($H$43=0,0,H23/$H$43)*'BIAYA BERSAMA'!$F$115 -> 9302759.7 | F48: =IF($H$43=0,0,H23/$H$43)*'BIAYA BERSAMA'!$F$117+IF($I$43=0,0,I23/$I$43)*('BIAYA BERSAMA'!$F$118+'BIAYA BERSAMA'!$F$119)+IF($G$43=0,0,G23/$G$43)*'BIAYA BERSAMA'!$F$120 -> 17715505 | G48: =SUM(B48:F48) -> 1.3369995e+08 | H48: =IF(C23=0,0,G48/C23) -> 26489.926
A49: =A24 -> Koperasi (KW 2 berbumbu, 11 SKU) | B49: =D24*FCC!$D$88 -> 0 | C49: =E24*FCC!$C$208+F24*$C$7 -> 46782287 | D49: =G24 -> 11730364 | E49: =IF($H$43=0,0,H24/$H$43)*'BIAYA BERSAMA'!$F$115 -> 5313010.9 | F49: =IF($H$43=0,0,H24/$H$43)*'BIAYA BERSAMA'!$F$117+IF($I$43=0,0,I24/$I$43)*('BIAYA BERSAMA'!$F$118+'BIAYA BERSAMA'!$F$119)+IF($G$43=0,0,G24/$G$43)*'BIAYA BERSAMA'!$F$120 -> 3457584 | G49: =SUM(B49:F49) -> 67283246 | H49: =IF(C24=0,0,G49/C24) -> 11454.417
A50: =A25 -> Maicih basreng (maklon, 3 SKU) | B50: =D25*FCC!$D$88 -> 0 | C50: =E25*FCC!$C$208+F25*$C$7 -> 0 | D50: =G25 -> 23956.193 | E50: =IF($H$43=0,0,H25/$H$43)*'BIAYA BERSAMA'!$F$115 -> 1003485.3 | F50: =IF($H$43=0,0,H25/$H$43)*'BIAYA BERSAMA'!$F$117+IF($I$43=0,0,I25/$I$43)*('BIAYA BERSAMA'!$F$118+'BIAYA BERSAMA'!$F$119)+IF($G$43=0,0,G25/$G$43)*'BIAYA BERSAMA'!$F$120 -> 2863367 | G50: =SUM(B50:F50) -> 3890808.5 | H50: =IF(C25=0,0,G50/C25) -> 6215.3491
A51: =A26 -> Maicih keripik (LV 3 & 10) | B51: =D26*FCC!$D$88 -> 0 | C51: =E26*FCC!$C$208+F26*$C$7 -> 8144466.9 | D51: =G26 -> 305079.82 | E51: =IF($H$43=0,0,H26/$H$43)*'BIAYA BERSAMA'!$F$115 -> 1649395.3 | F51: =IF($H$43=0,0,H26/$H$43)*'BIAYA BERSAMA'!$F$117+IF($I$43=0,0,I26/$I$43)*('BIAYA BERSAMA'!$F$118+'BIAYA BERSAMA'!$F$119)+IF($G$43=0,0,G26/$G$43)*'BIAYA BERSAMA'!$F$120 -> 3587864.2 | G51: =SUM(B51:F51) -> 13686806 | H51: =IF(C26=0,0,G51/C26) -> 15212.971
A52: =A27 -> Maicih keripik LV 5 | B52: =D27*FCC!$D$88 -> 0 | C52: =E27*FCC!$C$208+F27*$C$7 -> 0 | D52: =G27 -> 0 | E52: =IF($H$43=0,0,H27/$H$43)*'BIAYA BERSAMA'!$F$115 -> 0 | F52: =IF($H$43=0,0,H27/$H$43)*'BIAYA BERSAMA'!$F$117+IF($I$43=0,0,I27/$I$43)*('BIAYA BERSAMA'!$F$118+'BIAYA BERSAMA'!$F$119)+IF($G$43=0,0,G27/$G$43)*'BIAYA BERSAMA'!$F$120 -> 0 | G52: =SUM(B52:F52) -> 0 | H52: =IF(C27=0,0,G52/C27) -> 0
...

Sheet BIAYA BERSAMA
A1: BIAYA BERSAMA PABRIK – Agustus 2026
A2: Saldo GL biaya konversi pabrik → pool → driver per produk → alokasi. Semua pool habis dialokasikan (penyerapan penuh), kecuali jam menganggur bila parameter di bagian 6 diaktifkan.
A3: Biru = input (lampiran), hijau = tautan antarsheet, hitam = rumus. Ringkasan dalam Rp juta; rincian dalam Rp.
A5: 1. Saldo akun biaya pabrik – GL Agustus 2026 (Rp)
A6: Kode | B6: Nama akun | C6: Agu-26 (Rp) | D6: Pool | E6: Akun baru mulai Okt-26 | F6: Sumber
A7: 5101-002 | B7: COGM - DL - Biaya Upah Langsung Pabrik | C7: 961759797 | D7: Dipecah (bagian 2) | E7: 5101-111/121/131/141 | F7: TB Accurate Agu-26
A8: 5101-003 | B8: COGM - DL - THR & Bonus Pabrik | C8: 63137128 | D8: Dipecah (bagian 2) | E8: 5101-112/113/122/132/133/142/143 | F8: TB Accurate Agu-26
A9: 5101-004 | B9: COGM - DL - Pesangon Pabrik | C9: 0 | D9: Grup A | E9: 5101-150 | F9: TB Accurate Agu-26
A10: 5101-005 | B10: COGM - DL - Biaya Jamsostek Pabrik | C10: 128572648 | D10: Dipecah (bagian 2) | E10: 5101-114/124/134/144 | F10: TB Accurate Agu-26
A11: 5101-006 | B11: COGM - OHP - Biaya Listrik Pabrik | C11: 56566114 | D11: Grup C | E11: 5101-006 | F11: TB Accurate Agu-26
A12: 5101-007 | B12: COGM - OHP - Biaya Air Pabrik | C12: 79000 | D12: Grup C | E12: 5101-007 | F12: TB Accurate Agu-26
A13: 5101-008 | B13: COGM - OHP - Biaya Utilitas Pabrik | C13: 0 | D13: Grup C | E13: 5101-008 | F13: TB Accurate Agu-26
A14: 5101-009 | B14: COGM - OHP - Biaya Rumah Tangga Pabrik | C14: 24213641 | D14: Grup E | E14: 5101-009 | F14: TB Accurate Agu-26
A15: 5101-010 | B15: COGM - OHP - Biaya Perbaikan & Pemeliharaan Mesin | C15: 1.0365535e+08 | D15: Grup D | E15: 5101-010 | F15: TB Accurate Agu-26
A16: 5101-011 | B16: COGM - OHP - Biaya Perbaikan & Pemeliharaan Pabrik | C16: 41591502 | D16: Grup E | E16: 5101-011 | F16: TB Accurate Agu-26
A17: 5101-012 | B17: COGM - OHP - Biaya Perbaikan & Pemeliharaan Inventaris Pabrik | C17: 4703135 | D17: Grup E | E17: 5101-012 | F17: TB Accurate Agu-26
A18: 5101-013 | B18: COGM - OHP - Biaya Peny. Mesin Gol 1 | C18: 16700889 | D18: Grup D | E18: 5101-013 | F18: TB Accurate Agu-26
... A22: 6500-007 | B22: COGM - OHP - Biaya Peny. Inventaris Pabrik Gol 2 | C22: 14533271 | D22: Grup E | E22: 5101-017 | F22: TB Accurate Agu-26
B23: Total biaya konversi pabrik | C23: =SUM(C7:C22) -> 1.6066528e+09
B24: Referensi: BP Model Details Q173 | C24: 1.6066528e+09 | F24: Untuk kontrol
A26: 2. Rincian upah 5101-002 per kelompok, dan pembagian THR/BPJS (sementara sampai akun payroll baru aktif)
A27: Kelompok | B27: Unit / departemen | C27: Agu-26 (Rp) | D27: Pool | E27: Sumber
A28: Operator harian | B28: Unit I | C28: 511029300 | D28: Grup A | E28: WP CoGM Agu, Labor!E6
A29: Operator harian | B29: Unit II | C29: 0 | D29: Grup A | E29: Labor!E7
A30: Operator harian | B30: Unit III | C30: 0 | D30: Grup A | E30: Labor!E8
A31: Support harian | B31: QC | C31: 60505300 | D31: Grup B | E31: Labor!E9
A32: Support harian | B32: Formulasi | C32: 0 | D32: Grup B | E32: Labor!E10
A33: Support harian | B33: RnD | C33: 0 | D33: Grup B | E33: Labor!E11
A34: Support harian | B34: Engineering | C34: 35012300 | D34: Grup B | E34: Labor!E12
A35: Support harian | B35: PPIC | C35: 2829600 | D35: Grup B | E35: Labor!E13
A36: Support harian | B36: Gudang | C36: 15710000 | D36: Grup B | E36: Labor!E14
A37: Support harian | B37: HRGA | C37: 39263300 | D37: Grup B | E37: Labor!E15
A38: Support harian | B38: Agro | C38: 0 | D38: Grup B | E38: Labor!E16
A39: Borongan kupas | B39: Kupas singkong | C39: 110021625 | D39: Kupas | E39: Labor!J6
... A41: Staf bulanan pabrik | B41: Semua departemen pabrik | C41: 165813709 | D41: Grup B | E41: BP Model Details Q134 (register payroll)
B42: Subtotal rekap payroll | C42: =SUM(C28:C41) -> 940185134
B43: GL 5101-002 | C43: =$C$7 -> 961759797
B44: Selisih GL − rekap (belum terpetakan, sementara di Grup A) | C44: =C43-C42 -> 21574663
A46: Parameter: kupas ikut THR & BPJS? (1 = ya, 0 = tidak) | C46: 0 | E46: Lihat sheet ASUMSI no. 3
A47: Basis pembagian THR & BPJS | C47: Upah/gaji pokok | D47: Porsi | E47: THR (5101-003) | F47: BPJS (5101-005)
...

Sheet REKON & KONTROL
A1: REKAP, REKONSILIASI KE GL, DAN KONTROL – Agustus 2026
A2: Semua produk dijumlahkan dan dicocokkan ke GL. Biru = input (lampiran), hijau = tautan antarsheet, hitam = rumus. Ringkasan dalam Rp juta; rincian dalam Rp.
A4: 1. Rekap semua produk (Rp juta)
A5: Pos | B5: FCC | C5: Ubi Ungu | D5: Ubi Orange | E5: Lain-lain | F5: Total | H5: Budget total | I5: Selisih
A6: Produksi (kg) | B6: =FCC!$B$30 -> 338754 | C6: =UU!$B$32 -> 13376 | D6: =UO!$B$32 -> 7403 | E6: ='LAIN-LAIN'!$C$43 -> 17571.48 | F6: =SUM(B6:E6) -> 377104.48
A7: Material eksternal | B7: =FCC!$G$228/10^6 -> 5924.2269 | C7: =UU!$G$218/10^6 -> 379.68621 | D7: =UO!$G$219/10^6 -> 193.24667 | E7: ='LAIN-LAIN'!$D$68/10^6 -> 12.6336 | F7: =SUM(B7:E7) -> 6509.7933
A8: Bahan antarproduk (FCC premium, KW 2) | B8: 0 | C8: 0 | D8: 0 | E8: =('LAIN-LAIN'!$B$68+'LAIN-LAIN'!$C$68)/10^6 -> 270.8207 | F8: =SUM(B8:E8) -> 270.8207
A9: Upah kupas | B9: =FCC!$E$57/10^6 -> 110.02163 | C9: =UU!$E$58/10^6 -> 0 | D9: =UO!$E$58/10^6 -> 0 | E9: 0 | F9: =SUM(B9:E9) -> 110.02163
A10: Direct labour (Grup A) | B10: =FCC!$E$58/10^6 -> 554.72766 | C10: =UU!$E$59/10^6 -> 45.171801 | D10: =UO!$E$59/10^6 -> 24.009429 | E10: ='LAIN-LAIN'!$E$68/10^6 -> 26.707145 | F10: =SUM(B10:E10) -> 650.61603
A11: Factory overhead (Grup B–E) | B11: =FCC!$E$63/10^6 -> 738.46455 | C11: =UU!$E$64/10^6 -> 40.451703 | D11: =UO!$E$64/10^6 -> 21.678333 | E11: ='LAIN-LAIN'!$F$68/10^6 -> 45.420515 | F11: =SUM(B11:E11) -> 846.0151
A12: Total biaya produksi | B12: =SUM(B7:B11) -> 7327.4407 | C12: =SUM(C7:C11) -> 465.30971 | D12: =SUM(D7:D11) -> 238.93443 | E12: =SUM(E7:E11) -> 355.58196 | F12: =SUM(F7:F11) -> 8387.2668
A13: Rp per kg produksi | B13: =IF(B6=0,0,B12*10^6/B6) -> 21630.566 | C13: =IF(C6=0,0,C12*10^6/C6) -> 34786.91 | D13: =IF(D6=0,0,D12*10^6/D6) -> 32275.352 | E13: =IF(E6=0,0,E12*10^6/E6) -> 20236.313 | F13: =IF(F6=0,0,F12*10^6/F6) -> 22241.228
A14: HPP | B14: =FCC!$E$103/10^6 -> 6925.005 | C14: =UU!$E$98/10^6 -> 250.83102 | D14: =UO!$E$98/10^6 -> 238.93443 | E14: ='LAIN-LAIN'!$G$68/10^6 -> 355.58196 | F14: =SUM(B14:E14) -> 7770.3524 | H14: =(FCC!$E$105+UU!$E$100+UO!$E$100+INDEX(BUDGET!$C$199:$R$199,'LAIN-LAIN'!$E$5))/10^6 -> 7618.5801 | I14: =F14-H14 -> 151.77227
A15: Pendapatan (dikelompokkan sejalan dengan biaya) | B15: =FCC!$C$210/10^6 -> 8672.0977 | C15: =UU!$C$207/10^6 -> 349.70925 | D15: =UO!$C$208/10^6 -> 354.6037 | E15: =416714799.61/10^6 -> 416.7148 | F15: =SUM(B15:E15) -> 9793.1255
A16: Margin kotor per produk (%) | B16: =IF(B15=0,0,(B15-B14)/B15) -> 0.20146138 | C16: =IF(C15=0,0,(C15-C14)/C15) -> 0.28274411 | D16: =IF(D15=0,0,(D15-D14)/D15) -> 0.32619307 | E16: =IF(E15=0,0,(E15-E14)/E15) -> 0.14670186 | F16: =IF(F15=0,0,(F15-F14)/F15) -> 0.20655031
A17: Budget HPP memakai bulan yang dipilih di masing-masing sheet dan volume budget. Margin di atas belum termasuk pos di bagian 3 yang tidak dibagi ke produk.
A18: Pendapatan: FCC = premium IFM + KW 2 tawar; Others = retail & maklon + KW 2 berbumbu. Total sama dengan GL. BP baris 10–13 saat ini menghitung KW 2 dua kali (Rp 107,9 jt di Agustus).
A20: 2. Material semua produk vs pemakaian GL, dan varian per akun (Rp juta)
A21: Produk / lini | B21: Material kartu | C21: Porsi | D21: Varian sementara | E21: Akun varian mulai Okt-26
A22: FCC | B22: ='BIAYA BERSAMA'!C94/10^6 -> 5924.2269 | C22: =IF($B$28=0,0,B22/$B$28) -> 0.91004838 | D22: =$B$30*C22 -> 185.40464 | E22: 5101-301 Varian Produksi Singkong
A23: Ubi Ungu IFM | B23: ='BIAYA BERSAMA'!D94/10^6 -> 379.68621 | C23: =IF($B$28=0,0,B23/$B$28) -> 0.058325386 | D23: =$B$30*C23 -> 11.882662 | E23: 5101-302 Varian Produksi Ubi Ungu
A24: Ubi Orange IFM | B24: ='BIAYA BERSAMA'!E94/10^6 -> 193.24667 | C24: =IF($B$28=0,0,B24/$B$28) -> 0.029685531 | D24: =$B$30*C24 -> 6.047849 | E24: 5101-303 Varian Produksi Ubi Orange
A25: Lain-lain lini singkong (termasuk maklon) | B25: =SUMPRODUCT(('LAIN-LAIN'!$B$22:$B$42<>"Ubi Ungu")*('LAIN-LAIN'!$B$22:$B$42<>"Ubi Orange")*('LAIN-LAIN'!$B$22:$B$42<>"Ubi Ungu – cek bahan")*'LAIN-LAIN'!$G$22:$G$42)/10^6 -> 12.6336 | C25: =IF($B$28=0,0,B25/$B$28) -> 0.0019407068 | D25: =$B$30*C25 -> 0.39538124 | E25: 5101-301 Varian Produksi Singkong
A26: Lain-lain lini ubi ungu | B26: =SUMIF('LAIN-LAIN'!$B$22:$B$42,"Ubi Ungu*",'LAIN-LAIN'!$G$22:$G$42)/10^6 -> 0 | C26: =IF($B$28=0,0,B26/$B$28) -> 0 | D26: =$B$30*C26 -> 0 | E26: 5101-302 Varian Produksi Ubi Ungu
A27: Lain-lain lini ubi orange | B27: =SUMIF('LAIN-LAIN'!$B$22:$B$42,"Ubi Orange",'LAIN-LAIN'!$G$22:$G$42)/10^6 -> 0 | C27: =IF($B$28=0,0,B27/$B$28) -> 0 | D27: =$B$30*C27 -> 0 | E27: 5101-303 Varian Produksi Ubi Orange
A28: Total material kartu | B28: =SUM(B22:B27) -> 6509.7933 | D28: =SUM(D22:D27) -> 203.73054
A29: Pemakaian bahan baku menurut GL | B29: 6713.5239 | E29: BP DATA - GL Aktual 2026 J43
A30: Varian material (GL − kartu) | B30: =B29-B28 -> 203.73054
A31: 5101-301 Varian Produksi Singkong | D31: =D22+D25 -> 185.80002
A32: 5101-302 Varian Produksi Ubi Ungu | D32: =D23+D26 -> 11.882662
A33: 5101-303 Varian Produksi Ubi Orange | D33: =D24+D27 -> 6.047849
A34: Pembagian ke lini sementara memakai porsi kartu, karena GL belum memisahkan pemakaian per jenis bahan. Mulai Okt-26 dihitung per jenis bahan (akun 5101-201 s/d 207).
A36: 3. Rekonsiliasi HPP semua produk ke HPP GL (Rp juta)
A37: Total HPP kartu baru, semua produk | C37: =F14 -> 7770.3524
A38: + Varian material (GL − kartu) | C38: =$B$30 -> 203.73054
A39: + Kenaikan persediaan WIP & FG menurut kartu baru (FCC, UU, UO) | C39: =((FCC!$E$78+FCC!$E$91-FCC!$E$71-FCC!$E$85)+(UU!$E$77+UU!$E$89-UU!$E$70-UU!$E$84)+(UO!$E$77+UO!$E$89-UO!$E$70-UO!$E$84))/10^6 -> 325.80393
A40: − Kenaikan persediaan WIP & FG menurut GL (1106-002, 1106-003) | C40: =-((494002781.765743-238973459.696273)+(499690064.502333-276688460.92344))/10^6 -> -478.03093
A41: + Kenaikan persediaan KW 2 pada NRV (tidak dicatat di GL) | C41: =(-FCC!$E$73-'LAIN-LAIN'!$E$43*FCC!$C$208-FCC!$E$102)/10^6 -> 20.289793
A42: + Biaya jam menganggur dibebankan ke periode (BIAYA BERSAMA bagian 5) | C42: ='BIAYA BERSAMA'!$C$111/10^6 -> 0
A43: HPP menurut rekonsiliasi | C43: =SUM(C37:C42) -> 7842.1457
...

Sheet ASUMSI
A1: DAFTAR ASUMSI DAN SUMBER
A2: Setiap angka yang bukan aktual dari GL/laporan produksi. Status: Aktual / Estimasi / [TBC] = perlu konfirmasi.
A4: No | B4: Asumsi | C4: Nilai | D4: Dasar | E4: Pemilik | F4: Status | G4: Terdokumentasi? | H4: Dipakai di
A5: 1 | B5: Sistem biaya | C5: Biaya aktual, penyerapan penuh | D5: Kartu menyerap seluruh pool pabrik GL; overhead dialokasikan dengan driver aktual bulan berjalan (bukan tarif ditetapkan) | E5: Finance (costing) | F5: Usulan | G5: Belum | H5: Semua sheet produk
A6: 2 | B6: Pembagian 5101-002 per kelompok | C6: Rekap sheet Labor + register payroll staf | D6: Akun payroll per kelompok baru aktif Okt-26 | E6: HR / Finance | F6: Estimasi | G6: Sebagian | H6: BIAYA BERSAMA 2
A7: 3 | B7: Kupas ikut THR & BPJS | C7: 0 (tidak) | D7: THR pabrik 2026 ≈ 1x rata-rata upah Jan–Mar tanpa kupas | E7: HR | F7: [TBC] | G7: Belum | H7: BIAYA BERSAMA 2
A8: 4 | B8: Pembagian THR & BPJS antarkelompok | C8: Pro rata upah/gaji pokok | D8: Akun THR/BPJS belum terpisah per kelompok | E8: Finance | F8: Estimasi | G8: Belum | H8: BIAYA BERSAMA 2
A9: 5 | B9: NRV KW 2 | C9: Rp 9.777,27/kg | D9: Harga KW 2 ke KGS tertimbang Jan–Agu (tawar + berbumbu), tanpa pengurang biaya jual | E9: Commercial / Finance | F9: Estimasi | G9: Sebagian | H9: FCC, LAIN-LAIN
A10: 6 | B10: Konversi CNG | C10: 22,2967 m3 per MMBTU | D10: Uji 12 invoice (catatan proyek CNG) | E10: Purchasing | F10: Estimasi | G10: Ya (catatan) | H10: FCC, UU, UO
A11: 7 | B11: Nilai KW 2 ubi sebagai bahan Lain-lain | C11: Rp 0/kg | D11: UU/UO tidak mencatat KW 2 di kartu; tidak ada kredit NRV | E11: Produksi / Finance | F11: [TBC] | G11: Belum | H11: LAIN-LAIN
A12: 8 | B12: Driver alokasi | C12: A, B: man-hour; C, D: kWh; E: nilai material; kupas: kg dikupas | D12: Data kartu Labor dan Overhead Allocation | E12: Finance (costing) | F12: Usulan | G12: Belum | H12: BIAYA BERSAMA 6
A13: 9 | B13: Kapasitas normal tenaga kerja | C13: Jam dibayar Unit I; jam tak terpakai tetap diserap (parameter 0) | D13: Belum ada penetapan kapasitas normal (PSAK 202) | E13: Produksi / Finance | F13: [TBC] | G13: Belum | H13: BIAYA BERSAMA 5
A14: 10 | B14: Nilai WIP awal FCC Agustus | C14: Nilai kartu lama (penyerapan parsial) | D14: Hanya untuk bulan percontohan; berikutnya WIP akhir kartu baru | E14: Finance | F14: Estimasi | G14: - | H14: FCC 2c
A15: 11 | B15: Harga material | C15: Sheet Average Price WP lama | D15: Target: laporan nilai persediaan Accurate | E15: Finance / Gudang | F15: Estimasi | G15: Sebagian | H15: Lampiran B
A16: 12 | B16: Nilai tanpa kuantitas di Accurate | C16: Tidak ikut rata-rata FG | D16: Residu penilaian; perlu dibersihkan di Accurate | E16: Finance | F16: Aktual | G16: - | H16: UU, UO bagian 3
... A18: 14 | B18: Lini bahan utama produk Maxi, Umbiis, Pellet lainnya | C18: Ditandai "cek bahan" | D18: Belum ada konfirmasi bahan | E18: Produksi | F18: [TBC] | G18: Belum | H18: LAIN-LAIN 2

Sheet BUDGET
A1: BUDGET – ekstrak dari Business Plan v2 (sheet Business Plan - Model Details, kolom R:AG)
A2: Nilai ditempel dari BP, bukan tautan. Dipakai sebagai pembanding di sheet produk (bulan dipilih di masing-masing sheet).
A4: Baris MD | B4: Keterangan | C4: Sep-26 | D4: Okt-26 | E4: Nov-26 | F4: Des-26 | G4: Jan-27 | H4: Feb-27 | I4: Mar-27 | J4: Apr-27 | K4: Mei-27 | L4: Jun-27 | M4: Jul-27 | N4: Agu-27 | O4: Sep-27 | P4: Okt-27 | Q4: Nov-27 | R4: Des-27
A5: Flat Cassava Chips (FCC)
A6: MD411 | B6: Premium / layak jual | C6: 0.92953993 | D6: 0.92797454 | E6: 0.92989808 | F6: 0.92913752 | G6: 0.92900338 | H6: 0.92934632 | I6: 0.92916241 | J6: 0.9291707 | K6: 0.92922648 | L6: 0.92918653 | M6: 0.92919457 | N6: 0.92920253 | O6: 0.92919454 | P6: 0.92919721 | Q6: 0.92919809 | R6: 0.92919662
A7: MD412 | B7: KW 2 | C7: 0.035044382 | D7: 0.036571749 | E7: 0.037721086 | F7: 0.038771452 | G7: 0.038629975 | H7: 0.038727903 | I7: 0.038742466 | J7: 0.038070834 | K7: 0.037784981 | L7: 0.038127556 | M7: 0.038322031 | N7: 0.03839715 | O7: 0.038350362 | P7: 0.03831541 | Q7: 0.038263849 | R7: 0.038204022
A8: MD413 | B8: Keripik waste | C8: 0.035415693 | D8: 0.035453707 | E8: 0.032380835 | F8: 0.032091032 | G8: 0.032366646 | H8: 0.031925772 | I8: 0.032095127 | J8: 0.032758462 | K8: 0.032988541 | L8: 0.032685915 | M8: 0.032483398 | N8: 0.032400324 | O8: 0.032455096 | P8: 0.032487377 | Q8: 0.032538057 | R8: 0.032599362
A9: MD414 | B9: WIP from Premium/Layak Jual | C9: 0 | D9: 0 | E9: 0 | F9: 0 | G9: 0 | H9: 0 | I9: 0 | J9: 0 | K9: 0 | L9: 0 | M9: 0 | N9: 0 | O9: 0 | P9: 0 | Q9: 0 | R9: 0
A10: MD417 | B10: Target Volume Penjualan/Layak Jual | C10: 278373.52 | D10: 278373.52 | E10: 278373.52 | F10: 278373.52 | G10: 278373.52 | H10: 278373.52 | I10: 278373.52 | J10: 278373.52 | K10: 278373.52 | L10: 278373.52 | M10: 278373.52 | N10: 278373.52 | O10: 278373.52 | P10: 278373.52 | Q10: 278373.52 | R10: 278373.52
A11: MD418 | B11: KW 2 | C11: 10494.899 | D11: 10970.782 | E11: 11292.153 | F11: 11616.09 | G11: 11575.374 | H11: 11600.436 | I11: 11607.095 | J11: 11405.775 | K11: 11319.456 | L11: 11422.574 | M11: 11480.737 | N11: 11503.143 | O11: 11489.225 | P11: 11478.721 | Q11: 11463.263 | R11: 11445.358
A12: MD419 | B12: Keripik waste | C12: 10606.097 | D12: 10635.392 | E12: 9693.4997 | F12: 9614.6085 | G12: 9698.5836 | H12: 9562.9468 | I12: 9615.5779 | J12: 9814.2228 | K12: 9882.5596 | L12: 9792.3212 | M12: 9731.5653 | N12: 9706.5945 | O12: 9723.0868 | P12: 9732.7297 | Q12: 9747.9036 | R12: 9766.2851
A13: MD420 | B13: WIP | C13: 0 | D13: 0 | E13: 0 | F13: 0 | G13: 0 | H13: 0 | I13: 0 | J13: 0 | K13: 0 | L13: 0 | M13: 0 | N13: 0 | O13: 0 | P13: 0 | Q13: 0 | R13: 0
A14: MD421 | B14: Target output Produksi | C14: 299474.51 | D14: 299979.69 | E14: 299359.17 | F14: 299604.22 | G14: 299647.47 | H14: 299536.9 | I14: 299596.19 | J14: 299593.51 | K14: 299575.53 | L14: 299588.41 | M14: 299585.82 | N14: 299583.25 | O14: 299585.83 | P14: 299584.97 | Q14: 299584.68 | R14: 299585.16
A15: MD424 | B15: Overall yield singkong to Output | C15: 3.2 | D15: 3.2 | E15: 3.2 | F15: 3.2 | G15: 3.2 | H15: 3.2 | I15: 3.2 | J15: 3.2 | K15: 3.2 | L15: 3.2 | M15: 3.2 | N15: 3.2 | O15: 3.2 | P15: 3.2 | Q15: 3.2 | R15: 3.2
A16: MD425 | B16: Total Kebutuhan equivalent to singkong kulit | C16: 958318.44 | D16: 959935.01 | E16: 957949.34 | F16: 958733.49 | G16: 958871.92 | H16: 958518.08 | I16: 958707.81 | J16: 958699.25 | K16: 958641.7 | L16: 958682.92 | M16: 958674.62 | N16: 958666.41 | O16: 958674.65 | P16: 958671.9 | Q16: 958670.99 | R16: 958672.51
A17: MD427 | B17: Portion | C17: 0.92509938 | D17: 0.92522552 | E17: 0.92507052 | F17: 0.92513181 | G17: 0.92514262 | H17: 0.92511498 | I17: 0.9251298 | J17: 0.92512913 | K17: 0.92512464 | L17: 0.92512786 | M17: 0.92512721 | N17: 0.92512657 | O17: 0.92512721 | P17: 0.925127 | Q17: 0.92512693 | R17: 0.92512705
... A86: MD205 | B86: Ubi Orange | C86: 5620.6313 | D86: 5620.6313 | E86: 5620.6313 | F86: 5620.6313 | G86: 5620.6313 | H86: 5620.6313 | I86: 5620.6313 | J86: 5620.6313 | K86: 5620.6313 | L86: 5620.6313 | M86: 5620.6313 | N86: 5620.6313 | O86: 5620.6313 | P86: 5620.6313 | Q86: 5620.6313 | R86: 5620.6313
B87: Grup A diselaraskan: DL operator + THR 1/12 + BPJS DL, porsi volume | C87: =(C59+C59/12+C64)*IF(C71=0,0,C72/C71) -> 6.3190982e+08 | D87: =(D59+D59/12+D64)*IF(D71=0,0,D72/D71) -> 6.3161259e+08 | E87: =(E59+E59/12+E64)*IF(E71=0,0,E72/E71) -> 6.317616e+08 | F87: =(F59+F59/12+F64)*IF(F71=0,0,F72/F71) -> 6.3176134e+08 | G87: =(G59+G59/12+G64)*IF(G71=0,0,G72/G71) -> 6.3171184e+08 | H87: =(H59+H59/12+H64)*IF(H71=0,0,H72/H71) -> 6.3174493e+08 | I87: =(I59+I59/12+I64)*IF(I71=0,0,I72/I71) -> 6.3173937e+08 | J87: =(J59+J59/12+J64)*IF(J71=0,0,J72/J71) -> 6.3173205e+08 | ... R87: =(R59+R59/12+R64)*IF(R71=0,0,R72/R71) -> 6.3173661e+08
B88: Grup B diselaraskan: support + staf + THR + BPJS IDL, porsi volume | C88: =(C60+C60/12+C61+C63+C65)*IF(C71=0,0,C72/C71) -> 3.9907776e+08 | D88: =(D60+D60/12+D61+D63+D65)*IF(D71=0,0,D72/D71) -> 3.9889005e+08 | E88: =(E60+E60/12+E61+E63+E65)*IF(E71=0,0,E72/E71) -> 3.9898416e+08 | F88: =(F60+F60/12+F61+F63+F65)*IF(F71=0,0,F72/F71) -> 3.9898399e+08 | G88: =(G60+G60/12+G61+G63+G65)*IF(G71=0,0,G72/G71) -> 3.9895273e+08 | H88: =(H60+H60/12+H61+H63+H65)*IF(H71=0,0,H72/H71) -> 3.9897363e+08 | I88: =(I60+I60/12+I61+I63+I65)*IF(I71=0,0,I72/I71) -> 3.9897012e+08 | J88: =(J60+J60/12+J61+J63+J65)*IF(J71=0,0,J72/J71) -> 3.9896549e+08 | ... R88: =(R60+R60/12+R61+R63+R65)*IF(R71=0,0,R72/R71) -> 3.9896837e+08
B89: Cek: A + B diselaraskan − pool A + B budget (harus nol) | C89: =C87+C88-C54-C55 -> 2.3841858e-06 | D89: =D87+D88-D54-D55 -> -1.8775463e-06 | E89: =E87+E88-E54-E55 -> -2.2649765e-06 | F89: =F87+F88-F54-F55 -> -1.4901161e-06 | G89: =G87+G88-G54-G55 -> -1.2516975e-06 | H89: =H87+H88-H54-H55 -> -9.8347664e-07 | I89: =I87+I88-I54-I55 -> 2.1755695e-06 | J89: =J87+J88-J54-J55 -> 1.8179417e-06 | ... R89: =R87+R88-R54-R55 -> 1.0430813e-06
A91: Ubi Ungu IFM (QKSP)
A92: MD572 | B92: Premium / layak jual | C92: 0.99 | D92: 0.99 | E92: 0.99 | F92: 0.99 | G92: 0.99 | H92: 0.99 | I92: 0.99 | J92: 0.99 | K92: 0.99 | L92: 0.99 | M92: 0.99 | N92: 0.99 | O92: 0.99 | P92: 0.99 | Q92: 0.99 | R92: 0.99
A93: MD573 | B93: KW 2 | C93: 0 | D93: 0 | E93: 0 | F93: 0 | G93: 0 | H93: 0 | I93: 0 | J93: 0 | K93: 0 | L93: 0 | M93: 0 | N93: 0 | O93: 0 | P93: 0 | Q93: 0 | R93: 0
A94: MD574 | B94: Keripik waste | C94: 0.01 | D94: 0.01 | E94: 0.01 | F94: 0.01 | G94: 0.01 | H94: 0.01 | I94: 0.01 | J94: 0.01 | K94: 0.01 | L94: 0.01 | M94: 0.01 | N94: 0.01 | O94: 0.01 | P94: 0.01 | Q94: 0.01 | R94: 0.01
A95: MD578 | B95: Target Volume Penjualan/Layak Jual | C95: 6388 | D95: 6388 | E95: 6388 | F95: 6388 | G95: 6388 | H95: 6388 | I95: 6388 | J95: 6388 | K95: 6388 | L95: 6388 | M95: 6388 | N95: 6388 | O95: 6388 | P95: 6388 | Q95: 6388 | R95: 6388
A96: MD579 | B96: KW 2 | C96: 0 | D96: 0 | E96: 0 | F96: 0 | G96: 0 | H96: 0 | I96: 0 | J96: 0 | K96: 0 | L96: 0 | M96: 0 | N96: 0 | O96: 0 | P96: 0 | Q96: 0 | R96: 0
A97: MD580 | B97: Keripik waste | C97: 64.525253 | D97: 64.525253 | E97: 64.525253 | F97: 64.525253 | G97: 64.525253 | H97: 64.525253 | I97: 64.525253 | J97: 64.525253 | K97: 64.525253 | L97: 64.525253 | M97: 64.525253 | N97: 64.525253 | O97: 64.525253 | P97: 64.525253 | Q97: 64.525253 | R97: 64.525253
A98: MD581 | B98: WIP | C98: 0 | D98: 0 | E98: 0 | F98: 0 | G98: 0 | H98: 0 | I98: 0 | J98: 0 | K98: 0 | L98: 0 | M98: 0 | N98: 0 | O98: 0 | P98: 0 | Q98: 0 | R98: 0
A99: MD582 | B99: Target output Produksi | C99: 6452.5253 | D99: 6452.5253 | E99: 6452.5253 | F99: 6452.5253 | G99: 6452.5253 | H99: 6452.5253 | I99: 6452.5253 | J99: 6452.5253 | K99: 6452.5253 | L99: 6452.5253 | M99: 6452.5253 | N99: 6452.5253 | O99: 6452.5253 | P99: 6452.5253 | Q99: 6452.5253 | R99: 6452.5253
A100: MD586 | B100: Yield target | C100: 3.1297847 | D100: 3.1297847 | E100: 3.1297847 | F100: 3.1297847 | G100: 3.1297847 | H100: 3.1297847 | I100: 3.1297847 | J100: 3.1297847 | K100: 3.1297847 | L100: 3.1297847 | M100: 3.1297847 | N100: 3.1297847 | O100: 3.1297847 | P100: 3.1297847 | Q100: 3.1297847 | R100: 3.1297847
A101: MD587 | B101: Raw materials | C101: 20195.015 | D101: 20195.015 | E101: 20195.015 | F101: 20195.015 | G101: 20195.015 | H101: 20195.015 | I101: 20195.015 | J101: 20195.015 | K101: 20195.015 | L101: 20195.015 | M101: 20195.015 | N101: 20195.015 | O101: 20195.015 | P101: 20195.015 | Q101: 20195.015 | R101: 20195.015
A102: MD589 | B102: Total Ubi Ungu | C102: 1.194004e+08 | D102: 1.194004e+08 | E102: 1.194004e+08 | F102: 1.194004e+08 | G102: 1.194004e+08 | H102: 1.194004e+08 | I102: 1.194004e+08 | J102: 1.194004e+08 | K102: 1.194004e+08 | L102: 1.194004e+08 | M102: 1.194004e+08 | N102: 1.194004e+08 | O102: 1.194004e+08 | P102: 1.194004e+08 | Q102: 1.194004e+08 | R102: 1.194004e+08
A103: MD598 | B103: Raw materials | C103: 2561.9104 | D103: 2561.9104 | E103: 2561.9104 | F103: 2561.9104 | G103: 2561.9104 | H103: 2561.9104 | I103: 2561.9104 | J103: 2561.9104 | K103: 2561.9104 | L103: 2561.9104 | M103: 2561.9104 | N103: 2561.9104 | O103: 2561.9104 | P103: 2561.9104 | Q103: 2561.9104 | R103: 2561.9104
... A139: MD205 | B139: Ubi Orange | C139: 5620.6313 | D139: 5620.6313 | E139: 5620.6313 | F139: 5620.6313 | G139: 5620.6313 | H139: 5620.6313 | I139: 5620.6313 | J139: 5620.6313 | K139: 5620.6313 | L139: 5620.6313 | M139: 5620.6313 | N139: 5620.6313 | O139: 5620.6313 | P139: 5620.6313 | Q139: 5620.6313 | R139: 5620.6313
B140: Grup A diselaraskan: DL operator + THR 1/12 + BPJS DL, porsi volume | C140: =(C129+C129/12+C134)*IF(C136=0,0,C138/C136) -> 13615229 | D140: =(D129+D129/12+D134)*IF(D136=0,0,D138/D136) -> 13585907 | E140: =(E129+E129/12+E134)*IF(E136=0,0,E138/E136) -> 13617280 | F140: =(F129+F129/12+F134)*IF(F136=0,0,F138/F136) -> 13606137 | G140: =(G129+G129/12+G134)*IF(G136=0,0,G138/G136) -> 13603107 | H140: =(H129+H129/12+H134)*IF(H136=0,0,H138/H136) -> 13608841 | I140: =(I129+I129/12+I134)*IF(I136=0,0,I138/I136) -> 13606028 | J140: =(J129+J129/12+J134)*IF(J136=0,0,J138/J136) -> 13605992 | ... R140: =(R129+R129/12+R134)*IF(R136=0,0,R138/R136) -> 13606470
B141: Grup B diselaraskan: support + staf + THR + BPJS IDL, porsi volume | C141: =(C130+C130/12+C131+C133+C135)*IF(C136=0,0,C138/C136) -> 8598592.6 | D141: =(D130+D130/12+D131+D133+D135)*IF(D136=0,0,D138/D136) -> 8580074.6 | E141: =(E130+E130/12+E131+E133+E135)*IF(E136=0,0,E138/E136) -> 8599888 | F141: =(F130+F130/12+F131+F133+F135)*IF(F136=0,0,F138/F136) -> 8592850.7 | G141: =(G130+G130/12+G131+G133+G135)*IF(G136=0,0,G138/G136) -> 8590937.1 | H141: =(H130+H130/12+H131+H133+H135)*IF(H136=0,0,H138/H136) -> 8594558.5 | I141: =(I130+I130/12+I131+I133+I135)*IF(I136=0,0,I138/I136) -> 8592782 | J141: =(J130+J130/12+J131+J133+J135)*IF(J136=0,0,J138/J136) -> 8592759.2 | ... R141: =(R130+R130/12+R131+R133+R135)*IF(R136=0,0,R138/R136) -> 8593060.8
B142: Cek: A + B diselaraskan − pool A + B budget (harus nol) | C142: =C140+C141-C120-C121 -> 5.7742e-08 | D142: =D140+D141-D120-D121 -> -1.1175871e-08 | E142: =E140+E141-E120-E121 -> -5.7276338e-08 | F142: =F140+F141-F120-F121 -> -3.0733645e-08 | G142: =G140+G141-G120-G121 -> -1.3504177e-08 | H142: =H140+H141-H120-H121 -> -8.4750354e-08 | I142: =I140+I141-I120-I121 -> -2.5611371e-08 | J142: =J140+J141-J120-J121 -> 2.4680048e-08 | ... R142: =R140+R141-R120-R121 -> 0
A144: Ubi Orange IFM (QKSO)
A145: MD735 | B145: Premium / layak jual | C145: 0.99 | D145: 0.99 | E145: 0.99 | F145: 0.99 | G145: 0.99 | H145: 0.99 | I145: 0.99 | J145: 0.99 | K145: 0.99 | L145: 0.99 | M145: 0.99 | N145: 0.99 | O145: 0.99 | P145: 0.99 | Q145: 0.99 | R145: 0.99
A146: MD736 | B146: KW 2 | C146: 0 | D146: 0 | E146: 0 | F146: 0 | G146: 0 | H146: 0 | I146: 0 | J146: 0 | K146: 0 | L146: 0 | M146: 0 | N146: 0 | O146: 0 | P146: 0 | Q146: 0 | R146: 0
...
